Workbook

Sheet LÉEME
A1: ANEXO 1 · CALCULADORA DE COSTOS, MERMA Y PRECIOS DE BARRA
A2: Coctelería Mexicana Clásica y Contemporánea · 51 fichas · Oficios de Barra vol. 1
A3: Endulcora · Estudio Gastronómico · en colaboración con Levent
A6: QUÉ ES ESTO
B7: Un modelo de costeo vivo para las 51 fichas del libro. Todas las hojas están enlazadas con fórmulas reales: si cambias el precio de una botella, las 51 fichas, sus cuatro canales de venta, el costo de vertido y el punto de equilibrio se recalculan solos.
A9: CÓMO SE USA
A10: 1 | B10: Ve a la hoja «Mi negocio» y pon tus datos reales: renta, sueldo, tragos al mes, hielo, cristalería y merma. Son diez celdas.
A11: 2 | B11: Ve a la hoja «Insumos» y sustituye los precios de referencia por los que tú pagas. Solo la columna «Precio de compra» (celdas en amarillo).
A12: 3 | B12: Abre «Fichas y precios». Ahí están los 51 tragos costeados con tus números, su costo de vertido y sus precios sugeridos en los cuatro canales.
A13: 4 | B13: Usa «Producción» para planear el mes y «Ventas» para registrar lo que vendes. El «Tablero» resume todo.
A15: LA REGLA DE ORO
B16: SOLO SE EDITAN LAS CELDAS AMARILLAS. Todo lo demás son fórmulas: si escribes encima, rompes el modelo.
A18: EL MODELO DE COSTEO
B19: Costo por unidad = Precio de compra ÷ Cantidad comprada
B20: Costo insumos lote = Σ (cantidad × costo por unidad)
B21: Costo base = Insumos + Empaque + Energía + Mano de obra + Overhead
B22: Costo total unitario = Costo base ÷ (1 − % merma) ← se DIVIDE, no se suma
B23: PVP = Costo total ÷ (1 − margen)
B24: Costo por rebanada = Costo total ÷ rebanadas del molde
B25: Punto de equilibrio = Gastos fijos ÷ (PVP − costo variable unitario)
A27: LAS NUEVE HOJAS
A28: LÉEME | B28: Esta página.
A29: Insumos | B29: 121 insumos de barra con presentación, precio de compra (editable) y costo por mililitro o gramo.
A30: Métodos de barra | B30: Los 6 métodos T-1 a T-6 y las 6 preparaciones de casa, con cuántas fichas usa cada uno y su costo promedio.
A31: Ingredientes | B31: Las 323 líneas del manual normalizadas contra el catálogo, con el texto original del chef al lado para poder auditarlas.
A32: Mi negocio | B32: Tus parámetros. Es la hoja que hay que llenar primero.
A33: Fichas y precios | B33: La hoja principal: los 51 tragos con su costo, su vertido y sus 4 precios.
A34: Producción | B34: Plan mensual o cotización de evento: cuántos tragos de cada ficha y qué cuestan.
A35: Ventas | B35: Registro de ventas con cálculo automático de utilidad.
A36: Tablero | B36: Resumen, punto de equilibrio y ranking de rentabilidad.
A38: ADVERTENCIAS
B39: Los precios precargados son REFERENCIAS de mercado CDMX 2026, no cotizaciones. Sustitúyelos.
B40: Endulcora no garantiza ingresos ni resultados de negocio. Este archivo es una herramienta de cálculo, no una promesa. Prohibida la venta de bebidas alcohólicas a menores de 18 años. Evite el exceso.
B41: Las líneas marcadas en «Ingredientes» con nota en la columna «Equivalencia asumida» llevan un supuesto editorial (piezas a gramos, gajos, twists, golpes de amargo). Están declaradas una por una para que puedas revisarlas.

Sheet Insumos
A1: INSUMOS DE BARRA
A2: Sustituye la columna «Precio de compra» (amarillo) por tus precios reales.
A3: Endulcora · Estudio Gastronómico · en colaboración con Levent
A5: Clave | B5: Insumo | C5: Categoría | D5: Contenido del envase | E5: Unidad | F5: Precio de compra | G5: Costo por unidad | H5: Fichas que lo usan | I5: Consumo total (ml/g)
A6: B-001 | B6: Tequila blanco 100% agave | C6: Destilados de agave | D6: 750 | E6: ml | F6: 420 | G6: =IFERROR(F6/D6,0) -> 0.56 | H6: =COUNTIF(Ingredientes!$E:$E,A6) -> 9 | I6: =SUMIF(Ingredientes!$E:$E,A6,Ingredientes!$F:$F) -> 510
A7: B-002 | B7: Tequila reposado 100% agave | C7: Destilados de agave | D7: 750 | E7: ml | F7: 520 | G7: =IFERROR(F7/D7,0) -> 0.69333333 | H7: =COUNTIF(Ingredientes!$E:$E,A7) -> 8 | I7: =SUMIF(Ingredientes!$E:$E,A7,Ingredientes!$F:$F) -> 420
A8: B-003 | B8: Tequila añejo 100% agave | C8: Destilados de agave | D8: 750 | E8: ml | F8: 780 | G8: =IFERROR(F8/D8,0) -> 1.04 | H8: =COUNTIF(Ingredientes!$E:$E,A8) -> 1 | I8: =SUMIF(Ingredientes!$E:$E,A8,Ingredientes!$F:$F) -> 50
A9: B-004 | B9: Mezcal artesanal espadín joven | C9: Destilados de agave | D9: 750 | E9: ml | F9: 620 | G9: =IFERROR(F9/D9,0) -> 0.82666667 | H9: =COUNTIF(Ingredientes!$E:$E,A9) -> 12 | I9: =SUMIF(Ingredientes!$E:$E,A9,Ingredientes!$F:$F) -> 572.5
A10: B-005 | B10: Mezcal artesanal de agave silvestre (tobalá) | C10: Destilados de agave | D10: 750 | E10: ml | F10: 1450 | G10: =IFERROR(F10/D10,0) -> 1.9333333 | H10: =COUNTIF(Ingredientes!$E:$E,A10) -> 2 | I10: =SUMIF(Ingredientes!$E:$E,A10,Ingredientes!$F:$F) -> 120
A11: B-010 | B11: Charanda blanca de Uruapan | C11: Destilados regionales | D11: 750 | E11: ml | F11: 385 | G11: =IFERROR(F11/D11,0) -> 0.51333333 | H11: =COUNTIF(Ingredientes!$E:$E,A11) -> 3 | I11: =SUMIF(Ingredientes!$E:$E,A11,Ingredientes!$F:$F) -> 180
A12: B-011 | B12: Charanda añeja | C12: Destilados regionales | D12: 750 | E12: ml | F12: 495 | G12: =IFERROR(F12/D12,0) -> 0.66 | H12: =COUNTIF(Ingredientes!$E:$E,A12) -> 1 | I12: =SUMIF(Ingredientes!$E:$E,A12,Ingredientes!$F:$F) -> 60
A13: B-012 | B13: Raicilla artesanal | C13: Destilados regionales | D13: 750 | E13: ml | F13: 690 | G13: =IFERROR(F13/D13,0) -> 0.92 | H13: =COUNTIF(Ingredientes!$E:$E,A13) -> 2 | I13: =SUMIF(Ingredientes!$E:$E,A13,Ingredientes!$F:$F) -> 110
A14: B-013 | B14: Sotol artesanal de Chihuahua | C14: Destilados regionales | D14: 750 | E14: ml | F14: 650 | G14: =IFERROR(F14/D14,0) -> 0.86666667 | H14: =COUNTIF(Ingredientes!$E:$E,A14) -> 2 | I14: =SUMIF(Ingredientes!$E:$E,A14,Ingredientes!$F:$F) -> 80
A15: B-014 | B15: Bacanora blanco de Sonora | C15: Destilados regionales | D15: 750 | E15: ml | F15: 720 | G15: =IFERROR(F15/D15,0) -> 0.96 | H15: =COUNTIF(Ingredientes!$E:$E,A15) -> 1 | I15: =SUMIF(Ingredientes!$E:$E,A15,Ingredientes!$F:$F) -> 60
A16: B-015 | B16: Pox artesanal de Chiapas | C16: Destilados regionales | D16: 750 | E16: ml | F16: 380 | G16: =IFERROR(F16/D16,0) -> 0.50666667 | H16: =COUNTIF(Ingredientes!$E:$E,A16) -> 2 | I16: =SUMIF(Ingredientes!$E:$E,A16,Ingredientes!$F:$F) -> 100
A17: B-020 | B17: Licor de naranja triple sec | C17: Licores y aperitivos | D17: 700 | E17: ml | F17: 680 | G17: =IFERROR(F17/D17,0) -> 0.97142857 | H17: =COUNTIF(Ingredientes!$E:$E,A17) -> 3 | I17: =SUMIF(Ingredientes!$E:$E,A17,Ingredientes!$F:$F) -> 70
... A126: B-174 | B126: Vaina de tamarindo seco | C126: Garnituras y complementos | D126: 250 | E126: g | F126: 45 | G126: =IFERROR(F126/D126,0) -> 0.18 | H126: =COUNTIF(Ingredientes!$E:$E,A126) -> 1 | I126: =SUMIF(Ingredientes!$E:$E,A126,Ingredientes!$F:$F) -> 6
A128: Precios de referencia CDMX 2026. Ilustrativos, no cotizaciones.

Sheet Métodos de barra
A1: MÉTODOS DE BARRA
A2: Los seis métodos T-1 a T-6 y las seis preparaciones de casa.
A3: Endulcora · Estudio Gastronómico · en colaboración con Levent
A5: Clave | B5: Método base | C5: Qué es | D5: Fichas | E5: Costo promedio de insumos | F5: Costo mínimo | G5: Costo máximo
A6: T-1 | B6: Construido directo en vaso (build) | C6: Todo se integra en el propio vaso sobre hielo. La dilución es lenta y progresiva: el hielo macizo es parte de la receta, no un relleno. | D6: =COUNTIF('Fichas y precios'!$C:$C,A6) -> 11 | E6: =IFERROR(AVERAGEIF('Fichas y precios'!$C:$C,A6,'Fichas y precios'!$E:$E),0) -> 49.347246 | F6: =IFERROR(minifs('Fichas y precios'!$E$6:$E$56,'Fichas y precios'!$C$6:$C$56,A6),0) -> 0 | G6: =IFERROR(maxifs('Fichas y precios'!$E$6:$E$56,'Fichas y precios'!$C$6:$C$56,A6),0) -> 0
A7: T-2 | B7: Agitado (shake) | C7: De 10 a 12 segundos con hielo macizo. Airea, enfría y diluye entre 25 y 30 %. Obligatorio cuando hay cítrico, jarabe denso, pulpa o lácteo. | D7: =COUNTIF('Fichas y precios'!$C:$C,A7) -> 14 | E7: =IFERROR(AVERAGEIF('Fichas y precios'!$C:$C,A7,'Fichas y precios'!$E:$E),0) -> 59.164484 | F7: =IFERROR(minifs('Fichas y precios'!$E$6:$E$56,'Fichas y precios'!$C$6:$C$56,A7),0) -> 0 | G7: =IFERROR(maxifs('Fichas y precios'!$E$6:$E$56,'Fichas y precios'!$C$6:$C$56,A7),0) -> 0
A8: T-3 | B8: Refrescado en vaso mezclador (stir) | C8: De 20 a 30 segundos con cuchara de bar. Enfría sin airear y da textura sedosa: es para tragos de solo destilados y licores. | D8: =COUNTIF('Fichas y precios'!$C:$C,A8) -> 3 | E8: =IFERROR(AVERAGEIF('Fichas y precios'!$C:$C,A8,'Fichas y precios'!$E:$E),0) -> 57.369421 | F8: =IFERROR(minifs('Fichas y precios'!$E$6:$E$56,'Fichas y precios'!$C$6:$C$56,A8),0) -> 0 | G8: =IFERROR(maxifs('Fichas y precios'!$E$6:$E$56,'Fichas y precios'!$C$6:$C$56,A8),0) -> 0
A9: T-4 | B9: Macerado (muddle) y agitado | C9: Se rompe la fruta o la hierba con el mazo, sin triturarla, para liberar aceites esenciales antes de agitar. Machacar de más amarga. | D9: =COUNTIF('Fichas y precios'!$C:$C,A9) -> 3 | E9: =IFERROR(AVERAGEIF('Fichas y precios'!$C:$C,A9,'Fichas y precios'!$E:$E),0) -> 50.721085 | F9: =IFERROR(minifs('Fichas y precios'!$E$6:$E$56,'Fichas y precios'!$C$6:$C$56,A9),0) -> 0 | G9: =IFERROR(maxifs('Fichas y precios'!$E$6:$E$56,'Fichas y precios'!$C$6:$C$56,A9),0) -> 0
A10: T-5 | B10: Emulsión y dry shake | C10: Primer agitado sin hielo para desnaturalizar la proteína de la clara o el huevo, segundo con hielo para enfriar. Da la corona espumosa estable. | D10: =COUNTIF('Fichas y precios'!$C:$C,A10) -> 10 | E10: =IFERROR(AVERAGEIF('Fichas y precios'!$C:$C,A10,'Fichas y precios'!$E:$E),0) -> 51.372009 | F10: =IFERROR(minifs('Fichas y precios'!$E$6:$E$56,'Fichas y precios'!$C$6:$C$56,A10),0) -> 0 | G10: =IFERROR(maxifs('Fichas y precios'!$E$6:$E$56,'Fichas y precios'!$C$6:$C$56,A10),0) -> 0
A11: T-6 | B11: Montaje por capas, ahumado e infusión | C11: Gradientes de densidad, campanas de humo, flameados, infusiones térmicas y esferas de nieve. Es el grupo de mayor tiempo de barra y mayor impacto visual. | D11: =COUNTIF('Fichas y precios'!$C:$C,A11) -> 10 | E11: =IFERROR(AVERAGEIF('Fichas y precios'!$C:$C,A11,'Fichas y precios'!$E:$E),0) -> 68.013606 | F11: =IFERROR(minifs('Fichas y precios'!$E$6:$E$56,'Fichas y precios'!$C$6:$C$56,A11),0) -> 0 | G11: =IFERROR(maxifs('Fichas y precios'!$E$6:$E$56,'Fichas y precios'!$C$6:$C$56,A11),0) -> 0
A14: PREPARACIONES DE CASA
A15: Clave | B15: Preparación de casa | C15: Qué es
A16: P-1 | B16: Jarabes de casa | C16: Simple de caña 1:1, agave 2:1, piloncillo, especias, fruta. Se hacen en lote, cuestan centavos por trago y son el ajuste fino del balance dulce-ácido.
A17: P-2 | B17: Escarchados y sales de autor | C17: Flor de sal de Colima, sal de gusano, chicatana, chile piquín, cenizas de hierba. Media escarcha, tercio de borde o borde completo: se decide por diseño, no por costumbre.
A18: P-3 | B18: Jugos frescos y clarificados | C18: Exprimidos del día y colados. Un jugo de más de seis horas ya perdió aroma y ganó amargor. Es el insumo más perecedero de la barra y el que más merma genera.
A19: P-4 | B19: Infusiones, tinturas y ahumados | C19: Chiles, botánicos, café de olla, hoja santa. Tinturas al destilado neutro y ahumado por campana o flameado directo. Bajo costo, alto valor percibido.
A20: P-5 | B20: Fermentos de casa | C20: Tepache de cáscara de piña, curados de pulque, tejuino de maíz nixtamalizado. Requieren control sanitario y rotación estricta: son producto vivo.
A21: P-6 | B21: Garnituras funcionales y deshidratados | C21: Rodajas deshidratadas, chips, twists, banderillas. Funcional quiere decir que aporta aroma al acercar el vaso, no solo que se ve bien.

Sheet Ingredientes
A1: INGREDIENTES
A2: Cada línea del manual normalizada contra el catálogo de barra. La columna «Texto original del chef» permite auditar la equivalencia.
A3: Endulcora · Estudio Gastronómico · en colaboración con Levent
A5: # | B5: Ficha | C5: Texto original del chef | E5: Clave insumo | F5: Cantidad | G5: Unidad | H5: Costo de la línea | I5: Equivalencia asumida
A6: 1 | B6: Margarita Clásica 1942 | C6: 60 ml (2.0 oz) Tequila Blanco 100% puro de agave (40% ABV) | E6: B-001 | F6: 60 | G6: ml | H6: =IFERROR(F6*VLOOKUP(E6,Insumos!$A:$G,7,FALSE()),0) -> 33.6
A7: 1 | B7: Margarita Clásica 1942 | C7: 30 ml (1.0 oz) Licor de naranja francés tipo triple sec (Cointreau) | E7: B-020 | F7: 30 | G7: ml | H7: =IFERROR(F7*VLOOKUP(E7,Insumos!$A:$G,7,FALSE()),0) -> 29.142857
A8: 1 | B8: Margarita Clásica 1942 | C8: 22 ml (0.75 oz) Jugo fresco de lima verde recién exprimido y colado | E8: B-071 | F8: 22 | G8: ml | H8: =IFERROR(F8*VLOOKUP(E8,Insumos!$A:$G,7,FALSE()),0) -> 2.42
A9: 1 | B9: Margarita Clásica 1942 | C9: 8 ml (0.25 oz) Jarabe de agave ligero (dilución 2:1 agave/agua para balancear la acidez cítrica) | E9: B-096 | F9: 8 | G9: ml | H9: =IFERROR(F9*VLOOKUP(E9,Insumos!$A:$G,7,FALSE()),0) -> 1.48
A10: 1 | B10: Margarita Clásica 1942 | C10: 1 g Flor de sal de Colima o sal marina de grano fino (media escarcha en el borde) | E10: B-115 | F10: 1 | G10: g | H10: =IFERROR(F10*VLOOKUP(E10,Insumos!$A:$G,7,FALSE()),0) -> 0.78
A11: 1 | B11: Margarita Clásica 1942 | C11: 1 Rodaja deshidratada de lima verde para decorar | E11: B-155 | F11: 4 | G11: g | H11: =IFERROR(F11*VLOOKUP(E11,Insumos!$A:$G,7,FALSE()),0) -> 8.8 | I11: 1 rodaja deshidratada ≈ 4 g
A12: 2 | B12: Paloma Tradicional con Refresco de Toronja Artesanal y Sal de Colima | C12: 60 ml (2.0 oz) Tequila Blanco o Tequila Reposado 100% de agave | E12: B-001 | F12: 60 | G12: ml | H12: =IFERROR(F12*VLOOKUP(E12,Insumos!$A:$G,7,FALSE()),0) -> 33.6
A13: 2 | B13: Paloma Tradicional con Refresco de Toronja Artesanal y Sal de Colima | C13: 20 ml (0.7 oz) Jugo fresco de toronja rosa colado | E13: B-075 | F13: 20 | G13: ml | H13: =IFERROR(F13*VLOOKUP(E13,Insumos!$A:$G,7,FALSE()),0) -> 1.64
A14: 2 | B14: Paloma Tradicional con Refresco de Toronja Artesanal y Sal de Colima | C14: 15 ml (0.5 oz) Jugo fresco de limón criollo colado | E14: B-070 | F14: 15 | G14: ml | H14: =IFERROR(F14*VLOOKUP(E14,Insumos!$A:$G,7,FALSE()),0) -> 1.425
A15: 2 | B15: Paloma Tradicional con Refresco de Toronja Artesanal y Sal de Colima | C15: 120 ml (4.0 oz) Refresco artesanal de toronja (o soda de toronja con azúcar de caña) | E15: B-056 | F15: 120 | G15: ml | H15: =IFERROR(F15*VLOOKUP(E15,Insumos!$A:$G,7,FALSE()),0) -> 10.816901
A16: 2 | B16: Paloma Tradicional con Refresco de Toronja Artesanal y Sal de Colima | C16: 1 g Sal marina fina disuelta directamente en el fondo | E16: B-116 | F16: 1 | G16: g | H16: =IFERROR(F16*VLOOKUP(E16,Insumos!$A:$G,7,FALSE()),0) -> 0.032
A17: 2 | B17: Paloma Tradicional con Refresco de Toronja Artesanal y Sal de Colima | C17: 1 Media luna de toronja fresca y sal de Colima escarchada en el borde exterior | E17: B-116 | F17: 45 | G17: g | H17: =IFERROR(F17*VLOOKUP(E17,Insumos!$A:$G,7,FALSE()),0) -> 1.44 | I17: media luna / twist de toronja ≈ 45 g
A18: 3 | B18: Tequila Sunrise Estilo Cantina Clásica | C18: 60 ml (2.0 oz) Tequila Blanco 100% agave | E18: B-001 | F18: 60 | G18: ml | H18: =IFERROR(F18*VLOOKUP(E18,Insumos!$A:$G,7,FALSE()),0) -> 33.6
A19: 3 | B19: Tequila Sunrise Estilo Cantina Clásica | C19: 120 ml (4.0 oz) Jugo natural de naranja recién exprimido y colado dos veces (sin pulpa flotante) | E19: B-073 | F19: 120 | G19: ml | H19: =IFERROR(F19*VLOOKUP(E19,Insumos!$A:$G,7,FALSE()),0) -> 6.96
A20: 3 | B20: Tequila Sunrise Estilo Cantina Clásica | C20: 20 ml (0.7 oz) Granadina casera de jugo de granada roja y azúcar (proporción 1:1 con 2 gotas de agua de azahar) | E20: B-100 | F20: 20 | G20: ml | H20: =IFERROR(F20*VLOOKUP(E20,Insumos!$A:$G,7,FALSE()),0) -> 2.6
A21: 3 | B21: Tequila Sunrise Estilo Cantina Clásica | C21: 1 Media luna de naranja fresca y 1 cereza al marasquino artesanal | E21: B-157 | F21: 28 | G21: g | H21: =IFERROR(F21*VLOOKUP(E21,Insumos!$A:$G,7,FALSE()),0) -> 11.55 | I21: media luna / twist de naranja ≈ 28 g
A22: 4 | B22: Tommy’s Margarita | C22: 60 ml (2.0 oz) Tequila Reposado 100% agave (notas amaderadas suaves y vainilla) | E22: B-002 | F22: 60 | G22: ml | H22: =IFERROR(F22*VLOOKUP(E22,Insumos!$A:$G,7,FALSE()),0) -> 41.6
A23: 4 | B23: Tommy’s Margarita | C23: 30 ml (1.0 oz) Jugo fresco de lima verde recién exprimido | E23: B-071 | F23: 30 | G23: ml | H23: =IFERROR(F23*VLOOKUP(E23,Insumos!$A:$G,7,FALSE()),0) -> 3.3
A24: 4 | B24: Tommy’s Margarita | C24: 15 ml (0.5 oz) Miel de agave pura disuelta con agua purificada en proporción 1:1 (jarabe de agave 50° Brix) | E24: B-061 | F24: 15 | G24: ml | H24: =IFERROR(F24*VLOOKUP(E24,Insumos!$A:$G,7,FALSE()),0) -> 0.03375
A25: 4 | B25: Tommy’s Margarita | C25: 1 Gajo de lima verde exprimido y depositado sobre el hielo | E25: B-171 | F25: 12 | G25: g | H25: =IFERROR(F25*VLOOKUP(E25,Insumos!$A:$G,7,FALSE()),0) -> 0.504 | I25: rodaja o gajo de cítrico ≈ 12 g
A26: 5 | B26: Batanga de Tequila Reposado, Refresco de Cola y Sal en Navaja | C26: 60 ml (2.0 oz) Tequila Reposado (o Tequila Blanco de perfil rústico) | E26: B-002 | F26: 60 | G26: ml | H26: =IFERROR(F26*VLOOKUP(E26,Insumos!$A:$G,7,FALSE()),0) -> 41.6
A27: 5 | B27: Batanga de Tequila Reposado, Refresco de Cola y Sal en Navaja | C27: 15 ml (0.5 oz) Jugo fresco de limón criollo recién exprimido | E27: B-070 | F27: 15 | G27: ml | H27: =IFERROR(F27*VLOOKUP(E27,Insumos!$A:$G,7,FALSE()),0) -> 1.425
A28: 5 | B28: Batanga de Tequila Reposado, Refresco de Cola y Sal en Navaja | C28: 140 ml Refresco de cola tradicional endulzado con azúcar de caña mexicana | E28: B-055 | F28: 140 | G28: ml | H28: =IFERROR(F28*VLOOKUP(E28,Insumos!$A:$G,7,FALSE()),0) -> 8.6760563
A29: 5 | B29: Batanga de Tequila Reposado, Refresco de Cola y Sal en Navaja | C29: 1.5 g Flor de sal de Colima (para escarchado total del borde) | E29: B-115 | F29: 1.5 | G29: g | H29: =IFERROR(F29*VLOOKUP(E29,Insumos!$A:$G,7,FALSE()),0) -> 1.17
A30: 5 | B30: Batanga de Tequila Reposado, Refresco de Cola y Sal en Navaja | C30: 1 Cuchillo de cocina de acero al carbono grande (para mezclar) | E30: B-168 | F30: 0 | G30: pz | H30: =IFERROR(F30*VLOOKUP(E30,Insumos!$A:$G,7,FALSE()),0) -> 0 | I30: utensilio de barra: no se consume, costo cero por trago
A31: 5 | B31: Batanga de Tequila Reposado, Refresco de Cola y Sal en Navaja | C31: 1 Rodaja gruesa de limón criollo dentro del trago | E31: B-171 | F31: 12 | G31: g | H31: =IFERROR(F31*VLOOKUP(E31,Insumos!$A:$G,7,FALSE()),0) -> 0.504 | I31: rodaja o gajo de cítrico ≈ 12 g
A32: 6 | B32: Charro Negro Clásico al Limón Criollo | C32: 60 ml (2.0 oz) Tequila Reposado 100% de agave (mínimo 6 meses en barrica) | E32: B-002 | F32: 60 | G32: ml | H32: =IFERROR(F32*VLOOKUP(E32,Insumos!$A:$G,7,FALSE()),0) -> 41.6
A33: 6 | B33: Charro Negro Clásico al Limón Criollo | C33: 15 ml (0.5 oz) Jugo fresco de limón criollo recién exprimido y colado | E33: B-070 | F33: 15 | G33: ml | H33: =IFERROR(F33*VLOOKUP(E33,Insumos!$A:$G,7,FALSE()),0) -> 1.425
A34: 6 | B34: Charro Negro Clásico al Limón Criollo | C34: 130 ml Refresco de cola tradicional con azúcar de caña | E34: B-055 | F34: 130 | G34: ml | H34: =IFERROR(F34*VLOOKUP(E34,Insumos!$A:$G,7,FALSE()),0) -> 8.056338
A35: 6 | B35: Charro Negro Clásico al Limón Criollo | C35: 1 g Sal fina marina (para media escarcha delgada) | E35: B-116 | F35: 1 | G35: g | H35: =IFERROR(F35*VLOOKUP(E35,Insumos!$A:$G,7,FALSE()),0) -> 0.032
A36: 6 | B36: Charro Negro Clásico al Limón Criollo | C36: 1 Media luna de limón criollo dentro del vaso | E36: B-171 | F36: 12 | G36: g | H36: =IFERROR(F36*VLOOKUP(E36,Insumos!$A:$G,7,FALSE()),0) -> 0.504 | I36: rodaja o gajo de cítrico ≈ 12 g
A37: 7 | B37: Vampiro de Tlaquepaque con Sangrita Casera de Tomate y Naranja | C37: 60 ml Jugo de tomate natural colado | E37: B-060 | F37: 60 | G37: ml | H37: =IFERROR(F37*VLOOKUP(E37,Insumos!$A:$G,7,FALSE()),0) -> 3.12
A38: 7 | B38: Vampiro de Tlaquepaque con Sangrita Casera de Tomate y Naranja | C38: 30 ml Jugo fresco de naranja dulce recién exprimido | E38: B-073 | F38: 30 | G38: ml | H38: =IFERROR(F38*VLOOKUP(E38,Insumos!$A:$G,7,FALSE()),0) -> 1.74
A39: 7 | B39: Vampiro de Tlaquepaque con Sangrita Casera de Tomate y Naranja | C39: 15 ml Jugo fresco de limón criollo | E39: B-070 | F39: 15 | G39: ml | H39: =IFERROR(F39*VLOOKUP(E39,Insumos!$A:$G,7,FALSE()),0) -> 1.425
A40: 7 | B40: Vampiro de Tlaquepaque con Sangrita Casera de Tomate y Naranja | C40: 5 ml Salsa inglesa (Worcestershire) | E40: B-140 | F40: 5 | G40: ml | H40: =IFERROR(F40*VLOOKUP(E40,Insumos!$A:$G,7,FALSE()),0) -> 1.0689655
A41: 7 | B41: Vampiro de Tlaquepaque con Sangrita Casera de Tomate y Naranja | C41: 5 ml Salsa botanera picante de chile de árbol o salsa Maggi | E41: B-143 | F41: 5 | G41: ml | H41: =IFERROR(F41*VLOOKUP(E41,Insumos!$A:$G,7,FALSE()),0) -> 0.6
...

Sheet Mi negocio
A1: MI NEGOCIO
A2: Empieza aquí. Solo las celdas amarillas. Todo el archivo depende de estas.
A3: Endulcora · Estudio Gastronómico · en colaboración con Levent
A5: Parámetro | B5: Valor | D5: Qué es
A6: Gastos fijos mensuales | B6: 18000 | D6: Renta, luz, agua, permisos, contador
A7: Tragos servidos al mes | B7: 1200 | D7: Cuántos tragos estimas servir al mes
A8: Sueldo mensual del bartender | B8: 15000 | D8: De quien está detrás de la barra
A9: Horas trabajadas al mes | B9: 200 | D9: 200 h ≈ jornada completa
A10: Hielo por trago | B10: 2.5 | D10: Hielo macizo de agua purificada
A11: Cristalería por trago | B11: 1.8 | D11: Rotura, lavado y reposición
A12: Merma comercial | B12: 0.08 | D12: Derrame, devolución, jugo perdido, sobre-servido. 15 a 20 % en barra libre
A13: Tragos por batch | B13: 6 | D13: Rendimiento de una botella preparada
A14: Envase de batch | B14: 28 | D14: Botella, tapa y etiqueta
A15: Copa estándar (ml de etanol) | B15: 16.5 | D15: 13 g de etanol puro. No lo cambies sin razón
A17: CALCULADO AUTOMÁTICAMENTE
A18: Overhead por trago | B18: =IFERROR(B6/B7,0) -> 15 | D18: Gastos fijos ÷ tragos al mes
A19: Costo de mano de obra por hora | B19: =IFERROR(B8/B9,0) -> 75 | D19: Sueldo ÷ horas
A22: MÁRGENES POR CANAL
A23: Canal | B23: Margen | D23: Unidad de venta
A24: Barra propia | B24: 0.62 | D24: Un trago
A25: Carta de restaurante | B25: 0.68 | D25: Un trago
A26: Evento y banquete | B26: 0.55 | D26: Un trago
A27: Batch embotellado | B27: 0.45 | D27: Botella de varios tragos
A29: Un ejemplo: si pagas $720 por la botella de mezcal en vez de $620, cámbialo en «Insumos» y las 51 fichas se recalculan al instante.

Sheet Fichas y precios
A1: FICHAS Y PRECIOS
A2: La hoja principal. Todo se recalcula desde «Insumos» y «Mi negocio». Aquí no se edita nada.
A3: Endulcora · Estudio Gastronómico · en colaboración con Levent
A5: # | B5: Ficha | C5: Método | D5: Cap. | E5: Costo insumos | F5: Hielo | G5: Cristalería | H5: Min. barra | I5: Mano de obra | J5: Overhead | K5: Costo base | L5: Merma | M5: COSTO TOTAL | N5: Etanol servido (ml) | O5: Copas estándar | P5: Barra propia | Q5: Carta restaurante | R5: Evento y banquete | S5: Batch embotellado | T5: Utilidad en barra | U5: Costo de vertido
A6: 1 | B6: Margarita Clásica 1942 | C6: T-2 | D6: 6 | E6: =SUMIF(Ingredientes!$A:$A,$A6,Ingredientes!$H:$H) -> 76.222857 | F6: ='Mi negocio'!$B$10 -> 2.5 | G6: ='Mi negocio'!$B$11 -> 1.8 | H6: 3 | I6: =H6/60*'Mi negocio'!$B$19 -> 3.75 | J6: ='Mi negocio'!$B$18 -> 15 | K6: =E6+F6+G6+I6+J6 -> 99.272857 | L6: ='Mi negocio'!$B$12 -> 0.08 | M6: =IFERROR(K6/(1-L6),0) -> 107.90528 | N6: 36 | O6: =IFERROR(N6/'Mi negocio'!$B$15,0) -> 2.1818182 | P6: =IFERROR(CEILING(M6/(1-'Mi negocio'!$B$24),5),0) -> 285 | Q6: =IFERROR(CEILING(M6/(1-'Mi negocio'!$B$25),5),0) -> 340 | R6: =IFERROR(CEILING(M6/(1-'Mi negocio'!$B$26),5),0) -> 240 | S6: =IFERROR(CEILING((M6*'Mi negocio'!$B$13+'Mi negocio'!$B$14)/(1-'Mi negocio'!$B$27),10),0) -> 1230 | T6: =P6-M6 -> 177.09472 | U6: =IFERROR(E6/P6,0) -> 0.26744862
A7: 2 | B7: Paloma Tradicional con Refresco de Toronja Artesanal y Sal de Colima | C7: T-1 | D7: 6 | E7: =SUMIF(Ingredientes!$A:$A,$A7,Ingredientes!$H:$H) -> 48.953901 | F7: ='Mi negocio'!$B$10 -> 2.5 | G7: ='Mi negocio'!$B$11 -> 1.8 | H7: 2 | I7: =H7/60*'Mi negocio'!$B$19 -> 2.5 | J7: ='Mi negocio'!$B$18 -> 15 | K7: =E7+F7+G7+I7+J7 -> 70.753901 | L7: ='Mi negocio'!$B$12 -> 0.08 | M7: =IFERROR(K7/(1-L7),0) -> 76.906415 | N7: 24 | O7: =IFERROR(N7/'Mi negocio'!$B$15,0) -> 1.4545455 | P7: =IFERROR(CEILING(M7/(1-'Mi negocio'!$B$24),5),0) -> 205 | Q7: =IFERROR(CEILING(M7/(1-'Mi negocio'!$B$25),5),0) -> 245 | R7: =IFERROR(CEILING(M7/(1-'Mi negocio'!$B$26),5),0) -> 175 | S7: =IFERROR(CEILING((M7*'Mi negocio'!$B$13+'Mi negocio'!$B$14)/(1-'Mi negocio'!$B$27),10),0) -> 890 | T7: =P7-M7 -> 128.09359 | U7: =IFERROR(E7/P7,0) -> 0.23879952
A8: 3 | B8: Tequila Sunrise Estilo Cantina Clásica | C8: T-6 | D8: 6 | E8: =SUMIF(Ingredientes!$A:$A,$A8,Ingredientes!$H:$H) -> 54.71 | F8: ='Mi negocio'!$B$10 -> 2.5 | G8: ='Mi negocio'!$B$11 -> 1.8 | H8: 6 | I8: =H8/60*'Mi negocio'!$B$19 -> 7.5 | J8: ='Mi negocio'!$B$18 -> 15 | K8: =E8+F8+G8+I8+J8 -> 81.51 | L8: ='Mi negocio'!$B$12 -> 0.08 | M8: =IFERROR(K8/(1-L8),0) -> 88.597826 | N8: 24 | O8: =IFERROR(N8/'Mi negocio'!$B$15,0) -> 1.4545455 | P8: =IFERROR(CEILING(M8/(1-'Mi negocio'!$B$24),5),0) -> 235 | Q8: =IFERROR(CEILING(M8/(1-'Mi negocio'!$B$25),5),0) -> 280 | R8: =IFERROR(CEILING(M8/(1-'Mi negocio'!$B$26),5),0) -> 200 | S8: =IFERROR(CEILING((M8*'Mi negocio'!$B$13+'Mi negocio'!$B$14)/(1-'Mi negocio'!$B$27),10),0) -> 1020 | T8: =P8-M8 -> 146.40217 | U8: =IFERROR(E8/P8,0) -> 0.23280851
A9: 4 | B9: Tommy’s Margarita | C9: T-2 | D9: 6 | E9: =SUMIF(Ingredientes!$A:$A,$A9,Ingredientes!$H:$H) -> 45.43775 | F9: ='Mi negocio'!$B$10 -> 2.5 | G9: ='Mi negocio'!$B$11 -> 1.8 | H9: 3 | I9: =H9/60*'Mi negocio'!$B$19 -> 3.75 | J9: ='Mi negocio'!$B$18 -> 15 | K9: =E9+F9+G9+I9+J9 -> 68.48775 | L9: ='Mi negocio'!$B$12 -> 0.08 | M9: =IFERROR(K9/(1-L9),0) -> 74.443207 | N9: 24 | O9: =IFERROR(N9/'Mi negocio'!$B$15,0) -> 1.4545455 | P9: =IFERROR(CEILING(M9/(1-'Mi negocio'!$B$24),5),0) -> 200 | Q9: =IFERROR(CEILING(M9/(1-'Mi negocio'!$B$25),5),0) -> 235 | R9: =IFERROR(CEILING(M9/(1-'Mi negocio'!$B$26),5),0) -> 170 | S9: =IFERROR(CEILING((M9*'Mi negocio'!$B$13+'Mi negocio'!$B$14)/(1-'Mi negocio'!$B$27),10),0) -> 870 | T9: =P9-M9 -> 125.55679 | U9: =IFERROR(E9/P9,0) -> 0.22718875
A10: 5 | B10: Batanga de Tequila Reposado, Refresco de Cola y Sal en Navaja | C10: T-2 | D10: 6 | E10: =SUMIF(Ingredientes!$A:$A,$A10,Ingredientes!$H:$H) -> 53.375056 | F10: ='Mi negocio'!$B$10 -> 2.5 | G10: ='Mi negocio'!$B$11 -> 1.8 | H10: 3 | I10: =H10/60*'Mi negocio'!$B$19 -> 3.75 | J10: ='Mi negocio'!$B$18 -> 15 | K10: =E10+F10+G10+I10+J10 -> 76.425056 | L10: ='Mi negocio'!$B$12 -> 0.08 | M10: =IFERROR(K10/(1-L10),0) -> 83.070713 | N10: 24 | O10: =IFERROR(N10/'Mi negocio'!$B$15,0) -> 1.4545455 | P10: =IFERROR(CEILING(M10/(1-'Mi negocio'!$B$24),5),0) -> 220 | Q10: =IFERROR(CEILING(M10/(1-'Mi negocio'!$B$25),5),0) -> 260 | R10: =IFERROR(CEILING(M10/(1-'Mi negocio'!$B$26),5),0) -> 185 | S10: =IFERROR(CEILING((M10*'Mi negocio'!$B$13+'Mi negocio'!$B$14)/(1-'Mi negocio'!$B$27),10),0) -> 960 | T10: =P10-M10 -> 136.92929 | U10: =IFERROR(E10/P10,0) -> 0.24261389
A11: 6 | B11: Charro Negro Clásico al Limón Criollo | C11: T-1 | D11: 6 | E11: =SUMIF(Ingredientes!$A:$A,$A11,Ingredientes!$H:$H) -> 51.617338 | F11: ='Mi negocio'!$B$10 -> 2.5 | G11: ='Mi negocio'!$B$11 -> 1.8 | H11: 2 | I11: =H11/60*'Mi negocio'!$B$19 -> 2.5 | J11: ='Mi negocio'!$B$18 -> 15 | K11: =E11+F11+G11+I11+J11 -> 73.417338 | L11: ='Mi negocio'!$B$12 -> 0.08 | M11: =IFERROR(K11/(1-L11),0) -> 79.801454 | N11: 24 | O11: =IFERROR(N11/'Mi negocio'!$B$15,0) -> 1.4545455 | P11: =IFERROR(CEILING(M11/(1-'Mi negocio'!$B$24),5),0) -> 215 | Q11: =IFERROR(CEILING(M11/(1-'Mi negocio'!$B$25),5),0) -> 250 | R11: =IFERROR(CEILING(M11/(1-'Mi negocio'!$B$26),5),0) -> 180 | S11: =IFERROR(CEILING((M11*'Mi negocio'!$B$13+'Mi negocio'!$B$14)/(1-'Mi negocio'!$B$27),10),0) -> 930 | T11: =P11-M11 -> 135.19855 | U11: =IFERROR(E11/P11,0) -> 0.24008064
A12: 7 | B12: Vampiro de Tlaquepaque con Sangrita Casera de Tomate y Naranja | C12: T-1 | D12: 6 | E12: =SUMIF(Ingredientes!$A:$A,$A12,Ingredientes!$H:$H) -> 56.672416 | F12: ='Mi negocio'!$B$10 -> 2.5 | G12: ='Mi negocio'!$B$11 -> 1.8 | H12: 2 | I12: =H12/60*'Mi negocio'!$B$19 -> 2.5 | J12: ='Mi negocio'!$B$18 -> 15 | K12: =E12+F12+G12+I12+J12 -> 78.472416 | L12: ='Mi negocio'!$B$12 -> 0.08 | M12: =IFERROR(K12/(1-L12),0) -> 85.296105 | N12: 24 | O12: =IFERROR(N12/'Mi negocio'!$B$15,0) -> 1.4545455 | P12: =IFERROR(CEILING(M12/(1-'Mi negocio'!$B$24),5),0) -> 225 | Q12: =IFERROR(CEILING(M12/(1-'Mi negocio'!$B$25),5),0) -> 270 | R12: =IFERROR(CEILING(M12/(1-'Mi negocio'!$B$26),5),0) -> 190 | S12: =IFERROR(CEILING((M12*'Mi negocio'!$B$13+'Mi negocio'!$B$14)/(1-'Mi negocio'!$B$27),10),0) -> 990 | T12: =P12-M12 -> 139.7039 | U12: =IFERROR(E12/P12,0) -> 0.25187741
A13: 8 | B13: Matador Clásico | C13: T-2 | D13: 6 | E13: =SUMIF(Ingredientes!$A:$A,$A13,Ingredientes!$H:$H) -> 38.53 | F13: ='Mi negocio'!$B$10 -> 2.5 | G13: ='Mi negocio'!$B$11 -> 1.8 | H13: 3 | I13: =H13/60*'Mi negocio'!$B$19 -> 3.75 | J13: ='Mi negocio'!$B$18 -> 15 | K13: =E13+F13+G13+I13+J13 -> 61.58 | L13: ='Mi negocio'!$B$12 -> 0.08 | M13: =IFERROR(K13/(1-L13),0) -> 66.934783 | N13: 24 | O13: =IFERROR(N13/'Mi negocio'!$B$15,0) -> 1.4545455 | P13: =IFERROR(CEILING(M13/(1-'Mi negocio'!$B$24),5),0) -> 180 | Q13: =IFERROR(CEILING(M13/(1-'Mi negocio'!$B$25),5),0) -> 210 | R13: =IFERROR(CEILING(M13/(1-'Mi negocio'!$B$26),5),0) -> 150 | S13: =IFERROR(CEILING((M13*'Mi negocio'!$B$13+'Mi negocio'!$B$14)/(1-'Mi negocio'!$B$27),10),0) -> 790 | T13: =P13-M13 -> 113.06522 | U13: =IFERROR(E13/P13,0) -> 0.21405556
A14: 9 | B14: Tequila Sour con Clara Pasteurizada y Tintura de Angostura | C14: T-5 | D14: 6 | E14: =SUMIF(Ingredientes!$A:$A,$A14,Ingredientes!$H:$H) -> 47.96 | F14: ='Mi negocio'!$B$10 -> 2.5 | G14: ='Mi negocio'!$B$11 -> 1.8 | H14: 4 | I14: =H14/60*'Mi negocio'!$B$19 -> 5 | J14: ='Mi negocio'!$B$18 -> 15 | K14: =E14+F14+G14+I14+J14 -> 72.26 | L14: ='Mi negocio'!$B$12 -> 0.08 | M14: =IFERROR(K14/(1-L14),0) -> 78.543478 | N14: 24.07 | O14: =IFERROR(N14/'Mi negocio'!$B$15,0) -> 1.4587879 | P14: =IFERROR(CEILING(M14/(1-'Mi negocio'!$B$24),5),0) -> 210 | Q14: =IFERROR(CEILING(M14/(1-'Mi negocio'!$B$25),5),0) -> 250 | R14: =IFERROR(CEILING(M14/(1-'Mi negocio'!$B$26),5),0) -> 175 | S14: =IFERROR(CEILING((M14*'Mi negocio'!$B$13+'Mi negocio'!$B$14)/(1-'Mi negocio'!$B$27),10),0) -> 910 | T14: =P14-M14 -> 131.45652 | U14: =IFERROR(E14/P14,0) -> 0.22838095
A15: 10 | B15: Mezcalita de Cítricos Ahumados con Escarchado de Sal de Gusano | C15: T-2 | D15: 7 | E15: =SUMIF(Ingredientes!$A:$A,$A15,Ingredientes!$H:$H) -> 90.020714 | F15: ='Mi negocio'!$B$10 -> 2.5 | G15: ='Mi negocio'!$B$11 -> 1.8 | H15: 3 | I15: =H15/60*'Mi negocio'!$B$19 -> 3.75 | J15: ='Mi negocio'!$B$18 -> 15 | K15: =E15+F15+G15+I15+J15 -> 113.07071 | L15: ='Mi negocio'!$B$12 -> 0.08 | M15: =IFERROR(K15/(1-L15),0) -> 122.90295 | N15: 37 | O15: =IFERROR(N15/'Mi negocio'!$B$15,0) -> 2.2424242 | P15: =IFERROR(CEILING(M15/(1-'Mi negocio'!$B$24),5),0) -> 325 | Q15: =IFERROR(CEILING(M15/(1-'Mi negocio'!$B$25),5),0) -> 385 | R15: =IFERROR(CEILING(M15/(1-'Mi negocio'!$B$26),5),0) -> 275 | S15: =IFERROR(CEILING((M15*'Mi negocio'!$B$13+'Mi negocio'!$B$14)/(1-'Mi negocio'!$B$27),10),0) -> 1400 | T15: =P15-M15 -> 202.09705 | U15: =IFERROR(E15/P15,0) -> 0.27698681
A16: 11 | B16: Oaxaca Old Fashioned | C16: T-3 | D16: 7 | E16: =SUMIF(Ingredientes!$A:$A,$A16,Ingredientes!$H:$H) -> 48.6505 | F16: ='Mi negocio'!$B$10 -> 2.5 | G16: ='Mi negocio'!$B$11 -> 1.8 | H16: 3 | I16: =H16/60*'Mi negocio'!$B$19 -> 3.75 | J16: ='Mi negocio'!$B$18 -> 15 | K16: =E16+F16+G16+I16+J16 -> 71.7005 | L16: ='Mi negocio'!$B$12 -> 0.08 | M16: =IFERROR(K16/(1-L16),0) -> 77.935326 | N16: 25.73 | O16: =IFERROR(N16/'Mi negocio'!$B$15,0) -> 1.5593939 | P16: =IFERROR(CEILING(M16/(1-'Mi negocio'!$B$24),5),0) -> 210 | Q16: =IFERROR(CEILING(M16/(1-'Mi negocio'!$B$25),5),0) -> 245 | R16: =IFERROR(CEILING(M16/(1-'Mi negocio'!$B$26),5),0) -> 175 | S16: =IFERROR(CEILING((M16*'Mi negocio'!$B$13+'Mi negocio'!$B$14)/(1-'Mi negocio'!$B$27),10),0) -> 910 | T16: =P16-M16 -> 132.06467 | U16: =IFERROR(E16/P16,0) -> 0.23166905
A17: 12 | B17: Naked and Famous | C17: T-2 | D17: 7 | E17: =SUMIF(Ingredientes!$A:$A,$A17,Ingredientes!$H:$H) -> 81.603571 | F17: ='Mi negocio'!$B$10 -> 2.5 | G17: ='Mi negocio'!$B$11 -> 1.8 | H17: 3 | I17: =H17/60*'Mi negocio'!$B$19 -> 3.75 | J17: ='Mi negocio'!$B$18 -> 15 | K17: =E17+F17+G17+I17+J17 -> 104.65357 | L17: ='Mi negocio'!$B$12 -> 0.08 | M17: =IFERROR(K17/(1-L17),0) -> 113.75388 | N17: 22.27 | O17: =IFERROR(N17/'Mi negocio'!$B$15,0) -> 1.349697 | P17: =IFERROR(CEILING(M17/(1-'Mi negocio'!$B$24),5),0) -> 300 | Q17: =IFERROR(CEILING(M17/(1-'Mi negocio'!$B$25),5),0) -> 360 | R17: =IFERROR(CEILING(M17/(1-'Mi negocio'!$B$26),5),0) -> 255 | S17: =IFERROR(CEILING((M17*'Mi negocio'!$B$13+'Mi negocio'!$B$14)/(1-'Mi negocio'!$B$27),10),0) -> 1300 | T17: =P17-M17 -> 186.24612 | U17: =IFERROR(E17/P17,0) -> 0.2720119
... A56: 51 | B56: Niebla Sagrada (Mezcal, Pepino, Jarabe de Romero y Copal) | C56: T-6 | D56: 11 | E56: =SUMIF(Ingredientes!$A:$A,$A56,Ingredientes!$H:$H) -> 126.318 | F56: ='Mi negocio'!$B$10 -> 2.5 | G56: ='Mi negocio'!$B$11 -> 1.8 | H56: 6 | I56: =H56/60*'Mi negocio'!$B$19 -> 7.5 | J56: ='Mi negocio'!$B$18 -> 15 | K56: =E56+F56+G56+I56+J56 -> 153.118 | L56: ='Mi negocio'!$B$12 -> 0.08 | M56: =IFERROR(K56/(1-L56),0) -> 166.43261 | N56: 28.8 | O56: =IFERROR(N56/'Mi negocio'!$B$15,0) -> 1.7454545 | P56: =IFERROR(CEILING(M56/(1-'Mi negocio'!$B$24),5),0) -> 440 | Q56: =IFERROR(CEILING(M56/(1-'Mi negocio'!$B$25),5),0) -> 525 | R56: =IFERROR(CEILING(M56/(1-'Mi negocio'!$B$26),5),0) -> 370 | S56: =IFERROR(CEILING((M56*'Mi negocio'!$B$13+'Mi negocio'!$B$14)/(1-'Mi negocio'!$B$27),10),0) -> 1870 | T56: =P56-M56 -> 273.56739 | U56: =IFERROR(E56/P56,0) -> 0.28708636
B58: PROMEDIO | E58: =AVERAGE(E6:E56) -> 56.651964 | M58: =AVERAGE(M6:M56) -> 87.485084 | N58: =AVERAGE(N6:N56) -> 22.875098 | O58: =AVERAGE(O6:O56) -> 1.3863696 | P58: =AVERAGE(P6:P56) -> 232.84314 | Q58: =AVERAGE(Q6:Q56) -> 276.07843 | R58: =AVERAGE(R6:R56) -> 196.56863 | S58: =AVERAGE(S6:S56) -> 1010.3922 | T58: =AVERAGE(T6:T56) -> 145.35805 | U58: =AVERAGE(U6:U56) -> 0.23663144
B60: Costo de vertido sano: 18 a 25 %. En rojo, arriba de 30 %. En rojo también los tragos de más de 2.5 copas estándar. Cifras ilustrativas.

Sheet Producción
A1: PRODUCCIÓN Y COTIZACIÓN
A2: Plan del mes o cotización de un evento. Escribe cuántos tragos de cada ficha (columna amarilla) y el resto se calcula.
A3: Endulcora · Estudio Gastronómico · en colaboración con Levent
A5: # | B5: Ficha | C5: Tragos a servir | D5: Costo insumos | E5: Costo total | F5: Minutos de barra | G5: Horas | H5: Ingreso en barra | I5: Ingreso en evento | J5: Utilidad en barra | K5: Copas servidas
A6: 1 | B6: Margarita Clásica 1942 | C6: 0 | D6: =C6*'Fichas y precios'!E6 -> 0 | E6: =C6*'Fichas y precios'!M6 -> 0 | F6: =C6*'Fichas y precios'!H6 -> 0 | G6: =F6/60 -> 0 | H6: =C6*'Fichas y precios'!P6 -> 0 | I6: =C6*'Fichas y precios'!R6 -> 0 | J6: =H6-E6 -> 0 | K6: =C6*'Fichas y precios'!O6 -> 0
A7: 2 | B7: Paloma Tradicional con Refresco de Toronja Artesanal y Sal de Colima | C7: 0 | D7: =C7*'Fichas y precios'!E7 -> 0 | E7: =C7*'Fichas y precios'!M7 -> 0 | F7: =C7*'Fichas y precios'!H7 -> 0 | G7: =F7/60 -> 0 | H7: =C7*'Fichas y precios'!P7 -> 0 | I7: =C7*'Fichas y precios'!R7 -> 0 | J7: =H7-E7 -> 0 | K7: =C7*'Fichas y precios'!O7 -> 0
A8: 3 | B8: Tequila Sunrise Estilo Cantina Clásica | C8: 0 | D8: =C8*'Fichas y precios'!E8 -> 0 | E8: =C8*'Fichas y precios'!M8 -> 0 | F8: =C8*'Fichas y precios'!H8 -> 0 | G8: =F8/60 -> 0 | H8: =C8*'Fichas y precios'!P8 -> 0 | I8: =C8*'Fichas y precios'!R8 -> 0 | J8: =H8-E8 -> 0 | K8: =C8*'Fichas y precios'!O8 -> 0
A9: 4 | B9: Tommy’s Margarita | C9: 0 | D9: =C9*'Fichas y precios'!E9 -> 0 | E9: =C9*'Fichas y precios'!M9 -> 0 | F9: =C9*'Fichas y precios'!H9 -> 0 | G9: =F9/60 -> 0 | H9: =C9*'Fichas y precios'!P9 -> 0 | I9: =C9*'Fichas y precios'!R9 -> 0 | J9: =H9-E9 -> 0 | K9: =C9*'Fichas y precios'!O9 -> 0
A10: 5 | B10: Batanga de Tequila Reposado, Refresco de Cola y Sal en Navaja | C10: 0 | D10: =C10*'Fichas y precios'!E10 -> 0 | E10: =C10*'Fichas y precios'!M10 -> 0 | F10: =C10*'Fichas y precios'!H10 -> 0 | G10: =F10/60 -> 0 | H10: =C10*'Fichas y precios'!P10 -> 0 | I10: =C10*'Fichas y precios'!R10 -> 0 | J10: =H10-E10 -> 0 | K10: =C10*'Fichas y precios'!O10 -> 0
A11: 6 | B11: Charro Negro Clásico al Limón Criollo | C11: 0 | D11: =C11*'Fichas y precios'!E11 -> 0 | E11: =C11*'Fichas y precios'!M11 -> 0 | F11: =C11*'Fichas y precios'!H11 -> 0 | G11: =F11/60 -> 0 | H11: =C11*'Fichas y precios'!P11 -> 0 | I11: =C11*'Fichas y precios'!R11 -> 0 | J11: =H11-E11 -> 0 | K11: =C11*'Fichas y precios'!O11 -> 0
A12: 7 | B12: Vampiro de Tlaquepaque con Sangrita Casera de Tomate y Naranja | C12: 0 | D12: =C12*'Fichas y precios'!E12 -> 0 | E12: =C12*'Fichas y precios'!M12 -> 0 | F12: =C12*'Fichas y precios'!H12 -> 0 | G12: =F12/60 -> 0 | H12: =C12*'Fichas y precios'!P12 -> 0 | I12: =C12*'Fichas y precios'!R12 -> 0 | J12: =H12-E12 -> 0 | K12: =C12*'Fichas y precios'!O12 -> 0
A13: 8 | B13: Matador Clásico | C13: 0 | D13: =C13*'Fichas y precios'!E13 -> 0 | E13: =C13*'Fichas y precios'!M13 -> 0 | F13: =C13*'Fichas y precios'!H13 -> 0 | G13: =F13/60 -> 0 | H13: =C13*'Fichas y precios'!P13 -> 0 | I13: =C13*'Fichas y precios'!R13 -> 0 | J13: =H13-E13 -> 0 | K13: =C13*'Fichas y precios'!O13 -> 0
A14: 9 | B14: Tequila Sour con Clara Pasteurizada y Tintura de Angostura | C14: 0 | D14: =C14*'Fichas y precios'!E14 -> 0 | E14: =C14*'Fichas y precios'!M14 -> 0 | F14: =C14*'Fichas y precios'!H14 -> 0 | G14: =F14/60 -> 0 | H14: =C14*'Fichas y precios'!P14 -> 0 | I14: =C14*'Fichas y precios'!R14 -> 0 | J14: =H14-E14 -> 0 | K14: =C14*'Fichas y precios'!O14 -> 0
A15: 10 | B15: Mezcalita de Cítricos Ahumados con Escarchado de Sal de Gusano | C15: 0 | D15: =C15*'Fichas y precios'!E15 -> 0 | E15: =C15*'Fichas y precios'!M15 -> 0 | F15: =C15*'Fichas y precios'!H15 -> 0 | G15: =F15/60 -> 0 | H15: =C15*'Fichas y precios'!P15 -> 0 | I15: =C15*'Fichas y precios'!R15 -> 0 | J15: =H15-E15 -> 0 | K15: =C15*'Fichas y precios'!O15 -> 0
A16: 11 | B16: Oaxaca Old Fashioned | C16: 0 | D16: =C16*'Fichas y precios'!E16 -> 0 | E16: =C16*'Fichas y precios'!M16 -> 0 | F16: =C16*'Fichas y precios'!H16 -> 0 | G16: =F16/60 -> 0 | H16: =C16*'Fichas y precios'!P16 -> 0 | I16: =C16*'Fichas y precios'!R16 -> 0 | J16: =H16-E16 -> 0 | K16: =C16*'Fichas y precios'!O16 -> 0
A17: 12 | B17: Naked and Famous | C17: 0 | D17: =C17*'Fichas y precios'!E17 -> 0 | E17: =C17*'Fichas y precios'!M17 -> 0 | F17: =C17*'Fichas y precios'!H17 -> 0 | G17: =F17/60 -> 0 | H17: =C17*'Fichas y precios'!P17 -> 0 | I17: =C17*'Fichas y precios'!R17 -> 0 | J17: =H17-E17 -> 0 | K17: =C17*'Fichas y precios'!O17 -> 0
... A56: 51 | B56: Niebla Sagrada (Mezcal, Pepino, Jarabe de Romero y Copal) | C56: 0 | D56: =C56*'Fichas y precios'!E56 -> 0 | E56: =C56*'Fichas y precios'!M56 -> 0 | F56: =C56*'Fichas y precios'!H56 -> 0 | G56: =F56/60 -> 0 | H56: =C56*'Fichas y precios'!P56 -> 0 | I56: =C56*'Fichas y precios'!R56 -> 0 | J56: =H56-E56 -> 0 | K56: =C56*'Fichas y precios'!O56 -> 0
B57: TOTAL | C57: =SUM(C6:C56) -> 0 | D57: =SUM(D6:D56) -> 0 | E57: =SUM(E6:E56) -> 0 | F57: =SUM(F6:F56) -> 0 | G57: =SUM(G6:G56) -> 0 | H57: =SUM(H6:H56) -> 0 | I57: =SUM(I6:I56) -> 0 | J57: =SUM(J6:J56) -> 0 | K57: =SUM(K6:K56) -> 0
B59: Para cotizar un evento: sube la merma de «Mi negocio» a 15-20 % antes de calcular. En barra libre se sirve y se derrama mucho más que en barra propia.
B60: La columna «Copas servidas» es el total de copas estándar del plan. Úsala para dimensionar el servicio responsable del Capítulo 15.

Sheet Ventas
A1: VENTAS
A2: Registra cada venta. Elige la ficha por número y el canal de la lista; el precio y la utilidad salen solos.
A3: Endulcora · Estudio Gastronómico · en colaboración con Levent | H3: TOTALES
G4: =SUM(G6:G305) -> 0 | I4: =SUM(I6:I305) -> 0 | J4: =SUM(J6:J305) -> 0
A5: Fecha | B5: # ficha | C5: Ficha | D5: Canal | E5: Unidades | F5: Precio unitario | G5: Ingreso | H5: Costo unitario | I5: Costo total | J5: Utilidad | K5: Margen | L5: Nota
C6: =IF($B6="","",IFERROR(VLOOKUP($B6,'Fichas y precios'!$A:$B,2,FALSE()),"")) | F6: =IF(OR($B6="",$D6=""),"",IFERROR(INDEX('Fichas y precios'!$P:$S,MATCH($B6,'Fichas y precios'!$A:$A,0),MATCH($D6,'Fichas y precios'!$P$5:$S$5,0)),"")) | G6: =IFERROR($E6*$F6,"") | H6: =IF($B6="","",IF($D6="Batch embotellado",IFERROR(VLOOKUP($B6,'Fichas y precios'!$A:$M,13,FALSE())*'Mi negocio'!$B$13+'Mi negocio'!$B$14,""),IFERROR(VLOOKUP($B6,'Fichas y precios'!$A:$M,13,FALSE()),""))) | I6: =IFERROR($E6*$H6,"") | J6: =IFERROR($G6-$I6,"") | K6: =IFERROR($J6/$G6,"")
C7: =IF($B7="","",IFERROR(VLOOKUP($B7,'Fichas y precios'!$A:$B,2,FALSE()),"")) | F7: =IF(OR($B7="",$D7=""),"",IFERROR(INDEX('Fichas y precios'!$P:$S,MATCH($B7,'Fichas y precios'!$A:$A,0),MATCH($D7,'Fichas y precios'!$P$5:$S$5,0)),"")) | G7: =IFERROR($E7*$F7,"") | H7: =IF($B7="","",IF($D7="Batch embotellado",IFERROR(VLOOKUP($B7,'Fichas y precios'!$A:$M,13,FALSE())*'Mi negocio'!$B$13+'Mi negocio'!$B$14,""),IFERROR(VLOOKUP($B7,'Fichas y precios'!$A:$M,13,FALSE()),""))) | I7: =IFERROR($E7*$H7,"") | J7: =IFERROR($G7-$I7,"") | K7: =IFERROR($J7/$G7,"")
C8: =IF($B8="","",IFERROR(VLOOKUP($B8,'Fichas y precios'!$A:$B,2,FALSE()),"")) | F8: =IF(OR($B8="",$D8=""),"",IFERROR(INDEX('Fichas y precios'!$P:$S,MATCH($B8,'Fichas y precios'!$A:$A,0),MATCH($D8,'Fichas y precios'!$P$5:$S$5,0)),"")) | G8: =IFERROR($E8*$F8,"") | H8: =IF($B8="","",IF($D8="Batch embotellado",IFERROR(VLOOKUP($B8,'Fichas y precios'!$A:$M,13,FALSE())*'Mi negocio'!$B$13+'Mi negocio'!$B$14,""),IFERROR(VLOOKUP($B8,'Fichas y precios'!$A:$M,13,FALSE()),""))) | I8: =IFERROR($E8*$H8,"") | J8: =IFERROR($G8-$I8,"") | K8: =IFERROR($J8/$G8,"")
C9: =IF($B9="","",IFERROR(VLOOKUP($B9,'Fichas y precios'!$A:$B,2,FALSE()),"")) | F9: =IF(OR($B9="",$D9=""),"",IFERROR(INDEX('Fichas y precios'!$P:$S,MATCH($B9,'Fichas y precios'!$A:$A,0),MATCH($D9,'Fichas y precios'!$P$5:$S$5,0)),"")) | G9: =IFERROR($E9*$F9,"") | H9: =IF($B9="","",IF($D9="Batch embotellado",IFERROR(VLOOKUP($B9,'Fichas y precios'!$A:$M,13,FALSE())*'Mi negocio'!$B$13+'Mi negocio'!$B$14,""),IFERROR(VLOOKUP($B9,'Fichas y precios'!$A:$M,13,FALSE()),""))) | I9: =IFERROR($E9*$H9,"") | J9: =IFERROR($G9-$I9,"") | K9: =IFERROR($J9/$G9,"")
C10: =IF($B10="","",IFERROR(VLOOKUP($B10,'Fichas y precios'!$A:$B,2,FALSE()),"")) | F10: =IF(OR($B10="",$D10=""),"",IFERROR(INDEX('Fichas y precios'!$P:$S,MATCH($B10,'Fichas y precios'!$A:$A,0),MATCH($D10,'Fichas y precios'!$P$5:$S$5,0)),"")) | G10: =IFERROR($E10*$F10,"") | H10: =IF($B10="","",IF($D10="Batch embotellado",IFERROR(VLOOKUP($B10,'Fichas y precios'!$A:$M,13,FALSE())*'Mi negocio'!$B$13+'Mi negocio'!$B$14,""),IFERROR(VLOOKUP($B10,'Fichas y precios'!$A:$M,13,FALSE()),""))) | I10: =IFERROR($E10*$H10,"") | J10: =IFERROR($G10-$I10,"") | K10: =IFERROR($J10/$G10,"")
C11: =IF($B11="","",IFERROR(VLOOKUP($B11,'Fichas y precios'!$A:$B,2,FALSE()),"")) | F11: =IF(OR($B11="",$D11=""),"",IFERROR(INDEX('Fichas y precios'!$P:$S,MATCH($B11,'Fichas y precios'!$A:$A,0),MATCH($D11,'Fichas y precios'!$P$5:$S$5,0)),"")) | G11: =IFERROR($E11*$F11,"") | H11: =IF($B11="","",IF($D11="Batch embotellado",IFERROR(VLOOKUP($B11,'Fichas y precios'!$A:$M,13,FALSE())*'Mi negocio'!$B$13+'Mi negocio'!$B$14,""),IFERROR(VLOOKUP($B11,'Fichas y precios'!$A:$M,13,FALSE()),""))) | I11: =IFERROR($E11*$H11,"") | J11: =IFERROR($G11-$I11,"") | K11: =IFERROR($J11/$G11,"")
C12: =IF($B12="","",IFERROR(VLOOKUP($B12,'Fichas y precios'!$A:$B,2,FALSE()),"")) | F12: =IF(OR($B12="",$D12=""),"",IFERROR(INDEX('Fichas y precios'!$P:$S,MATCH($B12,'Fichas y precios'!$A:$A,0),MATCH($D12,'Fichas y precios'!$P$5:$S$5,0)),"")) | G12: =IFERROR($E12*$F12,"") | H12: =IF($B12="","",IF($D12="Batch embotellado",IFERROR(VLOOKUP($B12,'Fichas y precios'!$A:$M,13,FALSE())*'Mi negocio'!$B$13+'Mi negocio'!$B$14,""),IFERROR(VLOOKUP($B12,'Fichas y precios'!$A:$M,13,FALSE()),""))) | I12: =IFERROR($E12*$H12,"") | J12: =IFERROR($G12-$I12,"") | K12: =IFERROR($J12/$G12,"")
C13: =IF($B13="","",IFERROR(VLOOKUP($B13,'Fichas y precios'!$A:$B,2,FALSE()),"")) | F13: =IF(OR($B13="",$D13=""),"",IFERROR(INDEX('Fichas y precios'!$P:$S,MATCH($B13,'Fichas y precios'!$A:$A,0),MATCH($D13,'Fichas y precios'!$P$5:$S$5,0)),"")) | G13: =IFERROR($E13*$F13,"") | H13: =IF($B13="","",IF($D13="Batch embotellado",IFERROR(VLOOKUP($B13,'Fichas y precios'!$A:$M,13,FALSE())*'Mi negocio'!$B$13+'Mi negocio'!$B$14,""),IFERROR(VLOOKUP($B13,'Fichas y precios'!$A:$M,13,FALSE()),""))) | I13: =IFERROR($E13*$H13,"") | J13: =IFERROR($G13-$I13,"") | K13: =IFERROR($J13/$G13,"")
C14: =IF($B14="","",IFERROR(VLOOKUP($B14,'Fichas y precios'!$A:$B,2,FALSE()),"")) | F14: =IF(OR($B14="",$D14=""),"",IFERROR(INDEX('Fichas y precios'!$P:$S,MATCH($B14,'Fichas y precios'!$A:$A,0),MATCH($D14,'Fichas y precios'!$P$5:$S$5,0)),"")) | G14: =IFERROR($E14*$F14,"") | H14: =IF($B14="","",IF($D14="Batch embotellado",IFERROR(VLOOKUP($B14,'Fichas y precios'!$A:$M,13,FALSE())*'Mi negocio'!$B$13+'Mi negocio'!$B$14,""),IFERROR(VLOOKUP($B14,'Fichas y precios'!$A:$M,13,FALSE()),""))) | I14: =IFERROR($E14*$H14,"") | J14: =IFERROR($G14-$I14,"") | K14: =IFERROR($J14/$G14,"")
C15: =IF($B15="","",IFERROR(VLOOKUP($B15,'Fichas y precios'!$A:$B,2,FALSE()),"")) | F15: =IF(OR($B15="",$D15=""),"",IFERROR(INDEX('Fichas y precios'!$P:$S,MATCH($B15,'Fichas y precios'!$A:$A,0),MATCH($D15,'Fichas y precios'!$P$5:$S$5,0)),"")) | G15: =IFERROR($E15*$F15,"") | H15: =IF($B15="","",IF($D15="Batch embotellado",IFERROR(VLOOKUP($B15,'Fichas y precios'!$A:$M,13,FALSE())*'Mi negocio'!$B$13+'Mi negocio'!$B$14,""),IFERROR(VLOOKUP($B15,'Fichas y precios'!$A:$M,13,FALSE()),""))) | I15: =IFERROR($E15*$H15,"") | J15: =IFERROR($G15-$I15,"") | K15: =IFERROR($J15/$G15,"")
C16: =IF($B16="","",IFERROR(VLOOKUP($B16,'Fichas y precios'!$A:$B,2,FALSE()),"")) | F16: =IF(OR($B16="",$D16=""),"",IFERROR(INDEX('Fichas y precios'!$P:$S,MATCH($B16,'Fichas y precios'!$A:$A,0),MATCH($D16,'Fichas y precios'!$P$5:$S$5,0)),"")) | G16: =IFERROR($E16*$F16,"") | H16: =IF($B16="","",IF($D16="Batch embotellado",IFERROR(VLOOKUP($B16,'Fichas y precios'!$A:$M,13,FALSE())*'Mi negocio'!$B$13+'Mi negocio'!$B$14,""),IFERROR(VLOOKUP($B16,'Fichas y precios'!$A:$M,13,FALSE()),""))) | I16: =IFERROR($E16*$H16,"") | J16: =IFERROR($G16-$I16,"") | K16: =IFERROR($J16/$G16,"")
C17: =IF($B17="","",IFERROR(VLOOKUP($B17,'Fichas y precios'!$A:$B,2,FALSE()),"")) | F17: =IF(OR($B17="",$D17=""),"",IFERROR(INDEX('Fichas y precios'!$P:$S,MATCH($B17,'Fichas y precios'!$A:$A,0),MATCH($D17,'Fichas y precios'!$P$5:$S$5,0)),"")) | G17: =IFERROR($E17*$F17,"") | H17: =IF($B17="","",IF($D17="Batch embotellado",IFERROR(VLOOKUP($B17,'Fichas y precios'!$A:$M,13,FALSE())*'Mi negocio'!$B$13+'Mi negocio'!$B$14,""),IFERROR(VLOOKUP($B17,'Fichas y precios'!$A:$M,13,FALSE()),""))) | I17: =IFERROR($E17*$H17,"") | J17: =IFERROR($G17-$I17,"") | K17: =IFERROR($J17/$G17,"")
... C305: =IF($B305="","",IFERROR(VLOOKUP($B305,'Fichas y precios'!$A:$B,2,FALSE()),"")) | F305: =IF(OR($B305="",$D305=""),"",IFERROR(INDEX('Fichas y precios'!$P:$S,MATCH($B305,'Fichas y precios'!$A:$A,0),MATCH($D305,'Fichas y precios'!$P$5:$S$5,0)),"")) | G305: =IFERROR($E305*$F305,"") | H305: =IF($B305="","",IF($D305="Batch embotellado",IFERROR(VLOOKUP($B305,'Fichas y precios'!$A:$M,13,FALSE())*'Mi negocio'!$B$13+'Mi negocio'!$B$14,""),IFERROR(VLOOKUP($B305,'Fichas y precios'!$A:$M,13,FALSE()),""))) | I305: =IFERROR($E305*$H305,"") | J305: =IFERROR($G305-$I305,"") | K305: =IFERROR($J305/$G305,"")

Sheet Tablero
A1: TABLERO
A2: Resumen del modelo con tus números.
A3: Endulcora · Estudio Gastronómico · en colaboración con Levent | D3: LAS 51 FICHAS ORDENADAS POR COSTO DE INSUMOS
A5: Fichas costeadas | B5: =COUNT('Fichas y precios'!$A$6:$A$56) -> 51
A6: Insumos en catálogo | B6: =COUNTA(Insumos!$A$6:$A$126) -> 121 | D6: # | E6: Ficha | F6: Costo insumos | G6: Costo total | H6: Barra
A7: Líneas del manual normalizadas | B7: =COUNTA(Ingredientes!$A$6:$A$328) -> 323 | D7: 18 | E7: El Chamuco (Mezcal, Limón, Agave y Chile Pasilla Flameado) | F7: ='Fichas y precios'!E23 -> 128.55 | G7: ='Fichas y precios'!M23 -> 168.8587 | H7: ='Fichas y precios'!P23 -> 445
D8: 51 | E8: Niebla Sagrada (Mezcal, Pepino, Jarabe de Romero y Copal) | F8: ='Fichas y precios'!E56 -> 126.318 | G8: ='Fichas y precios'!M56 -> 166.43261 | H8: ='Fichas y precios'!P56 -> 440
A9: Costo de insumos promedio por trago | B9: =AVERAGE('Fichas y precios'!$E$6:$E$56) -> 56.651964 | D9: 10 | E9: Mezcalita de Cítricos Ahumados con Escarchado de Sal de Gusano | F9: ='Fichas y precios'!E15 -> 90.020714 | G9: ='Fichas y precios'!M15 -> 122.90295 | H9: ='Fichas y precios'!P15 -> 325
A10: Costo total promedio por trago | B10: =AVERAGE('Fichas y precios'!$M$6:$M$56) -> 87.485084 | D10: 24 | E10: Bacanora Sunrise con Granadina de Pitahaya Silvestre | F10: ='Fichas y precios'!E29 -> 84.295 | G10: ='Fichas y precios'!M29 -> 120.75543 | H10: ='Fichas y precios'!P29 -> 320
A11: Precio promedio · barra propia | B11: =AVERAGE('Fichas y precios'!$P$6:$P$56) -> 232.84314 | D11: 25 | E11: Raicilla Collins con Tónica Artesanal y Toronja | F11: ='Fichas y precios'!E30 -> 81.83 | G11: ='Fichas y precios'!M30 -> 114 | H11: ='Fichas y precios'!P30 -> 300
A12: Precio promedio · carta de restaurante | B12: =AVERAGE('Fichas y precios'!$Q$6:$Q$56) -> 276.07843 | D12: 12 | E12: Naked and Famous | F12: ='Fichas y precios'!E17 -> 81.603571 | G12: ='Fichas y precios'!M17 -> 113.75388 | H12: ='Fichas y precios'!P17 -> 300
A13: Utilidad promedio por trago en barra | B13: =AVERAGE('Fichas y precios'!$T$6:$T$56) -> 145.35805 | D13: 16 | E13: Mezcal Mule con Cerveza de Jengibre y Menta Fresca | F13: ='Fichas y precios'!E21 -> 77.560986 | G13: ='Fichas y precios'!M21 -> 108.00107 | H13: ='Fichas y precios'!P21 -> 285
A14: COSTO DE VERTIDO PROMEDIO | B14: =IFERROR(AVERAGE('Fichas y precios'!$E$6:$E$56)/AVERAGE('Fichas y precios'!$P$6:$P$56),0) -> 0.24330528 | D14: 1 | E14: Margarita Clásica 1942 | F14: ='Fichas y precios'!E6 -> 76.222857 | G14: ='Fichas y precios'!M6 -> 107.90528 | H14: ='Fichas y precios'!P6 -> 285
D15: 28 | E15: Tepache Spritz con Vino Espumoso y Tequila Blanco | F15: ='Fichas y precios'!E33 -> 74.616667 | G15: ='Fichas y precios'!M33 -> 104.80072 | H15: ='Fichas y precios'!P33 -> 280
A16: Alcohol servido promedio (ml de etanol) | B16: =AVERAGE('Fichas y precios'!$N$6:$N$56) -> 22.875098 | D16: 45 | E16: Acuyo Cóctel (Mezcal, Hoja Santa Licuada y Manzana Verde) | F16: ='Fichas y precios'!E50 -> 72.093333 | G16: ='Fichas y precios'!M50 -> 103.41667 | H16: ='Fichas y precios'!P50 -> 275
A17: Copas estándar promedio por trago | B17: =AVERAGE('Fichas y precios'!$O$6:$O$56) -> 1.3863696 | D17: 32 | E17: Tepache Ahumado con Mezcal Espadín y Escarcha de Sal de Tamarindo | F17: ='Fichas y precios'!E37 -> 72.027333 | G17: ='Fichas y precios'!M37 -> 101.98623 | H17: ='Fichas y precios'!P37 -> 270
A18: Trago más cargado del libro (copas) | B18: =MAX('Fichas y precios'!$O$6:$O$56) -> 2.4230303 | D18: 15 | E18: Mezcalita de Tamarindo Concentrado con Sal de Hormiga Chicatana | F18: ='Fichas y precios'!E20 -> 71.545 | G18: ='Fichas y precios'!M20 -> 102.82065 | H18: ='Fichas y precios'!P20 -> 275
A19: Fichas de más de 2 copas estándar | B19: =COUNTIF('Fichas y precios'!$O$6:$O$56,">2") -> 3 | D19: 47 | E19: Xocolatl Flip con Tequila Añejo, Huevo Entero y Cacao Puro | F19: ='Fichas y precios'!E52 -> 69.297143 | G19: ='Fichas y precios'!M52 -> 101.73602 | H19: ='Fichas y precios'!P52 -> 270
D20: 13 | E20: Smoky Paloma con Mezcal de Horno y Toronja Rosa | F20: ='Fichas y precios'!E18 -> 68.725493 | G20: ='Fichas y precios'!M18 -> 101.11467 | H20: ='Fichas y precios'!P18 -> 270
A21: Costo variable promedio por trago | B21: =AVERAGE('Fichas y precios'!$E$6:$E$56)+'Mi negocio'!$B$10+'Mi negocio'!$B$11 -> 60.951964 | D21: 23 | E21: Pox Maya con Infusión de Café de Olla y Naranja Dulce | F21: ='Fichas y precios'!E28 -> 68.369762 | G21: ='Fichas y precios'!M28 -> 99.369306 | H21: ='Fichas y precios'!P28 -> 265
A22: Contribución marginal por trago | B22: =B11-B21 -> 171.89117 | D22: 21 | E22: Raicilla Sour con Hoja Santa Fresca y Salvia | F22: ='Fichas y precios'!E26 -> 62.21 | G22: ='Fichas y precios'!M26 -> 94.032609 | H22: ='Fichas y precios'!P26 -> 250
A23: PUNTO DE EQUILIBRIO (tragos al mes) | B23: =IFERROR(CEILING('Mi negocio'!$B$6/B22,1),0) -> 105 | D23: 46 | E23: Verde Ancestral con Cilantro, Aguacate y Mezcal Blanc | F23: ='Fichas y precios'!E51 -> 61.485619 | G23: ='Fichas y precios'!M51 -> 93.245238 | H23: ='Fichas y precios'!P51 -> 250
A24: Punto de equilibrio (tragos al día, 26 días) | B24: =IFERROR(CEILING(B23/26,1),0) -> 5 | D24: 41 | E24: Submarino de Cantina (Tequila Invertido en Tarro Cervecero) | F24: ='Fichas y precios'!E46 -> 60.136 | G24: ='Fichas y precios'!M46 -> 94.495652 | H24: ='Fichas y precios'!P46 -> 250
D25: 40 | E25: Clamato Preparado estilo Sinaloa con Camarón Seco y Pepino | F25: ='Fichas y precios'!E45 -> 59.968316 | G25: ='Fichas y precios'!M45 -> 94.313387 | H25: ='Fichas y precios'!P45 -> 250
A26: Tragos planeados en «Producción» | B26: =Producción!C57 -> 0 | D26: 14 | E26: Mezcalita de Piña Tatemada al Comal y Chile Serrano | F26: ='Fichas y precios'!E19 -> 58.411 | G26: ='Fichas y precios'!M19 -> 89.903261 | H26: ='Fichas y precios'!P19 -> 240
A27: Costo total de ese plan | B27: =Producción!E57 -> 0 | D27: 50 | E27: Carajillo Mexicano de Altura con Licor Maya de Anís y Miel (Xtavento) | F27: ='Fichas y precios'!E55 -> 58.1275 | G27: ='Fichas y precios'!M55 -> 89.595109 | H27: ='Fichas y precios'!P55 -> 240
A28: Ingreso estimado en barra | B28: =Producción!H57 -> 0 | D28: 7 | E28: Vampiro de Tlaquepaque con Sangrita Casera de Tomate y Naranja | F28: ='Fichas y precios'!E12 -> 56.672416 | G28: ='Fichas y precios'!M12 -> 85.296105 | H28: ='Fichas y precios'!P12 -> 225
A29: Utilidad estimada | B29: =Producción!J57 -> 0 | D29: 22 | E29: Sotolita del Desierto Chihuahuense con Damiana y Romero | F29: ='Fichas y precios'!E27 -> 55.260833 | G29: ='Fichas y precios'!M27 -> 85.120471 | H29: ='Fichas y precios'!P27 -> 225
A30: Copas estándar del plan | B30: =Producción!K57 -> 0 | D30: 26 | E30: Sotol Negroni con Vermut Rosso y Bitter Rojo | F30: ='Fichas y precios'!E31 -> 55.088 | G30: ='Fichas y precios'!M31 -> 84.932609 | H30: ='Fichas y precios'!P31 -> 225
D31: 3 | E31: Tequila Sunrise Estilo Cantina Clásica | F31: ='Fichas y precios'!E8 -> 54.71 | G31: ='Fichas y precios'!M8 -> 88.597826 | H31: ='Fichas y precios'!P8 -> 235
A32: Ventas registradas · ingreso | B32: =Ventas!G4 -> 0 | D32: 5 | E32: Batanga de Tequila Reposado, Refresco de Cola y Sal en Navaja | F32: ='Fichas y precios'!E10 -> 53.375056 | G32: ='Fichas y precios'!M10 -> 83.070713 | H32: ='Fichas y precios'!P10 -> 220
A33: Ventas registradas · utilidad | B33: =Ventas!J4 -> 0 | D33: 44 | E33: Habanero Mango Smash con Tequila Reposado y Menta | F33: ='Fichas y precios'!E49 -> 53.175 | G33: ='Fichas y precios'!M49 -> 84.211957 | H33: ='Fichas y precios'!P49 -> 225
D34: 6 | E34: Charro Negro Clásico al Limón Criollo | F34: ='Fichas y precios'!E11 -> 51.617338 | G34: ='Fichas y precios'!M11 -> 79.801454 | H34: ='Fichas y precios'!P11 -> 215
D35: 27 | E35: Ponche de Charanda Añejo con Guayaba y Especias de Olla | F35: ='Fichas y precios'!E32 -> 50.435 | G35: ='Fichas y precios'!M32 -> 83.951087 | H35: ='Fichas y precios'!P32 -> 225
D36: 2 | E36: Paloma Tradicional con Refresco de Toronja Artesanal y Sal de Colima | F36: ='Fichas y precios'!E7 -> 48.953901 | G36: ='Fichas y precios'!M7 -> 76.906415 | H36: ='Fichas y precios'!P7 -> 205
D37: 11 | E37: Oaxaca Old Fashioned | F37: ='Fichas y precios'!E16 -> 48.6505 | G37: ='Fichas y precios'!M16 -> 77.935326 | H37: ='Fichas y precios'!P16 -> 210
D38: 9 | E38: Tequila Sour con Clara Pasteurizada y Tintura de Angostura | F38: ='Fichas y precios'!E14 -> 47.96 | G38: ='Fichas y precios'!M14 -> 78.543478 | H38: ='Fichas y precios'!P14 -> 210
D39: 17 | E39: Sangre Oaxaqueña (Mezcal, Betabel Asado y Naranja) | F39: ='Fichas y precios'!E22 -> 47.766333 | G39: ='Fichas y precios'!M22 -> 76.974275 | H39: ='Fichas y precios'!P22 -> 205
D40: 33 | E40: Tejuino Rústico con Nieve de Mango y Piquín Artesanal | F40: ='Fichas y precios'!E38 -> 46.811 | G40: ='Fichas y precios'!M38 -> 77.294565 | H40: ='Fichas y precios'!P38 -> 205
D41: 4 | E41: Tommy’s Margarita | F41: ='Fichas y precios'!E9 -> 45.43775 | G41: ='Fichas y precios'!M9 -> 74.443207 | H41: ='Fichas y precios'!P9 -> 200
...
