Workbook

Sheet INICIO
A1: ENDULCORA · ESTUDIO GASTRONÓMICO
A2: Sistema de Costeo y Producción
A3: Herramienta complementaria del eBook «Galletas Estilo Nueva York» · Colección Oficios Dulces de Endulcora · Volumen II
B6: ¿QUÉ HACE ESTE ARCHIVO?
B7: Calcula automáticamente el costo real, el precio de venta y la utilidad de las 50 recetas del libro. Solo cambias los precios de tus ingredientes y TODO el sistema se actualiza solo: las 50 recetas, la lista de compras, el plan de producción y tu punto de equilibrio.
B9: CÓMO USARLO EN 5 PASOS
B10: PASO 1 · Hoja «1. INSUMOS» | C10: Actualiza el precio de compra y la presentación de cada ingrediente con TUS precios reales. Es lo único obligatorio.
B11: PASO 2 · Hoja «PANEL» | C11: Define tus parámetros: empaque, energía, tu costo por hora, merma, gastos fijos y los márgenes que quieres ganar.
B12: PASO 3 · Hoja «3. COSTEO» | C12: Consulta el costo y el precio sugerido de las 50 recetas, ya calculados. No escribas nada aquí: todo es automático.
B13: PASO 4 · Hoja «4. PRODUCCIÓN» | C13: Elige qué recetas vas a hornear y cuántos lotes. La hoja «5. COMPRAS» arma sola tu lista de mercado con cantidades y costo.
B14: PASO 5 · Hojas «6. VENTAS» y «7. RENTABILIDAD» | C14: Registra cada venta y mira tu utilidad real; después revisa cuántas piezas necesitas vender al mes para no perder dinero.
B16: CÓDIGO DE COLORES
B17: Celda amarilla, texto azul | C17: Tú escribes aquí. Son los únicos datos que debes capturar.
B18: Texto negro | C18: Fórmula automática. No la borres ni la sobreescribas.
B19: Texto verde | C19: Dato que viene de otra hoja (normalmente del PANEL). Puedes sobreescribirlo si esa receta es una excepción.
B20: Fondo morado | C20: Encabezado de tabla.
B22: IMPORTANTE SOBRE LOS PRECIOS PRECARGADOS
B23: Los precios de la hoja «1. INSUMOS» son ESTIMACIONES de referencia de mercado en Ciudad de México cargadas para que el archivo funcione desde el primer minuto. NO son cotizaciones: sustitúyelos por tus precios reales de proveedor antes de fijar precios de venta. Las 50 recetas y sus gramajes provienen textualmente del recetario maestro del eBook.
B25: Endulcora · Estudio Gastronómico | Chef y creador de recetas: Luis Alfonso Jiménez Cárdenas | Editor y creador de contenido: Manuel Ramiro Justo Guzmán | Contacto y talleres: 5665271901

Sheet PANEL
A1: ENDULCORA · ESTUDIO GASTRONÓMICO
A2: Panel de control
A3: Cambia aquí tus parámetros de negocio: todas las hojas se recalculan solas.
B6: ① PARÁMETROS GLOBALES | E6: ② CALCULADORA RÁPIDA DE UNA RECETA
B7: Costo de empaque por pieza (caja, base, etiqueta) | C7: 6 | E7: Elige una receta ▼ | F7: Galleta de Chispas de Chocolate Semiamargo con Sal de Mar
B8: Energía por pieza (prorrateo de horno) | C8: 2
B9: Tu costo de mano de obra por hora | C9: 80 | E9: Receta N.º | F9: =IFERROR(INDEX('3. COSTEO'!$A$8:$A$57,MATCH($F$7,'3. COSTEO'!$B$8:$B$57,0)),"") -> 1
B10: Piezas que produces por hora | C10: 20 | E10: Línea del recetario | F10: =IFERROR(INDEX('3. COSTEO'!$C$8:$C$57,MATCH($F$7,'3. COSTEO'!$B$8:$B$57,0)),"") -> Cap. 5 · Clásicos de Nueva York
B11: → Mano de obra por pieza | C11: =IF(C10=0,0,C9/C10) -> 4 | E11: Rendimiento (piezas por lote) | F11: =IFERROR(INDEX('3. COSTEO'!$D$8:$D$57,MATCH($F$7,'3. COSTEO'!$B$8:$B$57,0)),"") -> 6
B12: % de merma (piezas falladas y desperdicio) | C12: 0.08 | E12: Costo de insumos del lote completo | F12: =IFERROR(INDEX('3. COSTEO'!$E$8:$E$57,MATCH($F$7,'3. COSTEO'!$B$8:$B$57,0)),"") -> 120.03
B13: Gastos fijos del mes (renta, luz, limpieza, equipo) | C13: 4000 | E13: Costo de insumos por pieza | F13: =IFERROR(INDEX('3. COSTEO'!$F$8:$F$57,MATCH($F$7,'3. COSTEO'!$B$8:$B$57,0)),"") -> 20.005
B14: Piezas que produces al mes | C14: 400 | E14: + Empaque | F14: =IFERROR(INDEX('3. COSTEO'!$G$8:$G$57,MATCH($F$7,'3. COSTEO'!$B$8:$B$57,0)),"") -> 6
B15: → Overhead por pieza | C15: =IF(C14=0,0,C13/C14) -> 10 | E15: + Energía | F15: =IFERROR(INDEX('3. COSTEO'!$H$8:$H$57,MATCH($F$7,'3. COSTEO'!$B$8:$B$57,0)),"") -> 2
B16: Margen deseado en MENUDEO | C16: 0.6 | E16: + Mano de obra | F16: =IFERROR(INDEX('3. COSTEO'!$I$8:$I$57,MATCH($F$7,'3. COSTEO'!$B$8:$B$57,0)),"") -> 4
B17: Margen deseado en MAYOREO | C17: 0.35 | E17: + Merma | F17: =IFERROR(INDEX('3. COSTEO'!$K$8:$K$57,MATCH($F$7,'3. COSTEO'!$B$8:$B$57,0)),"") -> 2.5604
B18: Redondear precios al múltiplo de | C18: 5 | E18: + Overhead | F18: =IFERROR(INDEX('3. COSTEO'!$L$8:$L$57,MATCH($F$7,'3. COSTEO'!$B$8:$B$57,0)),"") -> 10
B19: IVA (solo si facturas) | C19: 0.16 | E19: ◆ COSTO TOTAL POR PIEZA | F19: =IFERROR(INDEX('3. COSTEO'!$M$8:$M$57,MATCH($F$7,'3. COSTEO'!$B$8:$B$57,0)),"") -> 44.5654
E20: PRECIO SUGERIDO MENUDEO | F20: =IFERROR(INDEX('3. COSTEO'!$O$8:$O$57,MATCH($F$7,'3. COSTEO'!$B$8:$B$57,0)),"") -> 115
E21: Utilidad por pieza (menudeo) | F21: =IFERROR(INDEX('3. COSTEO'!$P$8:$P$57,MATCH($F$7,'3. COSTEO'!$B$8:$B$57,0)),"") -> 70.4346
B22: ④ RESUMEN DEL RECETARIO | E22: Margen real que obtienes | F22: =IFERROR(INDEX('3. COSTEO'!$Q$8:$Q$57,MATCH($F$7,'3. COSTEO'!$B$8:$B$57,0)),"") -> 0.61247478
B23: Recetas cargadas | C23: =COUNT('3. COSTEO'!$A$8:$A$57) -> 50 | E23: PRECIO SUGERIDO MAYOREO | F23: =IFERROR(INDEX('3. COSTEO'!$R$8:$R$57,MATCH($F$7,'3. COSTEO'!$B$8:$B$57,0)),"") -> 70
B24: Costo promedio por pieza | C24: =AVERAGE('3. COSTEO'!$M$8:$M$57) -> 46.535957 | E24: Utilidad por pieza (mayoreo) | F24: =IFERROR(INDEX('3. COSTEO'!$S$8:$S$57,MATCH($F$7,'3. COSTEO'!$B$8:$B$57,0)),"") -> 25.4346
B25: Precio menudeo promedio | C25: =AVERAGE('3. COSTEO'!$O$8:$O$57) -> 118.8 | E25: Precio menudeo con IVA | F25: =IFERROR(INDEX('3. COSTEO'!$T$8:$T$57,MATCH($F$7,'3. COSTEO'!$B$8:$B$57,0)),"") -> 133.4
B26: Utilidad promedio por pieza | C26: =AVERAGE('3. COSTEO'!$P$8:$P$57) -> 72.264043
B27: Receta más económica | C27: =INDEX('3. COSTEO'!$B$8:$B$57,MATCH(MIN('3. COSTEO'!$M$8:$M$57),'3. COSTEO'!$M$8:$M$57,0)) -> Galleta Rollo de Canela (Marmoleada y Glaseada) | E27: ③ FICHA TÉCNICA DE LA RECETA SELECCIONADA
B28: Receta más costosa | C28: =INDEX('3. COSTEO'!$B$8:$B$57,MATCH(MAX('3. COSTEO'!$M$8:$M$57),'3. COSTEO'!$M$8:$M$57,0)) -> Pistache Intenso con Núcleo de Chocolate Blanco | E28: Dificultad | F28: =IFERROR(INDEX('3. COSTEO'!$U$8:$U$57,MATCH($F$7,'3. COSTEO'!$B$8:$B$57,0)),"") -> Básico (receta de entrada al oficio)
E29: Temperatura de horneado | F29: =IFERROR(INDEX('3. COSTEO'!$V$8:$V$57,MATCH($F$7,'3. COSTEO'!$B$8:$B$57,0)),"") -> 200 °C (alta temperatura para sellar el exterior rocoso rápidamente).
E30: Tiempo de horneado | F30: =IFERROR(INDEX('3. COSTEO'!$W$8:$W$57,MATCH($F$7,'3. COSTEO'!$B$8:$B$57,0)),"") -> 12 a 14 minutos.
E31: Reposo de masa | F31: =IFERROR(INDEX('3. COSTEO'!$X$8:$X$57,MATCH($F$7,'3. COSTEO'!$B$8:$B$57,0)),"") -> 4 a 12 horas en refrigeración (4 °C).
B33: Nota: el costo se calcula como Insumos + Empaque + Energía + Mano de obra + Merma + Overhead, tal como se explica en el Capítulo 10 del eBook.

Sheet 1. INSUMOS
A1: ENDULCORA · ESTUDIO GASTRONÓMICO
A2: 1 · Catálogo de insumos
A3: Actualiza SOLO las columnas amarillas con tus precios reales. El costo por gramo se calcula solo.
A7: # | B7: Insumo | C7: Categoría | D7: Unidad | E7: Presentación de compra | F7: Cantidad que trae | G7: Precio de compra | H7: Costo por unidad | I7: Proveedor / notas
A8: 1 | B8: Mantequilla sin sal | C8: Lácteos y grasas | D8: g | E8: Barra/bloque 1 kg | F8: 1000 | G8: 210 | H8: =IF(F8=0,0,G8/F8) -> 0.21
A9: 2 | B9: Queso crema (bloque firme) | C9: Lácteos y grasas | D9: g | E9: Bloque 1 kg | F9: 1000 | G9: 185 | H9: =IF(F9=0,0,G9/F9) -> 0.185
A10: 3 | B10: Queso mascarpone | C10: Lácteos y grasas | D10: g | E10: Tarro 500 g | F10: 500 | G10: 180 | H10: =IF(F10=0,0,G10/F10) -> 0.36
A11: 4 | B11: Queso azul | C11: Lácteos y grasas | D11: g | E11: Cuña 250 g | F11: 250 | G11: 145 | H11: =IF(F11=0,0,G11/F11) -> 0.58
A12: 5 | B12: Leche condensada | C12: Lácteos y grasas | D12: g | E12: Lata 397 g | F12: 397 | G12: 34 | H12: =IF(F12=0,0,G12/F12) -> 0.085642317
A13: 6 | B13: Aceite de oliva extra virgen | C13: Lácteos y grasas | D13: ml | E13: Botella 500 ml | F13: 500 | G13: 150 | H13: =IF(F13=0,0,G13/F13) -> 0.3
A14: 7 | B14: Aceite de trufa negra | C14: Lácteos y grasas | D14: ml | E14: Botella 50 ml | F14: 50 | G14: 260 | H14: =IF(F14=0,0,G14/F14) -> 5.2
A15: 8 | B15: Azúcar refinada | C15: Azúcares | D15: g | E15: Bolsa 1 kg | F15: 1000 | G15: 30 | H15: =IF(F15=0,0,G15/F15) -> 0.03
A16: 9 | B16: Azúcar mascabado | C16: Azúcares | D16: g | E16: Bolsa 1 kg | F16: 1000 | G16: 52 | H16: =IF(F16=0,0,G16/F16) -> 0.052
A17: 10 | B17: Azúcar mascabado oscuro | C17: Azúcares | D17: g | E17: Bolsa 1 kg | F17: 1000 | G17: 58 | H17: =IF(F17=0,0,G17/F17) -> 0.058
A18: 11 | B18: Azúcar glass | C18: Azúcares | D18: g | E18: Bolsa 500 g | F18: 500 | G18: 32 | H18: =IF(F18=0,0,G18/F18) -> 0.064
A19: 12 | B19: Piloncillo | C19: Azúcares | D19: g | E19: Conos 1 kg | F19: 1000 | G19: 48 | H19: =IF(F19=0,0,G19/F19) -> 0.048
... A98: 91 | B98: Jugo de yuzu | C98: Especias y aromas | D98: ml | E98: Botella 100 ml | F98: 100 | G98: 195 | H98: =IF(F98=0,0,G98/F98) -> 1.95
B100: Los precios cargados son estimaciones de referencia de mercado (CDMX) para que el archivo funcione de inmediato; NO son cotizaciones. Sustitúyelos por tus precios de proveedor.

Sheet 2. RECETAS
A1: ENDULCORA · ESTUDIO GASTRONÓMICO
A2: 2 · Recetario maestro desglosado
A3: Las 50 fórmulas del eBook con sus gramajes exactos. Hoja automática: no necesitas escribir nada aquí.
A7: # Receta | B7: Nombre de la receta | C7: Componente | D7: Insumo del catálogo | E7: Cantidad | F7: Unidad | G7: Costo por unidad | H7: Costo en la receta | I7: Lotes planeados | J7: Cantidad requerida | K7: Detalle textual del libro
A8: 1 | B8: Galleta de Chispas de Chocolate Semiamargo con Sal de Mar | C8: Masa | D8: Mantequilla sin sal | E8: 180 | F8: g | G8: =IFERROR(INDEX('1. INSUMOS'!$H$8:$H$98,MATCH($D8,'1. INSUMOS'!$B$8:$B$98,0)),0) -> 0.21 | H8: =E8*G8 -> 37.8 | I8: =IFERROR(INDEX('4. PRODUCCIÓN'!$D$8:$D$32,MATCH($A8,'4. PRODUCCIÓN'!$B$8:$B$32,0)),0) -> 0 | J8: =E8*I8 -> 0 | K8: Mantequilla sin sal (fría, cortada en cubos)
A9: 1 | B9: Galleta de Chispas de Chocolate Semiamargo con Sal de Mar | C9: Masa | D9: Azúcar mascabado oscuro | E9: 150 | F9: g | G9: =IFERROR(INDEX('1. INSUMOS'!$H$8:$H$98,MATCH($D9,'1. INSUMOS'!$B$8:$B$98,0)),0) -> 0.058 | H9: =E9*G9 -> 8.7 | I9: =IFERROR(INDEX('4. PRODUCCIÓN'!$D$8:$D$32,MATCH($A9,'4. PRODUCCIÓN'!$B$8:$B$32,0)),0) -> 0 | J9: =E9*I9 -> 0 | K9: Azúcar mascabado oscuro
A10: 1 | B10: Galleta de Chispas de Chocolate Semiamargo con Sal de Mar | C10: Masa | D10: Azúcar refinada | E10: 100 | F10: g | G10: =IFERROR(INDEX('1. INSUMOS'!$H$8:$H$98,MATCH($D10,'1. INSUMOS'!$B$8:$B$98,0)),0) -> 0.03 | H10: =E10*G10 -> 3 | I10: =IFERROR(INDEX('4. PRODUCCIÓN'!$D$8:$D$32,MATCH($A10,'4. PRODUCCIÓN'!$B$8:$B$32,0)),0) -> 0 | J10: =E10*I10 -> 0 | K10: Azúcar refinada (blanca)
A11: 1 | B11: Galleta de Chispas de Chocolate Semiamargo con Sal de Mar | C11: Masa | D11: Huevo entero (aprox. 50 g) | E11: 2 | F11: pza | G11: =IFERROR(INDEX('1. INSUMOS'!$H$8:$H$98,MATCH($D11,'1. INSUMOS'!$B$8:$B$98,0)),0) -> 3.2 | H11: =E11*G11 -> 6.4 | I11: =IFERROR(INDEX('4. PRODUCCIÓN'!$D$8:$D$32,MATCH($A11,'4. PRODUCCIÓN'!$B$8:$B$32,0)),0) -> 0 | J11: =E11*I11 -> 0 | K11: Huevos fríos (aprox. 100 g totales)
A12: 1 | B12: Galleta de Chispas de Chocolate Semiamargo con Sal de Mar | C12: Masa | D12: Harina de trigo | E12: 300 | F12: g | G12: =IFERROR(INDEX('1. INSUMOS'!$H$8:$H$98,MATCH($D12,'1. INSUMOS'!$B$8:$B$98,0)),0) -> 0.03 | H12: =E12*G12 -> 9 | I12: =IFERROR(INDEX('4. PRODUCCIÓN'!$D$8:$D$32,MATCH($A12,'4. PRODUCCIÓN'!$B$8:$B$32,0)),0) -> 0 | J12: =E12*I12 -> 0 | K12: Harina de trigo (mitad uso múltiple, mitad harina de fuerza/panadera)
A13: 1 | B13: Galleta de Chispas de Chocolate Semiamargo con Sal de Mar | C13: Masa | D13: Fécula de maíz (maicena) | E13: 10 | F13: g | G13: =IFERROR(INDEX('1. INSUMOS'!$H$8:$H$98,MATCH($D13,'1. INSUMOS'!$B$8:$B$98,0)),0) -> 0.09 | H13: =E13*G13 -> 0.9 | I13: =IFERROR(INDEX('4. PRODUCCIÓN'!$D$8:$D$32,MATCH($A13,'4. PRODUCCIÓN'!$B$8:$B$32,0)),0) -> 0 | J13: =E13*I13 -> 0 | K13: Fécula de maíz (maicena)
A14: 1 | B14: Galleta de Chispas de Chocolate Semiamargo con Sal de Mar | C14: Masa | D14: Bicarbonato de sodio | E14: 5 | F14: g | G14: =IFERROR(INDEX('1. INSUMOS'!$H$8:$H$98,MATCH($D14,'1. INSUMOS'!$B$8:$B$98,0)),0) -> 0.13 | H14: =E14*G14 -> 0.65 | I14: =IFERROR(INDEX('4. PRODUCCIÓN'!$D$8:$D$32,MATCH($A14,'4. PRODUCCIÓN'!$B$8:$B$32,0)),0) -> 0 | J14: =E14*I14 -> 0 | K14: Bicarbonato de sodio
A15: 1 | B15: Galleta de Chispas de Chocolate Semiamargo con Sal de Mar | C15: Masa | D15: Sal fina | E15: 4 | F15: g | G15: =IFERROR(INDEX('1. INSUMOS'!$H$8:$H$98,MATCH($D15,'1. INSUMOS'!$B$8:$B$98,0)),0) -> 0.02 | H15: =E15*G15 -> 0.08 | I15: =IFERROR(INDEX('4. PRODUCCIÓN'!$D$8:$D$32,MATCH($A15,'4. PRODUCCIÓN'!$B$8:$B$32,0)),0) -> 0 | J15: =E15*I15 -> 0 | K15: Sal fina
A16: 1 | B16: Galleta de Chispas de Chocolate Semiamargo con Sal de Mar | C16: Masa | D16: Chocolate semiamargo 54% (chunks) | E16: 250 | F16: g | G16: =IFERROR(INDEX('1. INSUMOS'!$H$8:$H$98,MATCH($D16,'1. INSUMOS'!$B$8:$B$98,0)),0) -> 0.21 | H16: =E16*G16 -> 52.5 | I16: =IFERROR(INDEX('4. PRODUCCIÓN'!$D$8:$D$32,MATCH($A16,'4. PRODUCCIÓN'!$B$8:$B$32,0)),0) -> 0 | J16: =E16*I16 -> 0 | K16: Chunks (trozos irregulares) de chocolate semiamargo (mínimo 54% cacao)
A17: 1 | B17: Galleta de Chispas de Chocolate Semiamargo con Sal de Mar | C17: Decoración | D17: Sal de mar en escamas | E17: 2 | F17: g | G17: =IFERROR(INDEX('1. INSUMOS'!$H$8:$H$98,MATCH($D17,'1. INSUMOS'!$B$8:$B$98,0)),0) -> 0.5 | H17: =E17*G17 -> 1 | I17: =IFERROR(INDEX('4. PRODUCCIÓN'!$D$8:$D$32,MATCH($A17,'4. PRODUCCIÓN'!$B$8:$B$32,0)),0) -> 0 | J17: =E17*I17 -> 0 | K17: C/S en el libro — cantidad estimada, ajústala: Sal de mar en escamas (para decorar)
A18: 2 | B18: Doble Chocolate Oscuro con Chunks de Chocolate Blanco | C18: Masa | D18: Mantequilla sin sal | E18: 180 | F18: g | G18: =IFERROR(INDEX('1. INSUMOS'!$H$8:$H$98,MATCH($D18,'1. INSUMOS'!$B$8:$B$98,0)),0) -> 0.21 | H18: =E18*G18 -> 37.8 | I18: =IFERROR(INDEX('4. PRODUCCIÓN'!$D$8:$D$32,MATCH($A18,'4. PRODUCCIÓN'!$B$8:$B$32,0)),0) -> 0 | J18: =E18*I18 -> 0 | K18: Mantequilla sin sal (fría en cubos)
A19: 2 | B19: Doble Chocolate Oscuro con Chunks de Chocolate Blanco | C19: Masa | D19: Azúcar mascabado | E19: 180 | F19: g | G19: =IFERROR(INDEX('1. INSUMOS'!$H$8:$H$98,MATCH($D19,'1. INSUMOS'!$B$8:$B$98,0)),0) -> 0.052 | H19: =E19*G19 -> 9.36 | I19: =IFERROR(INDEX('4. PRODUCCIÓN'!$D$8:$D$32,MATCH($A19,'4. PRODUCCIÓN'!$B$8:$B$32,0)),0) -> 0 | J19: =E19*I19 -> 0 | K19: Azúcar mascabado
... A557: 50 | B557: Ajo Negro y Chocolate Amargo con Sal Ahumada | C557: Decoración | D557: Sal ahumada | E557: 2 | F557: g | G557: =IFERROR(INDEX('1. INSUMOS'!$H$8:$H$98,MATCH($D557,'1. INSUMOS'!$B$8:$B$98,0)),0) -> 0.95 | H557: =E557*G557 -> 1.9 | I557: =IFERROR(INDEX('4. PRODUCCIÓN'!$D$8:$D$32,MATCH($A557,'4. PRODUCCIÓN'!$B$8:$B$32,0)),0) -> 0 | J557: =E557*I557 -> 0 | K557: C/S en el libro — cantidad estimada, ajústala: Sal ahumada (para decorar)

Sheet 3. COSTEO
A1: ENDULCORA · ESTUDIO GASTRONÓMICO
A2: 3 · Costeo y precios de las 50 recetas
A3: Todo se calcula solo a partir de «1. INSUMOS» y del «PANEL». Las columnas verdes puedes sobreescribirlas por receta.
A7: # | B7: Receta | C7: Línea del recetario | D7: Piezas por lote | E7: Costo insumos del lote | F7: Insumos por pieza | G7: Empaque | H7: Energía | I7: Mano de obra | J7: Subtotal | K7: Merma | L7: Overhead | M7: COSTO TOTAL / PIEZA | N7: PVP menudeo teórico | O7: PRECIO MENUDEO | P7: Utilidad menudeo | Q7: Margen real | R7: PRECIO MAYOREO | S7: Utilidad mayoreo | T7: Precio con IVA | U7: Dificultad | V7: Temperatura | W7: Tiempo de horneado | X7: Reposo de masa
A8: 1 | B8: Galleta de Chispas de Chocolate Semiamargo con Sal de Mar | C8: Cap. 5 · Clásicos de Nueva York | D8: 6 | E8: =SUMIFS('2. RECETAS'!$H$8:$H$557,'2. RECETAS'!$A$8:$A$557,$A8) -> 120.03 | F8: =IF(D8=0,0,E8/D8) -> 20.005 | G8: =PANEL!$C$7 -> 6 | H8: =PANEL!$C$8 -> 2 | I8: =PANEL!$C$11 -> 4 | J8: =F8+G8+H8+I8 -> 32.005 | K8: =J8*PANEL!$C$12 -> 2.5604 | L8: =PANEL!$C$15 -> 10 | M8: =J8+K8+L8 -> 44.5654 | N8: =IF(PANEL!$C$16>=1,0,M8/(1-PANEL!$C$16)) -> 111.4135 | O8: =IF(PANEL!$C$18<=0,N8,CEILING(N8,PANEL!$C$18)) -> 115 | P8: =O8-M8 -> 70.4346 | Q8: =IF(O8=0,0,P8/O8) -> 0.61247478 | R8: =IF(PANEL!$C$17>=1,0,IF(PANEL!$C$18<=0,M8/(1-PANEL!$C$17),CEILING(M8/(1-PANEL!$C$17),PANEL!$C$18))) -> 70 | S8: =R8-M8 -> 25.4346 | T8: =O8*(1+PANEL!$C$19) -> 133.4 | U8: Básico (receta de entrada al oficio) | V8: 200 °C (alta temperatura para sellar el exterior rocoso rápidamente). | W8: 12 a 14 minutos. | X8: 4 a 12 horas en refrigeración (4 °C).
A9: 2 | B9: Doble Chocolate Oscuro con Chunks de Chocolate Blanco | C9: Cap. 5 · Clásicos de Nueva York | D9: 6 | E9: =SUMIFS('2. RECETAS'!$H$8:$H$557,'2. RECETAS'!$A$8:$A$557,$A9) -> 136.1 | F9: =IF(D9=0,0,E9/D9) -> 22.683333 | G9: =PANEL!$C$7 -> 6 | H9: =PANEL!$C$8 -> 2 | I9: =PANEL!$C$11 -> 4 | J9: =F9+G9+H9+I9 -> 34.683333 | K9: =J9*PANEL!$C$12 -> 2.7746667 | L9: =PANEL!$C$15 -> 10 | M9: =J9+K9+L9 -> 47.458 | N9: =IF(PANEL!$C$16>=1,0,M9/(1-PANEL!$C$16)) -> 118.645 | O9: =IF(PANEL!$C$18<=0,N9,CEILING(N9,PANEL!$C$18)) -> 120 | P9: =O9-M9 -> 72.542 | Q9: =IF(O9=0,0,P9/O9) -> 0.60451667 | R9: =IF(PANEL!$C$17>=1,0,IF(PANEL!$C$18<=0,M9/(1-PANEL!$C$17),CEILING(M9/(1-PANEL!$C$17),PANEL!$C$18))) -> 75 | S9: =R9-M9 -> 27.542 | T9: =O9*(1+PANEL!$C$19) -> 139.2 | U9: Básico–Intermedio (ajuste de hidratación por el cacao) | V9: 200 °C | W9: 11 a 13 minutos (el chocolate oscuro se quema más rápido, vigilar de cer‐ | X9: 4 a 12 horas a 4 °C.
A10: 3 | B10: Red Velvet Clásica con Chispas Blancas y Nuez | C10: Cap. 5 · Clásicos de Nueva York | D10: 6 | E10: =SUMIFS('2. RECETAS'!$H$8:$H$557,'2. RECETAS'!$A$8:$A$557,$A10) -> 168.15 | F10: =IF(D10=0,0,E10/D10) -> 28.025 | G10: =PANEL!$C$7 -> 6 | H10: =PANEL!$C$8 -> 2 | I10: =PANEL!$C$11 -> 4 | J10: =F10+G10+H10+I10 -> 40.025 | K10: =J10*PANEL!$C$12 -> 3.202 | L10: =PANEL!$C$15 -> 10 | M10: =J10+K10+L10 -> 53.227 | N10: =IF(PANEL!$C$16>=1,0,M10/(1-PANEL!$C$16)) -> 133.0675 | O10: =IF(PANEL!$C$18<=0,N10,CEILING(N10,PANEL!$C$18)) -> 135 | P10: =O10-M10 -> 81.773 | Q10: =IF(O10=0,0,P10/O10) -> 0.60572593 | R10: =IF(PANEL!$C$17>=1,0,IF(PANEL!$C$18<=0,M10/(1-PANEL!$C$17),CEILING(M10/(1-PANEL!$C$17),PANEL!$C$18))) -> 85 | S10: =R10-M10 -> 31.773 | T10: =O10*(1+PANEL!$C$19) -> 156.6 | U10: Intermedio (control de color y acidez) | V10: 190 °C (un poco más baja para proteger el color rojo). | W10: 13 a 15 minutos. | X10: 4 a 12 horas a 4 °C.
A11: 4 | B11: Avena Rústica, Pasas Rubias y Canela | C11: Cap. 5 · Clásicos de Nueva York | D11: 6 | E11: =SUMIFS('2. RECETAS'!$H$8:$H$557,'2. RECETAS'!$A$8:$A$557,$A11) -> 113.8 | F11: =IF(D11=0,0,E11/D11) -> 18.966667 | G11: =PANEL!$C$7 -> 6 | H11: =PANEL!$C$8 -> 2 | I11: =PANEL!$C$11 -> 4 | J11: =F11+G11+H11+I11 -> 30.966667 | K11: =J11*PANEL!$C$12 -> 2.4773333 | L11: =PANEL!$C$15 -> 10 | M11: =J11+K11+L11 -> 43.444 | N11: =IF(PANEL!$C$16>=1,0,M11/(1-PANEL!$C$16)) -> 108.61 | O11: =IF(PANEL!$C$18<=0,N11,CEILING(N11,PANEL!$C$18)) -> 110 | P11: =O11-M11 -> 66.556 | Q11: =IF(O11=0,0,P11/O11) -> 0.60505455 | R11: =IF(PANEL!$C$17>=1,0,IF(PANEL!$C$18<=0,M11/(1-PANEL!$C$17),CEILING(M11/(1-PANEL!$C$17),PANEL!$C$18))) -> 70 | S11: =R11-M11 -> 26.556 | T11: =O11*(1+PANEL!$C$19) -> 127.6 | U11: Básico (masa indulgente y tolerante) | V11: 190 °C | W11: 14 a 16 minutos. | X11: 4 horas mínimo (crítico para que la avena absorba la humedad de la
A12: 5 | B12: Mantequilla Avellanada (Brown Butter) y Nuez Pecana Tostada | C12: Cap. 5 · Clásicos de Nueva York | D12: 6 | E12: =SUMIFS('2. RECETAS'!$H$8:$H$557,'2. RECETAS'!$A$8:$A$557,$A12) -> 181.97 | F12: =IF(D12=0,0,E12/D12) -> 30.328333 | G12: =PANEL!$C$7 -> 6 | H12: =PANEL!$C$8 -> 2 | I12: =PANEL!$C$11 -> 4 | J12: =F12+G12+H12+I12 -> 42.328333 | K12: =J12*PANEL!$C$12 -> 3.3862667 | L12: =PANEL!$C$15 -> 10 | M12: =J12+K12+L12 -> 55.7146 | N12: =IF(PANEL!$C$16>=1,0,M12/(1-PANEL!$C$16)) -> 139.2865 | O12: =IF(PANEL!$C$18<=0,N12,CEILING(N12,PANEL!$C$18)) -> 140 | P12: =O12-M12 -> 84.2854 | Q12: =IF(O12=0,0,P12/O12) -> 0.60203857 | R12: =IF(PANEL!$C$17>=1,0,IF(PANEL!$C$18<=0,M12/(1-PANEL!$C$17),CEILING(M12/(1-PANEL!$C$17),PANEL!$C$18))) -> 90 | S12: =R12-M12 -> 34.2854 | T12: =O12*(1+PANEL!$C$19) -> 162.4 | U12: Intermedio (requiere avellanar mantequilla sin quemarla) | V12: 190 °C | W12: 12 a 14 minutos. | X12: 4 a 12 horas.
A13: 6 | B13: Macadamia Dorada y Chocolate Blanco | C13: Cap. 5 · Clásicos de Nueva York | D13: 6 | E13: =SUMIFS('2. RECETAS'!$H$8:$H$557,'2. RECETAS'!$A$8:$A$557,$A13) -> 217.36 | F13: =IF(D13=0,0,E13/D13) -> 36.226667 | G13: =PANEL!$C$7 -> 6 | H13: =PANEL!$C$8 -> 2 | I13: =PANEL!$C$11 -> 4 | J13: =F13+G13+H13+I13 -> 48.226667 | K13: =J13*PANEL!$C$12 -> 3.8581333 | L13: =PANEL!$C$15 -> 10 | M13: =J13+K13+L13 -> 62.0848 | N13: =IF(PANEL!$C$16>=1,0,M13/(1-PANEL!$C$16)) -> 155.212 | O13: =IF(PANEL!$C$18<=0,N13,CEILING(N13,PANEL!$C$18)) -> 160 | P13: =O13-M13 -> 97.9152 | Q13: =IF(O13=0,0,P13/O13) -> 0.61197 | R13: =IF(PANEL!$C$17>=1,0,IF(PANEL!$C$18<=0,M13/(1-PANEL!$C$17),CEILING(M13/(1-PANEL!$C$17),PANEL!$C$18))) -> 100 | S13: =R13-M13 -> 37.9152 | T13: =O13*(1+PANEL!$C$19) -> 185.6 | U13: Básico–Intermedio (cuidar que el blanco no se queme) | V13: 195 °C | W13: 12 a 14 minutos. | X13: 4 a 12 horas en refrigeración.
A14: 7 | B14: Snickerdoodle Gruesa (Rebozada en Canela y Azúcar) | C14: Cap. 5 · Clásicos de Nueva York | D14: 6 | E14: =SUMIFS('2. RECETAS'!$H$8:$H$557,'2. RECETAS'!$A$8:$A$557,$A14) -> 70.03 | F14: =IF(D14=0,0,E14/D14) -> 11.671667 | G14: =PANEL!$C$7 -> 6 | H14: =PANEL!$C$8 -> 2 | I14: =PANEL!$C$11 -> 4 | J14: =F14+G14+H14+I14 -> 23.671667 | K14: =J14*PANEL!$C$12 -> 1.8937333 | L14: =PANEL!$C$15 -> 10 | M14: =J14+K14+L14 -> 35.5654 | N14: =IF(PANEL!$C$16>=1,0,M14/(1-PANEL!$C$16)) -> 88.9135 | O14: =IF(PANEL!$C$18<=0,N14,CEILING(N14,PANEL!$C$18)) -> 90 | P14: =O14-M14 -> 54.4346 | Q14: =IF(O14=0,0,P14/O14) -> 0.60482889 | R14: =IF(PANEL!$C$17>=1,0,IF(PANEL!$C$18<=0,M14/(1-PANEL!$C$17),CEILING(M14/(1-PANEL!$C$17),PANEL!$C$18))) -> 55 | S14: =R14-M14 -> 19.4346 | T14: =O14*(1+PANEL!$C$19) -> 104.4 | U14: Básico (clásico de rebozado) | V14: 190 °C | W14: 13 a 15 minutos. | X14: 4 a 12 horas.
A15: 8 | B15: Confetti Vanilla (Masa de vainilla con chispas) | C15: Cap. 5 · Clásicos de Nueva York | D15: 6 | E15: =SUMIFS('2. RECETAS'!$H$8:$H$557,'2. RECETAS'!$A$8:$A$557,$A15) -> 127.02 | F15: =IF(D15=0,0,E15/D15) -> 21.17 | G15: =PANEL!$C$7 -> 6 | H15: =PANEL!$C$8 -> 2 | I15: =PANEL!$C$11 -> 4 | J15: =F15+G15+H15+I15 -> 33.17 | K15: =J15*PANEL!$C$12 -> 2.6536 | L15: =PANEL!$C$15 -> 10 | M15: =J15+K15+L15 -> 45.8236 | N15: =IF(PANEL!$C$16>=1,0,M15/(1-PANEL!$C$16)) -> 114.559 | O15: =IF(PANEL!$C$18<=0,N15,CEILING(N15,PANEL!$C$18)) -> 115 | P15: =O15-M15 -> 69.1764 | Q15: =IF(O15=0,0,P15/O15) -> 0.60153391 | R15: =IF(PANEL!$C$17>=1,0,IF(PANEL!$C$18<=0,M15/(1-PANEL!$C$17),CEILING(M15/(1-PANEL!$C$17),PANEL!$C$18))) -> 75 | S15: =R15-M15 -> 29.1764 | T15: =O15*(1+PANEL!$C$19) -> 133.4 | U15: Básico (ideal para talleres infantiles) | V15: 190 °C | W15: 13 a 15 minutos. | X15: 4 horas en frío.
A16: 9 | B16: Peanut Butter Clásica Gruesa | C16: Cap. 5 · Clásicos de Nueva York | D16: 6 | E16: =SUMIFS('2. RECETAS'!$H$8:$H$557,'2. RECETAS'!$A$8:$A$557,$A16) -> 105.03 | F16: =IF(D16=0,0,E16/D16) -> 17.505 | G16: =PANEL!$C$7 -> 6 | H16: =PANEL!$C$8 -> 2 | I16: =PANEL!$C$11 -> 4 | J16: =F16+G16+H16+I16 -> 29.505 | K16: =J16*PANEL!$C$12 -> 2.3604 | L16: =PANEL!$C$15 -> 10 | M16: =J16+K16+L16 -> 41.8654 | N16: =IF(PANEL!$C$16>=1,0,M16/(1-PANEL!$C$16)) -> 104.6635 | O16: =IF(PANEL!$C$18<=0,N16,CEILING(N16,PANEL!$C$18)) -> 105 | P16: =O16-M16 -> 63.1346 | Q16: =IF(O16=0,0,P16/O16) -> 0.6012819 | R16: =IF(PANEL!$C$17>=1,0,IF(PANEL!$C$18<=0,M16/(1-PANEL!$C$17),CEILING(M16/(1-PANEL!$C$17),PANEL!$C$18))) -> 65 | S16: =R16-M16 -> 23.1346 | T16: =O16*(1+PANEL!$C$19) -> 121.8 | U16: Básico (masa densa y noble) | V16: 190 °C | W16: 14 a 16 minutos. | X16: 4 horas mínimo.
A17: 10 | B17: Triple Chocolate (Masa oscura, chispas de leche, semiamargas | C17: Cap. 5 · Clásicos de Nueva York | D17: 6 | E17: =SUMIFS('2. RECETAS'!$H$8:$H$557,'2. RECETAS'!$A$8:$A$557,$A17) -> 135.63 | F17: =IF(D17=0,0,E17/D17) -> 22.605 | G17: =PANEL!$C$7 -> 6 | H17: =PANEL!$C$8 -> 2 | I17: =PANEL!$C$11 -> 4 | J17: =F17+G17+H17+I17 -> 34.605 | K17: =J17*PANEL!$C$12 -> 2.7684 | L17: =PANEL!$C$15 -> 10 | M17: =J17+K17+L17 -> 47.3734 | N17: =IF(PANEL!$C$16>=1,0,M17/(1-PANEL!$C$16)) -> 118.4335 | O17: =IF(PANEL!$C$18<=0,N17,CEILING(N17,PANEL!$C$18)) -> 120 | P17: =O17-M17 -> 72.6266 | Q17: =IF(O17=0,0,P17/O17) -> 0.60522167 | R17: =IF(PANEL!$C$17>=1,0,IF(PANEL!$C$18<=0,M17/(1-PANEL!$C$17),CEILING(M17/(1-PANEL!$C$17),PANEL!$C$18))) -> 75 | S17: =R17-M17 -> 27.6266 | T17: =O17*(1+PANEL!$C$19) -> 139.2 | U17: Intermedio (tres chocolates con puntos de fusión distintos) | V17: 195 °C | W17: 12 a 14 minutos. | X17: 4 a 12 horas.
A18: 11 | B18: Brookie Gigante (El choque de dos mundos) | C18: Cap. 5 · Clásicos de Nueva York | D18: 6 | E18: =SUMIFS('2. RECETAS'!$H$8:$H$557,'2. RECETAS'!$A$8:$A$557,$A18) -> 103.48 | F18: =IF(D18=0,0,E18/D18) -> 17.246667 | G18: =PANEL!$C$7 -> 6 | H18: =PANEL!$C$8 -> 2 | I18: =PANEL!$C$11 -> 4 | J18: =F18+G18+H18+I18 -> 29.246667 | K18: =J18*PANEL!$C$12 -> 2.3397333 | L18: =PANEL!$C$15 -> 10 | M18: =J18+K18+L18 -> 41.5864 | N18: =IF(PANEL!$C$16>=1,0,M18/(1-PANEL!$C$16)) -> 103.966 | O18: =IF(PANEL!$C$18<=0,N18,CEILING(N18,PANEL!$C$18)) -> 105 | P18: =O18-M18 -> 63.4136 | Q18: =IF(O18=0,0,P18/O18) -> 0.60393905 | R18: =IF(PANEL!$C$17>=1,0,IF(PANEL!$C$18<=0,M18/(1-PANEL!$C$17),CEILING(M18/(1-PANEL!$C$17),PANEL!$C$18))) -> 65 | S18: =R18-M18 -> 23.4136 | T18: =O18*(1+PANEL!$C$19) -> 121.8 | U18: Intermedio (dos masas en una sola pieza) | V18: 190 °C | W18: 12 a 14 minutos.
A19: 12 | B19: Galleta Carrot Cake con Costra de Queso Crema | C19: Cap. 5 · Clásicos de Nueva York | D19: 6 | E19: =SUMIFS('2. RECETAS'!$H$8:$H$557,'2. RECETAS'!$A$8:$A$557,$A19) -> 104.13 | F19: =IF(D19=0,0,E19/D19) -> 17.355 | G19: =PANEL!$C$7 -> 6 | H19: =PANEL!$C$8 -> 2 | I19: =PANEL!$C$11 -> 4 | J19: =F19+G19+H19+I19 -> 29.355 | K19: =J19*PANEL!$C$12 -> 2.3484 | L19: =PANEL!$C$15 -> 10 | M19: =J19+K19+L19 -> 41.7034 | N19: =IF(PANEL!$C$16>=1,0,M19/(1-PANEL!$C$16)) -> 104.2585 | O19: =IF(PANEL!$C$18<=0,N19,CEILING(N19,PANEL!$C$18)) -> 105 | P19: =O19-M19 -> 63.2966 | Q19: =IF(O19=0,0,P19/O19) -> 0.60282476 | R19: =IF(PANEL!$C$17>=1,0,IF(PANEL!$C$18<=0,M19/(1-PANEL!$C$17),CEILING(M19/(1-PANEL!$C$17),PANEL!$C$18))) -> 65 | S19: =R19-M19 -> 23.2966 | T19: =O19*(1+PANEL!$C$19) -> 121.8 | U19: Intermedio (control de humedad de la zanahoria) | V19: 190 °C | W19: 14 a 16 minutos.
A20: 13 | B20: Galleta Rollo de Canela (Marmoleada y Glaseada) | C20: Cap. 5 · Clásicos de Nueva York | D20: 6 | E20: =SUMIFS('2. RECETAS'!$H$8:$H$557,'2. RECETAS'!$A$8:$A$557,$A20) -> 64.83 | F20: =IF(D20=0,0,E20/D20) -> 10.805 | G20: =PANEL!$C$7 -> 6 | H20: =PANEL!$C$8 -> 2 | I20: =PANEL!$C$11 -> 4 | J20: =F20+G20+H20+I20 -> 22.805 | K20: =J20*PANEL!$C$12 -> 1.8244 | L20: =PANEL!$C$15 -> 10 | M20: =J20+K20+L20 -> 34.6294 | N20: =IF(PANEL!$C$16>=1,0,M20/(1-PANEL!$C$16)) -> 86.5735 | O20: =IF(PANEL!$C$18<=0,N20,CEILING(N20,PANEL!$C$18)) -> 90 | P20: =O20-M20 -> 55.3706 | Q20: =IF(O20=0,0,P20/O20) -> 0.61522889 | R20: =IF(PANEL!$C$17>=1,0,IF(PANEL!$C$18<=0,M20/(1-PANEL!$C$17),CEILING(M20/(1-PANEL!$C$17),PANEL!$C$18))) -> 55 | S20: =R20-M20 -> 20.3706 | T20: =O20*(1+PANEL!$C$19) -> 104.4 | U20: Intermedio (marmoleado y glaseado) | V20: 190 °C | W20: 13 a 15 minutos.
A21: 14 | B21: Tarta de Manzana (Con Streusel y Manzana Especiada) | C21: Cap. 5 · Clásicos de Nueva York | D21: 6 | E21: =SUMIFS('2. RECETAS'!$H$8:$H$557,'2. RECETAS'!$A$8:$A$557,$A21) -> 100.59 | F21: =IF(D21=0,0,E21/D21) -> 16.765 | G21: =PANEL!$C$7 -> 6 | H21: =PANEL!$C$8 -> 2 | I21: =PANEL!$C$11 -> 4 | J21: =F21+G21+H21+I21 -> 28.765 | K21: =J21*PANEL!$C$12 -> 2.3012 | L21: =PANEL!$C$15 -> 10 | M21: =J21+K21+L21 -> 41.0662 | N21: =IF(PANEL!$C$16>=1,0,M21/(1-PANEL!$C$16)) -> 102.6655 | O21: =IF(PANEL!$C$18<=0,N21,CEILING(N21,PANEL!$C$18)) -> 105 | P21: =O21-M21 -> 63.9338 | Q21: =IF(O21=0,0,P21/O21) -> 0.60889333 | R21: =IF(PANEL!$C$17>=1,0,IF(PANEL!$C$18<=0,M21/(1-PANEL!$C$17),CEILING(M21/(1-PANEL!$C$17),PANEL!$C$18))) -> 65 | S21: =R21-M21 -> 23.9338 | T21: =O21*(1+PANEL!$C$19) -> 121.8 | U21: Intermedio (streusel y manzana rehidratada) | V21: 190 °C | W21: 14 a 16 minutos.
A22: 15 | B22: Galleta Banoffee (Plátano, Toffee y Chocolate) | C22: Cap. 5 · Clásicos de Nueva York | D22: 6 | E22: =SUMIFS('2. RECETAS'!$H$8:$H$557,'2. RECETAS'!$A$8:$A$557,$A22) -> 118.19 | F22: =IF(D22=0,0,E22/D22) -> 19.698333 | G22: =PANEL!$C$7 -> 6 | H22: =PANEL!$C$8 -> 2 | I22: =PANEL!$C$11 -> 4 | J22: =F22+G22+H22+I22 -> 31.698333 | K22: =J22*PANEL!$C$12 -> 2.5358667 | L22: =PANEL!$C$15 -> 10 | M22: =J22+K22+L22 -> 44.2342 | N22: =IF(PANEL!$C$16>=1,0,M22/(1-PANEL!$C$16)) -> 110.5855 | O22: =IF(PANEL!$C$18<=0,N22,CEILING(N22,PANEL!$C$18)) -> 115 | P22: =O22-M22 -> 70.7658 | Q22: =IF(O22=0,0,P22/O22) -> 0.61535478 | R22: =IF(PANEL!$C$17>=1,0,IF(PANEL!$C$18<=0,M22/(1-PANEL!$C$17),CEILING(M22/(1-PANEL!$C$17),PANEL!$C$18))) -> 70 | S22: =R22-M22 -> 25.7658 | T22: =O22*(1+PANEL!$C$19) -> 133.4 | U22: Intermedio (puré de plátano y toffee) | V22: 190 °C | W22: 14 a 16 minutos.
A23: 16 | B23: Volcán de Crema de Avellana (Estilo Nutella) | C23: Cap. 6 · Volcanes y rellenos | D23: 6 | E23: =SUMIFS('2. RECETAS'!$H$8:$H$557,'2. RECETAS'!$A$8:$A$557,$A23) -> 117.94154 | F23: =IF(D23=0,0,E23/D23) -> 19.656923 | G23: =PANEL!$C$7 -> 6 | H23: =PANEL!$C$8 -> 2 | I23: =PANEL!$C$11 -> 4 | J23: =F23+G23+H23+I23 -> 31.656923 | K23: =J23*PANEL!$C$12 -> 2.5325538 | L23: =PANEL!$C$15 -> 10 | M23: =J23+K23+L23 -> 44.189477 | N23: =IF(PANEL!$C$16>=1,0,M23/(1-PANEL!$C$16)) -> 110.47369 | O23: =IF(PANEL!$C$18<=0,N23,CEILING(N23,PANEL!$C$18)) -> 115 | P23: =O23-M23 -> 70.810523 | Q23: =IF(O23=0,0,P23/O23) -> 0.61574368 | R23: =IF(PANEL!$C$17>=1,0,IF(PANEL!$C$18<=0,M23/(1-PANEL!$C$17),CEILING(M23/(1-PANEL!$C$17),PANEL!$C$18))) -> 70 | S23: =R23-M23 -> 25.810523 | T23: =O23*(1+PANEL!$C$19) -> 133.4 | U23: Intermedio (encapsulado de núcleo congelado) | V23: 200 °C | W23: 13 a 15 minutos. Reposo de núcleos Mínimo 6 horas en el congelador. | X23: ◆ FÓRMULA ESTANDARIZADA
A24: 17 | B24: Biscoff Lotus (Masa especiada con centro de crema de galleta) | C24: Cap. 6 · Volcanes y rellenos | D24: 6 | E24: =SUMIFS('2. RECETAS'!$H$8:$H$557,'2. RECETAS'!$A$8:$A$557,$A24) -> 149.31 | F24: =IF(D24=0,0,E24/D24) -> 24.885 | G24: =PANEL!$C$7 -> 6 | H24: =PANEL!$C$8 -> 2 | I24: =PANEL!$C$11 -> 4 | J24: =F24+G24+H24+I24 -> 36.885 | K24: =J24*PANEL!$C$12 -> 2.9508 | L24: =PANEL!$C$15 -> 10 | M24: =J24+K24+L24 -> 49.8358 | N24: =IF(PANEL!$C$16>=1,0,M24/(1-PANEL!$C$16)) -> 124.5895 | O24: =IF(PANEL!$C$18<=0,N24,CEILING(N24,PANEL!$C$18)) -> 125 | P24: =O24-M24 -> 75.1642 | Q24: =IF(O24=0,0,P24/O24) -> 0.6013136 | R24: =IF(PANEL!$C$17>=1,0,IF(PANEL!$C$18<=0,M24/(1-PANEL!$C$17),CEILING(M24/(1-PANEL!$C$17),PANEL!$C$18))) -> 80 | S24: =R24-M24 -> 30.1642 | T24: =O24*(1+PANEL!$C$19) -> 145 | U24: Intermedio (masa especiada + núcleo blando) | V24: 195 °C | W24: 12 a 14 minutos.
A25: 18 | B25: S'mores de Campamento (Centro fundido de malvavisco) | C25: Cap. 6 · Volcanes y rellenos | D25: 6 | E25: =SUMIFS('2. RECETAS'!$H$8:$H$557,'2. RECETAS'!$A$8:$A$557,$A25) -> 105.85235 | F25: =IF(D25=0,0,E25/D25) -> 17.642059 | G25: =PANEL!$C$7 -> 6 | H25: =PANEL!$C$8 -> 2 | I25: =PANEL!$C$11 -> 4 | J25: =F25+G25+H25+I25 -> 29.642059 | K25: =J25*PANEL!$C$12 -> 2.3713647 | L25: =PANEL!$C$15 -> 10 | M25: =J25+K25+L25 -> 42.013424 | N25: =IF(PANEL!$C$16>=1,0,M25/(1-PANEL!$C$16)) -> 105.03356 | O25: =IF(PANEL!$C$18<=0,N25,CEILING(N25,PANEL!$C$18)) -> 110 | P25: =O25-M25 -> 67.986576 | Q25: =IF(O25=0,0,P25/O25) -> 0.61805979 | R25: =IF(PANEL!$C$17>=1,0,IF(PANEL!$C$18<=0,M25/(1-PANEL!$C$17),CEILING(M25/(1-PANEL!$C$17),PANEL!$C$18))) -> 65 | S25: =R25-M25 -> 22.986576 | T25: =O25*(1+PANEL!$C$19) -> 127.6 | U25: Intermedio (el malvavisco exige control de horneado) | V25: 200 °C | W25: 11 a 13 minutos (el malvavisco derretirá rápido). | X25: 4 horas.
A26: 19 | B26: Cajeta y Nuez (Inspiración Dulce de Leche) | C26: Cap. 6 · Volcanes y rellenos | D26: 6 | E26: =SUMIFS('2. RECETAS'!$H$8:$H$557,'2. RECETAS'!$A$8:$A$557,$A26) -> 146.555 | F26: =IF(D26=0,0,E26/D26) -> 24.425833 | G26: =PANEL!$C$7 -> 6 | H26: =PANEL!$C$8 -> 2 | I26: =PANEL!$C$11 -> 4 | J26: =F26+G26+H26+I26 -> 36.425833 | K26: =J26*PANEL!$C$12 -> 2.9140667 | L26: =PANEL!$C$15 -> 10 | M26: =J26+K26+L26 -> 49.3399 | N26: =IF(PANEL!$C$16>=1,0,M26/(1-PANEL!$C$16)) -> 123.34975 | O26: =IF(PANEL!$C$18<=0,N26,CEILING(N26,PANEL!$C$18)) -> 125 | P26: =O26-M26 -> 75.6601 | Q26: =IF(O26=0,0,P26/O26) -> 0.6052808 | R26: =IF(PANEL!$C$17>=1,0,IF(PANEL!$C$18<=0,M26/(1-PANEL!$C$17),CEILING(M26/(1-PANEL!$C$17),PANEL!$C$18))) -> 80 | S26: =R26-M26 -> 30.6601 | T26: =O26*(1+PANEL!$C$19) -> 145 | U26: Intermedio (la cajeta tiende a escurrir si no se congela bien) | V26: 190 °C | W26: 13 a 15 minutos.
A27: 20 | B27: Pistache Intenso con Núcleo de Chocolate Blanco | C27: Cap. 6 · Volcanes y rellenos | D27: 6 | E27: =SUMIFS('2. RECETAS'!$H$8:$H$557,'2. RECETAS'!$A$8:$A$557,$A27) -> 252.62 | F27: =IF(D27=0,0,E27/D27) -> 42.103333 | G27: =PANEL!$C$7 -> 6 | H27: =PANEL!$C$8 -> 2 | I27: =PANEL!$C$11 -> 4 | J27: =F27+G27+H27+I27 -> 54.103333 | K27: =J27*PANEL!$C$12 -> 4.3282667 | L27: =PANEL!$C$15 -> 10 | M27: =J27+K27+L27 -> 68.4316 | N27: =IF(PANEL!$C$16>=1,0,M27/(1-PANEL!$C$16)) -> 171.079 | O27: =IF(PANEL!$C$18<=0,N27,CEILING(N27,PANEL!$C$18)) -> 175 | P27: =O27-M27 -> 106.5684 | Q27: =IF(O27=0,0,P27/O27) -> 0.60896229 | R27: =IF(PANEL!$C$17>=1,0,IF(PANEL!$C$18<=0,M27/(1-PANEL!$C$17),CEILING(M27/(1-PANEL!$C$17),PANEL!$C$18))) -> 110 | S27: =R27-M27 -> 41.5684 | T27: =O27*(1+PANEL!$C$19) -> 203 | U27: Intermedio–Avanzado (ganache blanco 5:1 y núcleo congelado) | V27: 190 °C | W27: 12 a 14 minutos.
A28: 21 | B28: Frambuesa y Centro de Pay de Queso | C28: Cap. 6 · Volcanes y rellenos | D28: 6 | E28: =SUMIFS('2. RECETAS'!$H$8:$H$557,'2. RECETAS'!$A$8:$A$557,$A28) -> 151.45 | F28: =IF(D28=0,0,E28/D28) -> 25.241667 | G28: =PANEL!$C$7 -> 6 | H28: =PANEL!$C$8 -> 2 | I28: =PANEL!$C$11 -> 4 | J28: =F28+G28+H28+I28 -> 37.241667 | K28: =J28*PANEL!$C$12 -> 2.9793333 | L28: =PANEL!$C$15 -> 10 | M28: =J28+K28+L28 -> 50.221 | N28: =IF(PANEL!$C$16>=1,0,M28/(1-PANEL!$C$16)) -> 125.5525 | O28: =IF(PANEL!$C$18<=0,N28,CEILING(N28,PANEL!$C$18)) -> 130 | P28: =O28-M28 -> 79.779 | Q28: =IF(O28=0,0,P28/O28) -> 0.61368462 | R28: =IF(PANEL!$C$17>=1,0,IF(PANEL!$C$18<=0,M28/(1-PANEL!$C$17),CEILING(M28/(1-PANEL!$C$17),PANEL!$C$18))) -> 80 | S28: =R28-M28 -> 29.779 | T28: =O28*(1+PANEL!$C$19) -> 150.8 | U28: Intermedio–Avanzado (núcleo lácteo fresco) | V28: 190 °C | W28: 13 a 15 minutos.
A29: 22 | B29: Kinder Bueno (Masa de cacao ligero y núcleo de avellana | C29: Cap. 6 · Volcanes y rellenos | D29: 6 | E29: =SUMIFS('2. RECETAS'!$H$8:$H$557,'2. RECETAS'!$A$8:$A$557,$A29) -> 202.20429 | F29: =IF(D29=0,0,E29/D29) -> 33.700714 | G29: =PANEL!$C$7 -> 6 | H29: =PANEL!$C$8 -> 2 | I29: =PANEL!$C$11 -> 4 | J29: =F29+G29+H29+I29 -> 45.700714 | K29: =J29*PANEL!$C$12 -> 3.6560571 | L29: =PANEL!$C$15 -> 10 | M29: =J29+K29+L29 -> 59.356771 | N29: =IF(PANEL!$C$16>=1,0,M29/(1-PANEL!$C$16)) -> 148.39193 | O29: =IF(PANEL!$C$18<=0,N29,CEILING(N29,PANEL!$C$18)) -> 150 | P29: =O29-M29 -> 90.643229 | Q29: =IF(O29=0,0,P29/O29) -> 0.60428819 | R29: =IF(PANEL!$C$17>=1,0,IF(PANEL!$C$18<=0,M29/(1-PANEL!$C$17),CEILING(M29/(1-PANEL!$C$17),PANEL!$C$18))) -> 95 | S29: =R29-M29 -> 35.643229 | T29: =O29*(1+PANEL!$C$19) -> 174 | U29: Intermedio (masa de cacao ligero, no alcalino) | V29: 190 °C | W29: 12 a 14 minutos.
A30: 23 | B30: Caramelo Salado y Pretzels | C30: Cap. 6 · Volcanes y rellenos | D30: 6 | E30: =SUMIFS('2. RECETAS'!$H$8:$H$557,'2. RECETAS'!$A$8:$A$557,$A30) -> 122.785 | F30: =IF(D30=0,0,E30/D30) -> 20.464167 | G30: =PANEL!$C$7 -> 6 | H30: =PANEL!$C$8 -> 2 | I30: =PANEL!$C$11 -> 4 | J30: =F30+G30+H30+I30 -> 32.464167 | K30: =J30*PANEL!$C$12 -> 2.5971333 | L30: =PANEL!$C$15 -> 10 | M30: =J30+K30+L30 -> 45.0613 | N30: =IF(PANEL!$C$16>=1,0,M30/(1-PANEL!$C$16)) -> 112.65325 | O30: =IF(PANEL!$C$18<=0,N30,CEILING(N30,PANEL!$C$18)) -> 115 | P30: =O30-M30 -> 69.9387 | Q30: =IF(O30=0,0,P30/O30) -> 0.60816261 | R30: =IF(PANEL!$C$17>=1,0,IF(PANEL!$C$18<=0,M30/(1-PANEL!$C$17),CEILING(M30/(1-PANEL!$C$17),PANEL!$C$18))) -> 70 | S30: =R30-M30 -> 24.9387 | T30: =O30*(1+PANEL!$C$19) -> 133.4 | U30: Intermedio (equilibrio dulce–salado) | V30: 190 °C | W30: 13 a 15 minutos.
A31: 24 | B31: Ferrero Rocher (Masa de avellana y corazón de ganache | C31: Cap. 6 · Volcanes y rellenos | D31: 6 | E31: =SUMIFS('2. RECETAS'!$H$8:$H$557,'2. RECETAS'!$A$8:$A$557,$A31) -> 170.45 | F31: =IF(D31=0,0,E31/D31) -> 28.408333 | G31: =PANEL!$C$7 -> 6 | H31: =PANEL!$C$8 -> 2 | I31: =PANEL!$C$11 -> 4 | J31: =F31+G31+H31+I31 -> 40.408333 | K31: =J31*PANEL!$C$12 -> 3.2326667 | L31: =PANEL!$C$15 -> 10 | M31: =J31+K31+L31 -> 53.641 | N31: =IF(PANEL!$C$16>=1,0,M31/(1-PANEL!$C$16)) -> 134.1025 | O31: =IF(PANEL!$C$18<=0,N31,CEILING(N31,PANEL!$C$18)) -> 135 | P31: =O31-M31 -> 81.359 | Q31: =IF(O31=0,0,P31/O31) -> 0.60265926 | R31: =IF(PANEL!$C$17>=1,0,IF(PANEL!$C$18<=0,M31/(1-PANEL!$C$17),CEILING(M31/(1-PANEL!$C$17),PANEL!$C$18))) -> 85 | S31: =R31-M31 -> 31.359 | T31: =O31*(1+PANEL!$C$19) -> 156.6 | U31: Avanzado (masa de avellana + ganache oscuro) | V31: 190 °C | W31: 12 a 14 minutos.
A32: 25 | B32: Volcán de Matcha (Núcleo de ganache blanco fluido) | C32: Cap. 6 · Volcanes y rellenos | D32: 6 | E32: =SUMIFS('2. RECETAS'!$H$8:$H$557,'2. RECETAS'!$A$8:$A$557,$A32) -> 163.37 | F32: =IF(D32=0,0,E32/D32) -> 27.228333 | G32: =PANEL!$C$7 -> 6 | H32: =PANEL!$C$8 -> 2 | I32: =PANEL!$C$11 -> 4 | J32: =F32+G32+H32+I32 -> 39.228333 | K32: =J32*PANEL!$C$12 -> 3.1382667 | L32: =PANEL!$C$15 -> 10 | M32: =J32+K32+L32 -> 52.3666 | N32: =IF(PANEL!$C$16>=1,0,M32/(1-PANEL!$C$16)) -> 130.9165 | O32: =IF(PANEL!$C$18<=0,N32,CEILING(N32,PANEL!$C$18)) -> 135 | P32: =O32-M32 -> 82.6334 | Q32: =IF(O32=0,0,P32/O32) -> 0.61209926 | R32: =IF(PANEL!$C$17>=1,0,IF(PANEL!$C$18<=0,M32/(1-PANEL!$C$17),CEILING(M32/(1-PANEL!$C$17),PANEL!$C$18))) -> 85 | S32: =R32-M32 -> 32.6334 | T32: =O32*(1+PANEL!$C$19) -> 156.6 | U32: Intermedio–Avanzado (ganache blanco fluido con matcha) | V32: 185 °C (temperatura ligeramente menor para preservar el verde). | W32: 13 a 15 minutos.
A33: 26 | B33: Galleta Tiramisú (Centro de Mascarpone y Masa de Café) | C33: Cap. 7 · Postres reinventados y festivos | D33: 6 | E33: =SUMIFS('2. RECETAS'!$H$8:$H$557,'2. RECETAS'!$A$8:$A$557,$A33) -> 126.38 | F33: =IF(D33=0,0,E33/D33) -> 21.063333 | G33: =PANEL!$C$7 -> 6 | H33: =PANEL!$C$8 -> 2 | I33: =PANEL!$C$11 -> 4 | J33: =F33+G33+H33+I33 -> 33.063333 | K33: =J33*PANEL!$C$12 -> 2.6450667 | L33: =PANEL!$C$15 -> 10 | M33: =J33+K33+L33 -> 45.7084 | N33: =IF(PANEL!$C$16>=1,0,M33/(1-PANEL!$C$16)) -> 114.271 | O33: =IF(PANEL!$C$18<=0,N33,CEILING(N33,PANEL!$C$18)) -> 115 | P33: =O33-M33 -> 69.2916 | Q33: =IF(O33=0,0,P33/O33) -> 0.60253565 | R33: =IF(PANEL!$C$17>=1,0,IF(PANEL!$C$18<=0,M33/(1-PANEL!$C$17),CEILING(M33/(1-PANEL!$C$17),PANEL!$C$18))) -> 75 | S33: =R33-M33 -> 29.2916 | T33: =O33*(1+PANEL!$C$19) -> 133.4 | U33: Avanzado (mascarpone congelado + masa de café) | V33: 190 °C | W33: 13 a 15 minutos.
A34: 27 | B34: Galleta de Pay de Limón (Masa de Galleta María y Centro | C34: Cap. 7 · Postres reinventados y festivos | D34: 6 | E34: =SUMIFS('2. RECETAS'!$H$8:$H$557,'2. RECETAS'!$A$8:$A$557,$A34) -> 106.32364 | F34: =IF(D34=0,0,E34/D34) -> 17.720607 | G34: =PANEL!$C$7 -> 6 | H34: =PANEL!$C$8 -> 2 | I34: =PANEL!$C$11 -> 4 | J34: =F34+G34+H34+I34 -> 29.720607 | K34: =J34*PANEL!$C$12 -> 2.3776486 | L34: =PANEL!$C$15 -> 10 | M34: =J34+K34+L34 -> 42.098256 | N34: =IF(PANEL!$C$16>=1,0,M34/(1-PANEL!$C$16)) -> 105.24564 | O34: =IF(PANEL!$C$18<=0,N34,CEILING(N34,PANEL!$C$18)) -> 110 | P34: =O34-M34 -> 67.901744 | Q34: =IF(O34=0,0,P34/O34) -> 0.61728858 | R34: =IF(PANEL!$C$17>=1,0,IF(PANEL!$C$18<=0,M34/(1-PANEL!$C$17),CEILING(M34/(1-PANEL!$C$17),PANEL!$C$18))) -> 65 | S34: =R34-M34 -> 22.901744 | T34: =O34*(1+PANEL!$C$19) -> 127.6 | U34: Intermedio–Avanzado (curd cítrico congelado) | V34: 190 °C | W34: 12 a 14 minutos.
A35: 28 | B35: Churro Relleno (Masa Estriada de Canela con Centro Dulce) | C35: Cap. 7 · Postres reinventados y festivos | D35: 6 | E35: =SUMIFS('2. RECETAS'!$H$8:$H$557,'2. RECETAS'!$A$8:$A$557,$A35) -> 86.085 | F35: =IF(D35=0,0,E35/D35) -> 14.3475 | G35: =PANEL!$C$7 -> 6 | H35: =PANEL!$C$8 -> 2 | I35: =PANEL!$C$11 -> 4 | J35: =F35+G35+H35+I35 -> 26.3475 | K35: =J35*PANEL!$C$12 -> 2.1078 | L35: =PANEL!$C$15 -> 10 | M35: =J35+K35+L35 -> 38.4553 | N35: =IF(PANEL!$C$16>=1,0,M35/(1-PANEL!$C$16)) -> 96.13825 | O35: =IF(PANEL!$C$18<=0,N35,CEILING(N35,PANEL!$C$18)) -> 100 | P35: =O35-M35 -> 61.5447 | Q35: =IF(O35=0,0,P35/O35) -> 0.615447 | R35: =IF(PANEL!$C$17>=1,0,IF(PANEL!$C$18<=0,M35/(1-PANEL!$C$17),CEILING(M35/(1-PANEL!$C$17),PANEL!$C$18))) -> 60 | S35: =R35-M35 -> 21.5447 | T35: =O35*(1+PANEL!$C$19) -> 116 | U35: Intermedio (estriado de canela + núcleo dulce) | V35: 195 °C | W35: 13 a 15 minutos.
A36: 29 | B36: Galleta Tres Leches (Base Avainillada y Glaseado Lechoso) | C36: Cap. 7 · Postres reinventados y festivos | D36: 6 | E36: =SUMIFS('2. RECETAS'!$H$8:$H$557,'2. RECETAS'!$A$8:$A$557,$A36) -> 89.74 | F36: =IF(D36=0,0,E36/D36) -> 14.956667 | G36: =PANEL!$C$7 -> 6 | H36: =PANEL!$C$8 -> 2 | I36: =PANEL!$C$11 -> 4 | J36: =F36+G36+H36+I36 -> 26.956667 | K36: =J36*PANEL!$C$12 -> 2.1565333 | L36: =PANEL!$C$15 -> 10 | M36: =J36+K36+L36 -> 39.1132 | N36: =IF(PANEL!$C$16>=1,0,M36/(1-PANEL!$C$16)) -> 97.783 | O36: =IF(PANEL!$C$18<=0,N36,CEILING(N36,PANEL!$C$18)) -> 100 | P36: =O36-M36 -> 60.8868 | Q36: =IF(O36=0,0,P36/O36) -> 0.608868 | R36: =IF(PANEL!$C$17>=1,0,IF(PANEL!$C$18<=0,M36/(1-PANEL!$C$17),CEILING(M36/(1-PANEL!$C$17),PANEL!$C$18))) -> 65 | S36: =R36-M36 -> 25.8868 | T36: =O36*(1+PANEL!$C$19) -> 116 | U36: Intermedio–Avanzado (glaseado lechoso sin encharcar la miga) | V36: 190 °C | W36: 14 a 16 minutos.
A37: 30 | B37: Tarta de Pecanas (Masa Mantequilluda y Nido Caramelizado) | C37: Cap. 7 · Postres reinventados y festivos | D37: 6 | E37: =SUMIFS('2. RECETAS'!$H$8:$H$557,'2. RECETAS'!$A$8:$A$557,$A37) -> 65.85 | F37: =IF(D37=0,0,E37/D37) -> 10.975 | G37: =PANEL!$C$7 -> 6 | H37: =PANEL!$C$8 -> 2 | I37: =PANEL!$C$11 -> 4 | J37: =F37+G37+H37+I37 -> 22.975 | K37: =J37*PANEL!$C$12 -> 1.838 | L37: =PANEL!$C$15 -> 10 | M37: =J37+K37+L37 -> 34.813 | N37: =IF(PANEL!$C$16>=1,0,M37/(1-PANEL!$C$16)) -> 87.0325 | O37: =IF(PANEL!$C$18<=0,N37,CEILING(N37,PANEL!$C$18)) -> 90 | P37: =O37-M37 -> 55.187 | Q37: =IF(O37=0,0,P37/O37) -> 0.61318889 | R37: =IF(PANEL!$C$17>=1,0,IF(PANEL!$C$18<=0,M37/(1-PANEL!$C$17),CEILING(M37/(1-PANEL!$C$17),PANEL!$C$18))) -> 55 | S37: =R37-M37 -> 20.187 | T37: =O37*(1+PANEL!$C$19) -> 104.4 | U37: Intermedio (nido caramelizado de pecana) | V37: 190 °C | W37: 14 a 16 minutos.
... A48: 41 | B48: Miso Blanco, Chocolate Rubio (Gold) y Sésamo Tostado | C48: Cap. 8 · Alta gama y autor | D48: 6 | E48: =SUMIFS('2. RECETAS'!$H$8:$H$557,'2. RECETAS'!$A$8:$A$557,$A48) -> 162.21 | F48: =IF(D48=0,0,E48/D48) -> 27.035 | G48: =PANEL!$C$7 -> 6 | H48: =PANEL!$C$8 -> 2 | I48: =PANEL!$C$11 -> 4 | J48: =F48+G48+H48+I48 -> 39.035 | K48: =J48*PANEL!$C$12 -> 3.1228 | L48: =PANEL!$C$15 -> 10 | M48: =J48+K48+L48 -> 52.1578 | N48: =IF(PANEL!$C$16>=1,0,M48/(1-PANEL!$C$16)) -> 130.3945 | O48: =IF(PANEL!$C$18<=0,N48,CEILING(N48,PANEL!$C$18)) -> 135 | P48: =O48-M48 -> 82.8422 | Q48: =IF(O48=0,0,P48/O48) -> 0.61364593 | R48: =IF(PANEL!$C$17>=1,0,IF(PANEL!$C$18<=0,M48/(1-PANEL!$C$17),CEILING(M48/(1-PANEL!$C$17),PANEL!$C$18))) -> 85 | S48: =R48-M48 -> 32.8422 | T48: =O48*(1+PANEL!$C$19) -> 156.6 | U48: Avanzado (umami láctico con miso) | V48: 190 °C | W48: 13 a 15 minutos.
A49: 42 | B49: Aceite de Oliva Extra Virgen, Romero y Chocolate Oscuro 70% | C49: Cap. 8 · Alta gama y autor | D49: 6 | E49: =SUMIFS('2. RECETAS'!$H$8:$H$557,'2. RECETAS'!$A$8:$A$557,$A49) -> 114.98 | F49: =IF(D49=0,0,E49/D49) -> 19.163333 | G49: =PANEL!$C$7 -> 6 | H49: =PANEL!$C$8 -> 2 | I49: =PANEL!$C$11 -> 4 | J49: =F49+G49+H49+I49 -> 31.163333 | K49: =J49*PANEL!$C$12 -> 2.4930667 | L49: =PANEL!$C$15 -> 10 | M49: =J49+K49+L49 -> 43.6564 | N49: =IF(PANEL!$C$16>=1,0,M49/(1-PANEL!$C$16)) -> 109.141 | O49: =IF(PANEL!$C$18<=0,N49,CEILING(N49,PANEL!$C$18)) -> 110 | P49: =O49-M49 -> 66.3436 | Q49: =IF(O49=0,0,P49/O49) -> 0.60312364 | R49: =IF(PANEL!$C$17>=1,0,IF(PANEL!$C$18<=0,M49/(1-PANEL!$C$17),CEILING(M49/(1-PANEL!$C$17),PANEL!$C$18))) -> 70 | S49: =R49-M49 -> 26.3436 | T49: =O49*(1+PANEL!$C$19) -> 127.6 | U49: Intermedio–Avanzado (grasa vegetal y herbal en masa) | V49: 190 °C | W49: 12 a 14 minutos. | X49: 6 horas mínimo (crucial por el aceite líquido).
A50: 43 | B50: Queso Azul, Compota de Higo y Nuez Caramelizada | C50: Cap. 8 · Alta gama y autor | D50: 6 | E50: =SUMIFS('2. RECETAS'!$H$8:$H$557,'2. RECETAS'!$A$8:$A$557,$A50) -> 153.89 | F50: =IF(D50=0,0,E50/D50) -> 25.648333 | G50: =PANEL!$C$7 -> 6 | H50: =PANEL!$C$8 -> 2 | I50: =PANEL!$C$11 -> 4 | J50: =F50+G50+H50+I50 -> 37.648333 | K50: =J50*PANEL!$C$12 -> 3.0118667 | L50: =PANEL!$C$15 -> 10 | M50: =J50+K50+L50 -> 50.6602 | N50: =IF(PANEL!$C$16>=1,0,M50/(1-PANEL!$C$16)) -> 126.6505 | O50: =IF(PANEL!$C$18<=0,N50,CEILING(N50,PANEL!$C$18)) -> 130 | P50: =O50-M50 -> 79.3398 | Q50: =IF(O50=0,0,P50/O50) -> 0.61030615 | R50: =IF(PANEL!$C$17>=1,0,IF(PANEL!$C$18<=0,M50/(1-PANEL!$C$17),CEILING(M50/(1-PANEL!$C$17),PANEL!$C$18))) -> 80 | S50: =R50-M50 -> 29.3398 | T50: =O50*(1+PANEL!$C$19) -> 150.8 | U50: Avanzado (queso azul con alta humedad y sal) | V50: 190 °C | W50: 14 a 16 minutos.
A51: 44 | B51: Tocino Glaseado en Maple y Chunks de Chocolate con Leche | C51: Cap. 8 · Alta gama y autor | D51: 6 | E51: =SUMIFS('2. RECETAS'!$H$8:$H$557,'2. RECETAS'!$A$8:$A$557,$A51) -> 91.11 | F51: =IF(D51=0,0,E51/D51) -> 15.185 | G51: =PANEL!$C$7 -> 6 | H51: =PANEL!$C$8 -> 2 | I51: =PANEL!$C$11 -> 4 | J51: =F51+G51+H51+I51 -> 27.185 | K51: =J51*PANEL!$C$12 -> 2.1748 | L51: =PANEL!$C$15 -> 10 | M51: =J51+K51+L51 -> 39.3598 | N51: =IF(PANEL!$C$16>=1,0,M51/(1-PANEL!$C$16)) -> 98.3995 | O51: =IF(PANEL!$C$18<=0,N51,CEILING(N51,PANEL!$C$18)) -> 100 | P51: =O51-M51 -> 60.6402 | Q51: =IF(O51=0,0,P51/O51) -> 0.606402 | R51: =IF(PANEL!$C$17>=1,0,IF(PANEL!$C$18<=0,M51/(1-PANEL!$C$17),CEILING(M51/(1-PANEL!$C$17),PANEL!$C$18))) -> 65 | S51: =R51-M51 -> 25.6402 | T51: =O51*(1+PANEL!$C$19) -> 116 | U51: Avanzado (tocino glaseado que debe quedar crujiente) | V51: 190 °C | W51: 13 a 15 minutos.
A52: 45 | B52: Trufa Negra y Chocolate Semiamargo con Sal en Escamas | C52: Cap. 8 · Alta gama y autor | D52: 6 | E52: =SUMIFS('2. RECETAS'!$H$8:$H$557,'2. RECETAS'!$A$8:$A$557,$A52) -> 151.03 | F52: =IF(D52=0,0,E52/D52) -> 25.171667 | G52: =PANEL!$C$7 -> 6 | H52: =PANEL!$C$8 -> 2 | I52: =PANEL!$C$11 -> 4 | J52: =F52+G52+H52+I52 -> 37.171667 | K52: =J52*PANEL!$C$12 -> 2.9737333 | L52: =PANEL!$C$15 -> 10 | M52: =J52+K52+L52 -> 50.1454 | N52: =IF(PANEL!$C$16>=1,0,M52/(1-PANEL!$C$16)) -> 125.3635 | O52: =IF(PANEL!$C$18<=0,N52,CEILING(N52,PANEL!$C$18)) -> 130 | P52: =O52-M52 -> 79.8546 | Q52: =IF(O52=0,0,P52/O52) -> 0.61426615 | R52: =IF(PANEL!$C$17>=1,0,IF(PANEL!$C$18<=0,M52/(1-PANEL!$C$17),CEILING(M52/(1-PANEL!$C$17),PANEL!$C$18))) -> 80 | S52: =R52-M52 -> 29.8546 | T52: =O52*(1+PANEL!$C$19) -> 150.8 | U52: Avanzado (trufa negra, ingrediente volátil y costoso) | V52: 190 °C | W52: 12 a 14 minutos.
A53: 46 | B53: Matcha, Yuzu y Chocolate Blanco Caramelizado (Gold) | C53: Cap. 8 · Alta gama y autor | D53: 6 | E53: =SUMIFS('2. RECETAS'!$H$8:$H$557,'2. RECETAS'!$A$8:$A$557,$A53) -> 218.77 | F53: =IF(D53=0,0,E53/D53) -> 36.461667 | G53: =PANEL!$C$7 -> 6 | H53: =PANEL!$C$8 -> 2 | I53: =PANEL!$C$11 -> 4 | J53: =F53+G53+H53+I53 -> 48.461667 | K53: =J53*PANEL!$C$12 -> 3.8769333 | L53: =PANEL!$C$15 -> 10 | M53: =J53+K53+L53 -> 62.3386 | N53: =IF(PANEL!$C$16>=1,0,M53/(1-PANEL!$C$16)) -> 155.8465 | O53: =IF(PANEL!$C$18<=0,N53,CEILING(N53,PANEL!$C$18)) -> 160 | P53: =O53-M53 -> 97.6614 | Q53: =IF(O53=0,0,P53/O53) -> 0.61038375 | R53: =IF(PANEL!$C$17>=1,0,IF(PANEL!$C$18<=0,M53/(1-PANEL!$C$17),CEILING(M53/(1-PANEL!$C$17),PANEL!$C$18))) -> 100 | S53: =R53-M53 -> 37.6614 | T53: =O53*(1+PANEL!$C$19) -> 185.6 | U53: Avanzado (matcha + yuzu, dos ácidos delicados) | V53: 185 °C (temperatura cuidada para no oxidar el verde del té). | W53: 13 a 15 minutos.
...

Sheet 4. PRODUCCIÓN
A1: ENDULCORA · ESTUDIO GASTRONÓMICO
A2: 4 · Plan de producción
A3: Elige las recetas del menú ▼ y cuántos lotes vas a hornear. La hoja «5. COMPRAS» arma sola tu lista de mercado.
A7: Receta a producir (elige del menú ▼) | B7: # | C7: Piezas por lote | D7: Lotes a producir | E7: Piezas totales | F7: Costo total de producción | G7: Ingreso estimado (menudeo) | H7: Utilidad estimada
B8: =IFERROR(INDEX('3. COSTEO'!$A$8:$A$57,MATCH($A8,'3. COSTEO'!$B$8:$B$57,0)),"") | C8: =IFERROR(INDEX('3. COSTEO'!$D$8:$D$57,MATCH($A8,'3. COSTEO'!$B$8:$B$57,0)),"") | D8: 0 | E8: =IF($A8="","",C8*D8) | F8: =IF($A8="","",E8*INDEX('3. COSTEO'!$M$8:$M$57,MATCH($A8,'3. COSTEO'!$B$8:$B$57,0))) | G8: =IF($A8="","",E8*INDEX('3. COSTEO'!$O$8:$O$57,MATCH($A8,'3. COSTEO'!$B$8:$B$57,0))) | H8: =IF($A8="","",G8-F8)
B9: =IFERROR(INDEX('3. COSTEO'!$A$8:$A$57,MATCH($A9,'3. COSTEO'!$B$8:$B$57,0)),"") | C9: =IFERROR(INDEX('3. COSTEO'!$D$8:$D$57,MATCH($A9,'3. COSTEO'!$B$8:$B$57,0)),"") | D9: 0 | E9: =IF($A9="","",C9*D9) | F9: =IF($A9="","",E9*INDEX('3. COSTEO'!$M$8:$M$57,MATCH($A9,'3. COSTEO'!$B$8:$B$57,0))) | G9: =IF($A9="","",E9*INDEX('3. COSTEO'!$O$8:$O$57,MATCH($A9,'3. COSTEO'!$B$8:$B$57,0))) | H9: =IF($A9="","",G9-F9)
B10: =IFERROR(INDEX('3. COSTEO'!$A$8:$A$57,MATCH($A10,'3. COSTEO'!$B$8:$B$57,0)),"") | C10: =IFERROR(INDEX('3. COSTEO'!$D$8:$D$57,MATCH($A10,'3. COSTEO'!$B$8:$B$57,0)),"") | D10: 0 | E10: =IF($A10="","",C10*D10) | F10: =IF($A10="","",E10*INDEX('3. COSTEO'!$M$8:$M$57,MATCH($A10,'3. COSTEO'!$B$8:$B$57,0))) | G10: =IF($A10="","",E10*INDEX('3. COSTEO'!$O$8:$O$57,MATCH($A10,'3. COSTEO'!$B$8:$B$57,0))) | H10: =IF($A10="","",G10-F10)
B11: =IFERROR(INDEX('3. COSTEO'!$A$8:$A$57,MATCH($A11,'3. COSTEO'!$B$8:$B$57,0)),"") | C11: =IFERROR(INDEX('3. COSTEO'!$D$8:$D$57,MATCH($A11,'3. COSTEO'!$B$8:$B$57,0)),"") | D11: 0 | E11: =IF($A11="","",C11*D11) | F11: =IF($A11="","",E11*INDEX('3. COSTEO'!$M$8:$M$57,MATCH($A11,'3. COSTEO'!$B$8:$B$57,0))) | G11: =IF($A11="","",E11*INDEX('3. COSTEO'!$O$8:$O$57,MATCH($A11,'3. COSTEO'!$B$8:$B$57,0))) | H11: =IF($A11="","",G11-F11)
B12: =IFERROR(INDEX('3. COSTEO'!$A$8:$A$57,MATCH($A12,'3. COSTEO'!$B$8:$B$57,0)),"") | C12: =IFERROR(INDEX('3. COSTEO'!$D$8:$D$57,MATCH($A12,'3. COSTEO'!$B$8:$B$57,0)),"") | D12: 0 | E12: =IF($A12="","",C12*D12) | F12: =IF($A12="","",E12*INDEX('3. COSTEO'!$M$8:$M$57,MATCH($A12,'3. COSTEO'!$B$8:$B$57,0))) | G12: =IF($A12="","",E12*INDEX('3. COSTEO'!$O$8:$O$57,MATCH($A12,'3. COSTEO'!$B$8:$B$57,0))) | H12: =IF($A12="","",G12-F12)
B13: =IFERROR(INDEX('3. COSTEO'!$A$8:$A$57,MATCH($A13,'3. COSTEO'!$B$8:$B$57,0)),"") | C13: =IFERROR(INDEX('3. COSTEO'!$D$8:$D$57,MATCH($A13,'3. COSTEO'!$B$8:$B$57,0)),"") | D13: 0 | E13: =IF($A13="","",C13*D13) | F13: =IF($A13="","",E13*INDEX('3. COSTEO'!$M$8:$M$57,MATCH($A13,'3. COSTEO'!$B$8:$B$57,0))) | G13: =IF($A13="","",E13*INDEX('3. COSTEO'!$O$8:$O$57,MATCH($A13,'3. COSTEO'!$B$8:$B$57,0))) | H13: =IF($A13="","",G13-F13)
B14: =IFERROR(INDEX('3. COSTEO'!$A$8:$A$57,MATCH($A14,'3. COSTEO'!$B$8:$B$57,0)),"") | C14: =IFERROR(INDEX('3. COSTEO'!$D$8:$D$57,MATCH($A14,'3. COSTEO'!$B$8:$B$57,0)),"") | D14: 0 | E14: =IF($A14="","",C14*D14) | F14: =IF($A14="","",E14*INDEX('3. COSTEO'!$M$8:$M$57,MATCH($A14,'3. COSTEO'!$B$8:$B$57,0))) | G14: =IF($A14="","",E14*INDEX('3. COSTEO'!$O$8:$O$57,MATCH($A14,'3. COSTEO'!$B$8:$B$57,0))) | H14: =IF($A14="","",G14-F14)
B15: =IFERROR(INDEX('3. COSTEO'!$A$8:$A$57,MATCH($A15,'3. COSTEO'!$B$8:$B$57,0)),"") | C15: =IFERROR(INDEX('3. COSTEO'!$D$8:$D$57,MATCH($A15,'3. COSTEO'!$B$8:$B$57,0)),"") | D15: 0 | E15: =IF($A15="","",C15*D15) | F15: =IF($A15="","",E15*INDEX('3. COSTEO'!$M$8:$M$57,MATCH($A15,'3. COSTEO'!$B$8:$B$57,0))) | G15: =IF($A15="","",E15*INDEX('3. COSTEO'!$O$8:$O$57,MATCH($A15,'3. COSTEO'!$B$8:$B$57,0))) | H15: =IF($A15="","",G15-F15)
B16: =IFERROR(INDEX('3. COSTEO'!$A$8:$A$57,MATCH($A16,'3. COSTEO'!$B$8:$B$57,0)),"") | C16: =IFERROR(INDEX('3. COSTEO'!$D$8:$D$57,MATCH($A16,'3. COSTEO'!$B$8:$B$57,0)),"") | D16: 0 | E16: =IF($A16="","",C16*D16) | F16: =IF($A16="","",E16*INDEX('3. COSTEO'!$M$8:$M$57,MATCH($A16,'3. COSTEO'!$B$8:$B$57,0))) | G16: =IF($A16="","",E16*INDEX('3. COSTEO'!$O$8:$O$57,MATCH($A16,'3. COSTEO'!$B$8:$B$57,0))) | H16: =IF($A16="","",G16-F16)
B17: =IFERROR(INDEX('3. COSTEO'!$A$8:$A$57,MATCH($A17,'3. COSTEO'!$B$8:$B$57,0)),"") | C17: =IFERROR(INDEX('3. COSTEO'!$D$8:$D$57,MATCH($A17,'3. COSTEO'!$B$8:$B$57,0)),"") | D17: 0 | E17: =IF($A17="","",C17*D17) | F17: =IF($A17="","",E17*INDEX('3. COSTEO'!$M$8:$M$57,MATCH($A17,'3. COSTEO'!$B$8:$B$57,0))) | G17: =IF($A17="","",E17*INDEX('3. COSTEO'!$O$8:$O$57,MATCH($A17,'3. COSTEO'!$B$8:$B$57,0))) | H17: =IF($A17="","",G17-F17)
B18: =IFERROR(INDEX('3. COSTEO'!$A$8:$A$57,MATCH($A18,'3. COSTEO'!$B$8:$B$57,0)),"") | C18: =IFERROR(INDEX('3. COSTEO'!$D$8:$D$57,MATCH($A18,'3. COSTEO'!$B$8:$B$57,0)),"") | D18: 0 | E18: =IF($A18="","",C18*D18) | F18: =IF($A18="","",E18*INDEX('3. COSTEO'!$M$8:$M$57,MATCH($A18,'3. COSTEO'!$B$8:$B$57,0))) | G18: =IF($A18="","",E18*INDEX('3. COSTEO'!$O$8:$O$57,MATCH($A18,'3. COSTEO'!$B$8:$B$57,0))) | H18: =IF($A18="","",G18-F18)
B19: =IFERROR(INDEX('3. COSTEO'!$A$8:$A$57,MATCH($A19,'3. COSTEO'!$B$8:$B$57,0)),"") | C19: =IFERROR(INDEX('3. COSTEO'!$D$8:$D$57,MATCH($A19,'3. COSTEO'!$B$8:$B$57,0)),"") | D19: 0 | E19: =IF($A19="","",C19*D19) | F19: =IF($A19="","",E19*INDEX('3. COSTEO'!$M$8:$M$57,MATCH($A19,'3. COSTEO'!$B$8:$B$57,0))) | G19: =IF($A19="","",E19*INDEX('3. COSTEO'!$O$8:$O$57,MATCH($A19,'3. COSTEO'!$B$8:$B$57,0))) | H19: =IF($A19="","",G19-F19)
... B32: =IFERROR(INDEX('3. COSTEO'!$A$8:$A$57,MATCH($A32,'3. COSTEO'!$B$8:$B$57,0)),"") | C32: =IFERROR(INDEX('3. COSTEO'!$D$8:$D$57,MATCH($A32,'3. COSTEO'!$B$8:$B$57,0)),"") | D32: 0 | E32: =IF($A32="","",C32*D32) | F32: =IF($A32="","",E32*INDEX('3. COSTEO'!$M$8:$M$57,MATCH($A32,'3. COSTEO'!$B$8:$B$57,0))) | G32: =IF($A32="","",E32*INDEX('3. COSTEO'!$O$8:$O$57,MATCH($A32,'3. COSTEO'!$B$8:$B$57,0))) | H32: =IF($A32="","",G32-F32)
A33: TOTALES DEL PLAN | E33: =SUM(E8:E32) -> 0 | F33: =SUM(F8:F32) -> 0 | G33: =SUM(G8:G32) -> 0 | H33: =SUM(H8:H32) -> 0
A35: Ejemplo: escribe 3 lotes de la Receta 01 y verás en «5. COMPRAS» exactamente cuántos kilos de mantequilla y chocolate necesitas comprar.

Sheet 5. COMPRAS
A1: ENDULCORA · ESTUDIO GASTRONÓMICO
A2: 5 · Lista de compras automática
A3: Se llena sola con lo que hayas capturado en «4. PRODUCCIÓN». Filtra la columna «Cantidad requerida» para ver solo lo que sí necesitas.
A7: Insumo | B7: Categoría | C7: Unidad | D7: Cantidad requerida | E7: Trae la presentación | F7: Paquetes a comprar | G7: Precio por paquete | H7: Inversión en compra | I7: Costo realmente consumido
A8: Mantequilla sin sal | B8: ='1. INSUMOS'!C8 -> Lácteos y grasas | C8: ='1. INSUMOS'!D8 -> g | D8: =SUMIFS('2. RECETAS'!$J$8:$J$557,'2. RECETAS'!$D$8:$D$557,$A8) -> 0 | E8: ='1. INSUMOS'!F8 -> 1000 | F8: =IF(OR(D8=0,E8=0),0,ROUNDUP(D8/E8,0)) -> 0 | G8: ='1. INSUMOS'!G8 -> 210 | H8: =F8*G8 -> 0 | I8: =D8*'1. INSUMOS'!H8 -> 0
A9: Queso crema (bloque firme) | B9: ='1. INSUMOS'!C9 -> Lácteos y grasas | C9: ='1. INSUMOS'!D9 -> g | D9: =SUMIFS('2. RECETAS'!$J$8:$J$557,'2. RECETAS'!$D$8:$D$557,$A9) -> 0 | E9: ='1. INSUMOS'!F9 -> 1000 | F9: =IF(OR(D9=0,E9=0),0,ROUNDUP(D9/E9,0)) -> 0 | G9: ='1. INSUMOS'!G9 -> 185 | H9: =F9*G9 -> 0 | I9: =D9*'1. INSUMOS'!H9 -> 0
A10: Queso mascarpone | B10: ='1. INSUMOS'!C10 -> Lácteos y grasas | C10: ='1. INSUMOS'!D10 -> g | D10: =SUMIFS('2. RECETAS'!$J$8:$J$557,'2. RECETAS'!$D$8:$D$557,$A10) -> 0 | E10: ='1. INSUMOS'!F10 -> 500 | F10: =IF(OR(D10=0,E10=0),0,ROUNDUP(D10/E10,0)) -> 0 | G10: ='1. INSUMOS'!G10 -> 180 | H10: =F10*G10 -> 0 | I10: =D10*'1. INSUMOS'!H10 -> 0
A11: Queso azul | B11: ='1. INSUMOS'!C11 -> Lácteos y grasas | C11: ='1. INSUMOS'!D11 -> g | D11: =SUMIFS('2. RECETAS'!$J$8:$J$557,'2. RECETAS'!$D$8:$D$557,$A11) -> 0 | E11: ='1. INSUMOS'!F11 -> 250 | F11: =IF(OR(D11=0,E11=0),0,ROUNDUP(D11/E11,0)) -> 0 | G11: ='1. INSUMOS'!G11 -> 145 | H11: =F11*G11 -> 0 | I11: =D11*'1. INSUMOS'!H11 -> 0
A12: Leche condensada | B12: ='1. INSUMOS'!C12 -> Lácteos y grasas | C12: ='1. INSUMOS'!D12 -> g | D12: =SUMIFS('2. RECETAS'!$J$8:$J$557,'2. RECETAS'!$D$8:$D$557,$A12) -> 0 | E12: ='1. INSUMOS'!F12 -> 397 | F12: =IF(OR(D12=0,E12=0),0,ROUNDUP(D12/E12,0)) -> 0 | G12: ='1. INSUMOS'!G12 -> 34 | H12: =F12*G12 -> 0 | I12: =D12*'1. INSUMOS'!H12 -> 0
A13: Aceite de oliva extra virgen | B13: ='1. INSUMOS'!C13 -> Lácteos y grasas | C13: ='1. INSUMOS'!D13 -> ml | D13: =SUMIFS('2. RECETAS'!$J$8:$J$557,'2. RECETAS'!$D$8:$D$557,$A13) -> 0 | E13: ='1. INSUMOS'!F13 -> 500 | F13: =IF(OR(D13=0,E13=0),0,ROUNDUP(D13/E13,0)) -> 0 | G13: ='1. INSUMOS'!G13 -> 150 | H13: =F13*G13 -> 0 | I13: =D13*'1. INSUMOS'!H13 -> 0
A14: Aceite de trufa negra | B14: ='1. INSUMOS'!C14 -> Lácteos y grasas | C14: ='1. INSUMOS'!D14 -> ml | D14: =SUMIFS('2. RECETAS'!$J$8:$J$557,'2. RECETAS'!$D$8:$D$557,$A14) -> 0 | E14: ='1. INSUMOS'!F14 -> 50 | F14: =IF(OR(D14=0,E14=0),0,ROUNDUP(D14/E14,0)) -> 0 | G14: ='1. INSUMOS'!G14 -> 260 | H14: =F14*G14 -> 0 | I14: =D14*'1. INSUMOS'!H14 -> 0
A15: Azúcar refinada | B15: ='1. INSUMOS'!C15 -> Azúcares | C15: ='1. INSUMOS'!D15 -> g | D15: =SUMIFS('2. RECETAS'!$J$8:$J$557,'2. RECETAS'!$D$8:$D$557,$A15) -> 0 | E15: ='1. INSUMOS'!F15 -> 1000 | F15: =IF(OR(D15=0,E15=0),0,ROUNDUP(D15/E15,0)) -> 0 | G15: ='1. INSUMOS'!G15 -> 30 | H15: =F15*G15 -> 0 | I15: =D15*'1. INSUMOS'!H15 -> 0
A16: Azúcar mascabado | B16: ='1. INSUMOS'!C16 -> Azúcares | C16: ='1. INSUMOS'!D16 -> g | D16: =SUMIFS('2. RECETAS'!$J$8:$J$557,'2. RECETAS'!$D$8:$D$557,$A16) -> 0 | E16: ='1. INSUMOS'!F16 -> 1000 | F16: =IF(OR(D16=0,E16=0),0,ROUNDUP(D16/E16,0)) -> 0 | G16: ='1. INSUMOS'!G16 -> 52 | H16: =F16*G16 -> 0 | I16: =D16*'1. INSUMOS'!H16 -> 0
A17: Azúcar mascabado oscuro | B17: ='1. INSUMOS'!C17 -> Azúcares | C17: ='1. INSUMOS'!D17 -> g | D17: =SUMIFS('2. RECETAS'!$J$8:$J$557,'2. RECETAS'!$D$8:$D$557,$A17) -> 0 | E17: ='1. INSUMOS'!F17 -> 1000 | F17: =IF(OR(D17=0,E17=0),0,ROUNDUP(D17/E17,0)) -> 0 | G17: ='1. INSUMOS'!G17 -> 58 | H17: =F17*G17 -> 0 | I17: =D17*'1. INSUMOS'!H17 -> 0
A18: Azúcar glass | B18: ='1. INSUMOS'!C18 -> Azúcares | C18: ='1. INSUMOS'!D18 -> g | D18: =SUMIFS('2. RECETAS'!$J$8:$J$557,'2. RECETAS'!$D$8:$D$557,$A18) -> 0 | E18: ='1. INSUMOS'!F18 -> 500 | F18: =IF(OR(D18=0,E18=0),0,ROUNDUP(D18/E18,0)) -> 0 | G18: ='1. INSUMOS'!G18 -> 32 | H18: =F18*G18 -> 0 | I18: =D18*'1. INSUMOS'!H18 -> 0
A19: Piloncillo | B19: ='1. INSUMOS'!C19 -> Azúcares | C19: ='1. INSUMOS'!D19 -> g | D19: =SUMIFS('2. RECETAS'!$J$8:$J$557,'2. RECETAS'!$D$8:$D$557,$A19) -> 0 | E19: ='1. INSUMOS'!F19 -> 1000 | F19: =IF(OR(D19=0,E19=0),0,ROUNDUP(D19/E19,0)) -> 0 | G19: ='1. INSUMOS'!G19 -> 48 | H19: =F19*G19 -> 0 | I19: =D19*'1. INSUMOS'!H19 -> 0
... A98: Jugo de yuzu | B98: ='1. INSUMOS'!C98 -> Especias y aromas | C98: ='1. INSUMOS'!D98 -> ml | D98: =SUMIFS('2. RECETAS'!$J$8:$J$557,'2. RECETAS'!$D$8:$D$557,$A98) -> 0 | E98: ='1. INSUMOS'!F98 -> 100 | F98: =IF(OR(D98=0,E98=0),0,ROUNDUP(D98/E98,0)) -> 0 | G98: ='1. INSUMOS'!G98 -> 195 | H98: =F98*G98 -> 0 | I98: =D98*'1. INSUMOS'!H98 -> 0
A99: TOTAL DE LA COMPRA | H99: =SUM(H8:H98) -> 0 | I99: =SUM(I8:I98) -> 0
