Workbook

Sheet LÉEME
A1: Anexo 1 · Costeo, merma y precios
A2: Anexo 1 · Costeo, merma y precios · Endulcora · Estudio Gastronómico · En colaboración con Levent
A4: • | B4: Qué es: Hoja de costeo del eBook «Gomas y Gomitas». Calcula el costo real de las 50 formulaciones por pieza y por bolsa de 100 g, y su precio por canal, con tus propios precios de compra.
A5: • | B5: Cómo se usa: 1) Insumos: captura presentación y precio que tú pagas. 2) Preparaciones de la casa: revisa las preparaciones base; su costo alimenta a las recetas que las usan. 3) Mi negocio: gastos fijos, sueldo, horas, merma y márgenes. 4) Recetas y precios: revisa costos y precios. 5) Registra lotes en Producción y ventas en Ventas. 6) Revisa el Tablero cada semana.
A6: • | B6: Celdas amarillas: Son las únicas que debes editar. Todo lo demás es fórmula: si la borras, se rompe el cálculo.
A7: • | B7: Modelo de costeo: Costo por unidad = Precio ÷ Presentación · Las 2 preparaciones de la casa toman su costo de su propia fórmula · El molde y la bandeja se dividen entre sus coladas de vida útil · Insumos por pieza = Σ(cantidad × costo unitario) ÷ piezas que rinde la colada · Minutos por pieza = minutos de colada ÷ piezas por colada + minutos de pieza · Estufado = horas de curado × costo de una pieza-hora de cámara · Costo base = insumos + cocción y luz + mano de obra + gastos fijos + estufado · Costo total = Costo base ÷ (1 − merma) (se DIVIDE, no se suma) · Precio = Costo total ÷ (1 − margen), redondeado a $5 sobre la BOLSA · Precio de la bolsa = Precio por pieza × piezas por bolsa.
A8: • | B8: Preparaciones de la casa: La hoja «Preparaciones de la casa» costea la solución ácida al 50% y el agente de brillo de carnauba desde su propia fórmula. Son las dos únicas preparaciones intermedias del recetario: en confitería de gomas todo lo demás se hace de un tirón, del jarabe al molde.
A9: • | B9: Hojas: Insumos (catálogo editable) · Preparaciones de la casa (las preparaciones base) · Ingredientes (cada línea del recetario normalizada, con el texto original) · Mi negocio (supuestos) · Recetas y precios (hoja principal) · Producción (bitácora de lotes y merma) · Ventas (bitácora) · Tablero (resumen).
A10: • | B10: Unidades: Todo se costea por PIEZA, que pesa entre 2.5 y 12.5 g según la fórmula, y se agrupa en BOLSAS de 100 g. La columna «Piezas por bolsa de 100 g» es editable y da el «Costo de la bolsa», que es como se vende de verdad. El redondeo de precios se aplica sobre la bolsa, no sobre la pieza: una gomita no se cotiza en pesos cerrados.
A11: • | B11: Advertencia: Los precios cargados son de referencia (mercado CDMX 2026), no cotizaciones. Los resultados son ilustrativos hasta que captures tus precios reales. No se promete ningún ingreso.
A12: • | B12: Créditos: Contenido y recetas: Chef Luis Alfonso Jiménez Cárdenas · Edición y costeo: Manuel Ramiro Justo Guzmán · Endulcora · Estudio Gastronómico, en colaboración con Levent · WhatsApp 56 6527 1901. Uso personal del comprador; prohibida su reventa o redistribución.
B14: Celda de ejemplo que sí puedes editar → | C14: 100

Sheet Insumos
A1: Insumos
A2: Captura la presentación que compras y lo que pagas. Precios de referencia CDMX 2026 (no son cotizaciones).
A4: ID | B4: Categoría | C4: Insumo | D4: Unidad | E4: Presentación | F4: Precio pagado | G4: Costo por unidad | H4: Usos | I4: Proveedor
A5: I-001 | B5: Sistemas gelificantes | C5: Gelatina en polvo de 240-260 Bloom | D5: g | E5: 1000 | F5: 420 | G5: =IFERROR(F5/E5,0) | H5: =COUNTIF(Ingredientes!$E:$E,C5)
A6: I-002 | B6: Sistemas gelificantes | C6: Gelatina en polvo de 200-220 Bloom | D6: g | E6: 1000 | F6: 365 | G6: =IFERROR(F6/E6,0) | H6: =COUNTIF(Ingredientes!$E:$E,C6)
A7: I-003 | B7: Sistemas gelificantes | C7: Pectina de alto metoxilo lenta (HM slow-set) | D7: g | E7: 1000 | F7: 1250 | G7: =IFERROR(F7/E7,0) | H7: =COUNTIF(Ingredientes!$E:$E,C7)
A8: I-004 | B8: Sistemas gelificantes | C8: Pectina de alto metoxilo rápida (HM rapid-set) | D8: g | E8: 1000 | F8: 1290 | G8: =IFERROR(F8/E8,0) | H8: =COUNTIF(Ingredientes!$E:$E,C8)
A9: I-005 | B9: Sistemas gelificantes | C9: Pectina de bajo metoxilo amidada (LMA) | D9: g | E9: 500 | F9: 720 | G9: =IFERROR(F9/E9,0) | H9: =COUNTIF(Ingredientes!$E:$E,C9)
A10: I-006 | B10: Sistemas gelificantes | C10: Carragenato kappa grado confitería | D10: g | E10: 500 | F10: 580 | G10: =IFERROR(F10/E10,0) | H10: =COUNTIF(Ingredientes!$E:$E,C10)
A11: I-007 | B11: Sistemas gelificantes | C11: Carragenato iota purificado | D11: g | E11: 500 | F11: 640 | G11: =IFERROR(F11/E11,0) | H11: =COUNTIF(Ingredientes!$E:$E,C11)
A12: I-008 | B12: Sistemas gelificantes | C12: Goma arábiga en polvo atomizada (acacia) | D12: g | E12: 1000 | F12: 395 | G12: =IFERROR(F12/E12,0) | H12: =COUNTIF(Ingredientes!$E:$E,C12)
A13: I-009 | B13: Sistemas gelificantes | C13: Almidón modificado de maíz fluidificado | D13: g | E13: 1000 | F13: 128 | G13: =IFERROR(F13/E13,0) | H13: =COUNTIF(Ingredientes!$E:$E,C13)
A14: I-010 | B14: Sistemas gelificantes | C14: Agar-agar en polvo de 900 g/cm² | D14: g | E14: 250 | F14: 420 | G14: =IFERROR(F14/E14,0) | H14: =COUNTIF(Ingredientes!$E:$E,C14)
A15: I-011 | B15: Azúcares, jarabes y polioles | C15: Azúcar blanca refinada | D15: g | E15: 1000 | F15: 34 | G15: =IFERROR(F15/E15,0) | H15: =COUNTIF(Ingredientes!$E:$E,C15)
A16: I-012 | B16: Azúcares, jarabes y polioles | C16: Azúcar cristal de grano medio a grueso (rebozado) | D16: g | E16: 1000 | F16: 38 | G16: =IFERROR(F16/E16,0) | H16: =COUNTIF(Ingredientes!$E:$E,C16)
... A98: I-094 | B98: Empaque y presentación | C98: Bolsita desecante y sello de inviolabilidad | D98: pz | E98: 1 | F98: 1.2 | G98: =IFERROR(F98/E98,0) | H98: =COUNTIF(Ingredientes!$E:$E,C98)
A99: I-095 | B99: Preparaciones de la casa | C99: Solución de ácido cítrico al 50% p/v (elaborada) | D99: ml | E99: ='Preparaciones de la casa'!D5 | F99: ='Preparaciones de la casa'!F5 | G99: =IFERROR(F99/E99,0) | H99: =COUNTIF(Ingredientes!$E:$E,C99)
A100: I-096 | B100: Preparaciones de la casa | C100: Agente de brillo de carnauba en MCT (elaborado) | D100: g | E100: ='Preparaciones de la casa'!D6 | F100: ='Preparaciones de la casa'!F6 | G100: =IFERROR(F100/E100,0) | H100: =COUNTIF(Ingredientes!$E:$E,C100)
C102: Las preparaciones del recetario toman su precio de la hoja «Preparaciones de la casa»: no se capturan a mano.

Sheet Preparaciones de la casa
A1: Preparaciones de la casa
A2: Las dos únicas preparaciones intermedias del recetario. Todo lo demás se formula desde el azúcar en una sola cocción continua: en confitería de gomas no hay bases a medio camino.
A4: Código | B4: Preparación base | C4: Para qué sirve | D4: Rendimiento | E4: Unidad | F4: Costo de insumos del lote | G4: Costo unitario | H4: Entra en las recetas
A5: B-1 | B5: Solución de ácido cítrico al 50% p/v (elaborada) | C5: La solución ácida al 50% p/v que piden casi todas las fórmulas. Se prepara en frío, se guarda tapada y se dosifica a 72 °C para no hidrolizar el gelificante. | D5: 100 | E5: ml | F5: =SUMIF(Ingredientes!$A:$A,102,Ingredientes!$I:$I) | G5: =IFERROR(F5/D5,0)
A6: B-2 | B6: Agente de brillo de carnauba en MCT (elaborado) | C6: El agente de brillo: cera de carnauba disuelta al 1% en aceite de coco fraccionado. Dos gramos por colada bastan y el bote dura toda una temporada de producción. | D6: 250 | E6: g | F6: =SUMIF(Ingredientes!$A:$A,103,Ingredientes!$I:$I) | G6: =IFERROR(F6/D6,0)
B8: Que haya sólo dos preparaciones no es una omisión: es la naturaleza del oficio. Una gomita se hace de un tirón, del jarabe al molde, sin componentes que se guarden.
A10: Notas técnicas
B11: Por qué la solución ácida se prepara aparte | C11: El ácido se dosifica al final, a 72 °C y en segundos. Pesarlo en polvo a esa velocidad es imposible y un error de medio gramo mueve el pH fuera del rango de gelificación. En solución al 50% se dosifica por volumen, rápido y exacto.
B12: Por qué el brillo se prepara aparte | C12: La cera de carnauba sólo se disuelve en aceite caliente y en proporción exacta. Un bote de 250 g alcanza para más de cien coladas, así que se prepara una vez por temporada.

Sheet Ingredientes
A1: Ingredientes
A2: Cada línea del recetario normalizada a un insumo del catálogo, con el texto original del chef al lado para auditarla.
A4: Nº | B4: Receta | C4: Bloque | D4: Texto original del chef | E4: Insumo | F4: Cantidad | G4: Unidad | H4: Costo unitario | I4: Costo de insumos de la colada
A5: 1 | B5: Gomita Clásica de Oso de Fresa Silvestre (Classic High-Bloom Strawberry Bear) | C5: gelificante | D5: 45 g Gelatina en polvo pura de 250 Bloom (9.0% peso total fórmula) | E5: Gelatina en polvo de 240-260 Bloom | F5: 45 | G5: g | H5: =IFERROR(VLOOKUP(E5,Insumos!$C$5:$G$100,5,FALSE),0) | I5: =F5*H5/IF(C5="molde",MAX(1,'Mi negocio'!$C$34),1)
A6: 1 | B6: Gomita Clásica de Oso de Fresa Silvestre (Classic High-Bloom Strawberry Bear) | C6: sabor | D6: 100 ml Agua desmineralizada a 15 °C | E6: Agua desmineralizada o purificada | F6: 100 | G6: ml | H6: =IFERROR(VLOOKUP(E6,Insumos!$C$5:$G$100,5,FALSE),0) | I6: =F6*H6/IF(C6="molde",MAX(1,'Mi negocio'!$C$34),1)
A7: 1 | B7: Gomita Clásica de Oso de Fresa Silvestre (Classic High-Bloom Strawberry Bear) | C7: azucar | D7: 200 g Azúcar blanca refinada pura (99.8% polarización) | E7: Azúcar blanca refinada | F7: 200 | G7: g | H7: =IFERROR(VLOOKUP(E7,Insumos!$C$5:$G$100,5,FALSE),0) | I7: =F7*H7/IF(C7="molde",MAX(1,'Mi negocio'!$C$34),1)
A8: 1 | B8: Gomita Clásica de Oso de Fresa Silvestre (Classic High-Bloom Strawberry Bear) | C8: azucar | D8: 160 g Jarabe de glucosa estándar de maíz de 42 DE (80% sólidos) | E8: Jarabe de glucosa 42 DE | F8: 160 | G8: g | H8: =IFERROR(VLOOKUP(E8,Insumos!$C$5:$G$100,5,FALSE),0) | I8: =F8*H8/IF(C8="molde",MAX(1,'Mi negocio'!$C$34),1)
A9: 1 | B9: Gomita Clásica de Oso de Fresa Silvestre (Classic High-Bloom Strawberry Bear) | C9: sabor | D9: 60 ml Agua purificada limpia | E9: Agua desmineralizada o purificada | F9: 60 | G9: ml | H9: =IFERROR(VLOOKUP(E9,Insumos!$C$5:$G$100,5,FALSE),0) | I9: =F9*H9/IF(C9="molde",MAX(1,'Mi negocio'!$C$34),1)
A10: 1 | B10: Gomita Clásica de Oso de Fresa Silvestre (Classic High-Bloom Strawberry Bear) | C10: azucar | D10: 15 g Sorbitol líquido al 70% (plastificante hidrófilo y humectante) | E10: Sorbitol líquido al 70% | F10: 15 | G10: g | H10: =IFERROR(VLOOKUP(E10,Insumos!$C$5:$G$100,5,FALSE),0) | I10: =F10*H10/IF(C10="molde",MAX(1,'Mi negocio'!$C$34),1)
A11: 1 | B11: Gomita Clásica de Oso de Fresa Silvestre (Classic High-Bloom Strawberry Bear) | C11: sabor | D11: 10 ml Solución de ácido cítrico al 50% p/v (5 g de ácido cítrico anhidro en 5 ml de agua desmineralizada) | E11: Solución de ácido cítrico al 50% p/v (elaborada) | F11: 10 | G11: ml | H11: =IFERROR(VLOOKUP(E11,Insumos!$C$5:$G$100,5,FALSE),0) | I11: =F11*H11/IF(C11="molde",MAX(1,'Mi negocio'!$C$34),1)
A12: 1 | B12: Gomita Clásica de Oso de Fresa Silvestre (Classic High-Bloom Strawberry Bear) | C12: sabor | D12: 2.5 ml Aroma natural hidrosoluble de fresa silvestre concentrado | E12: Aroma natural hidrosoluble concentrado | F12: 2.5 | G12: ml | H12: =IFERROR(VLOOKUP(E12,Insumos!$C$5:$G$100,5,FALSE),0) | I12: =F12*H12/IF(C12="molde",MAX(1,'Mi negocio'!$C$34),1)
A13: 1 | B13: Gomita Clásica de Oso de Fresa Silvestre (Classic High-Bloom Strawberry Bear) | C13: sabor | D13: 0.4 g Colorante rojo carmín hidrosoluble (rojo allura / extracto de cochinilla) | E13: Colorante rojo carmín o allura hidrosoluble | F13: 0.4 | G13: g | H13: =IFERROR(VLOOKUP(E13,Insumos!$C$5:$G$100,5,FALSE),0) | I13: =F13*H13/IF(C13="molde",MAX(1,'Mi negocio'!$C$34),1)
A14: 1 | B14: Gomita Clásica de Oso de Fresa Silvestre (Classic High-Bloom Strawberry Bear) | C14: acabado | D14: 2 g Aceite de coco fraccionado (MCT) mezclado con 0.1 g de cera de carnauba refinada | E14: Aceite de coco fraccionado (MCT) | F14: 2 | G14: ml | H14: =IFERROR(VLOOKUP(E14,Insumos!$C$5:$G$100,5,FALSE),0) | I14: =F14*H14/IF(C14="molde",MAX(1,'Mi negocio'!$C$34),1)
A15: 2 | B15: Gota Francesa de Naranja y Mandarina en Pectina de Alto Metoxilo (Pâte de Fruits Gélifiée en Pectine Jaune) | C15: sabor | D15: 180 g Puré concentrado de naranja valencia y mandarina criolla (100% fruta, tamizado sin pulpa gruesa) | E15: Zumo concentrado clarificado de cítrico | F15: 180 | G15: ml | H15: =IFERROR(VLOOKUP(E15,Insumos!$C$5:$G$100,5,FALSE),0) | I15: =F15*H15/IF(C15="molde",MAX(1,'Mi negocio'!$C$34),1)
A16: 2 | B16: Gota Francesa de Naranja y Mandarina en Pectina de Alto Metoxilo (Pâte de Fruits Gélifiée en Pectine Jaune) | C16: sabor | D16: 30 ml Agua desmineralizada pura | E16: Agua desmineralizada o purificada | F16: 30 | G16: ml | H16: =IFERROR(VLOOKUP(E16,Insumos!$C$5:$G$100,5,FALSE),0) | I16: =F16*H16/IF(C16="molde",MAX(1,'Mi negocio'!$C$34),1)
... A1063: 103 | B1063: B-2 · Agente de brillo de carnauba en MCT | C1063: acabado | D1063: 2.5 g Cera de carnauba refinada · lote de B-2 | E1063: Cera de carnauba refinada | F1063: 2.5 | G1063: g | H1063: =IFERROR(VLOOKUP(E1063,Insumos!$C$5:$G$100,5,FALSE),0) | I1063: =F1063*H1063/IF(C1063="molde",MAX(1,'Mi negocio'!$C$34),1)

Sheet Mi negocio
A1: Mi negocio
A2: Los supuestos que mueven todo. Si estos números están mal, todos tus precios están mal.
B4: Gasto fijo mensual | C4: Monto | D4: Nota
B5: Renta del obrador y del área de estufado | C5: 11500
B6: Luz, gas y cocción de jarabes | C6: 3200
B7: Control de temperatura y humedad de la cámara de curado | C7: 2800
B8: Agua, limpieza y sanitización | C8: 1100
B9: Internet, telefonía y punto de venta | C9: 800
B10: Publicidad, redes y contenido | C10: 2400
B11: Permisos, licencias sanitarias y comisiones de plataforma | C11: 1900
B12: Mantenimiento de cazo, bomba dosificadora y deshumidificador | C12: 1200
B13: Depreciación de equipo (cazo, refractómetro, pH-metro, estufa) | C13: 2400
B14: Otros gastos fijos | C14: 700
B17: Total de gastos fijos | C17: =SUM(C5:C16)
B19: Piezas producidos al mes | C19: 120000 | D19: Piezas que esperas producir al mes. Es el divisor de tus gastos fijos. En gomitas el volumen manda: la misma cocción da 200 piezas o 2 000.
B20: Gastos fijos por pieza (overhead) | C20: =IFERROR(C17/C19,0) | D20: Se suma al costo de cada pieza.
B21: Sueldo mensual que te pagas | C21: 20000
B22: Horas de trabajo al mes | C22: 180
B23: Costo de tu hora | C23: =IFERROR(C21/C22,0) | D23: Mano de obra = minutos ÷ 60 × costo de la hora.
B24: % de merma por defecto | C24: 0.1 | D24: Colada que no cuajó, piezas pegadas por exudación, sinéresis en la bolsa, desmolde roto y pieza cristalizada. En gomitas la merma se decide en el pH y en el Brix, no en las manos.
B25: Redondeo de precios (pesos) | C25: 5 | D25: Los precios suben al múltiplo superior de esta cifra.
B26: Márgenes objetivo por canal | C26: 1200 | D26: La ficha del chef está escrita para una colada de 500 g. Una planta real cuela varios kilos de una vez: los minutos de cocción y de jarabe se reparten entre todas las piezas.
B27: Margen · Mostrador y venta directa | C27: 0.58 | D27: Rango sugerido 54 – 62 %.
B28: Margen · Evento, regalo y corporativo | C28: 0.52 | D28: Rango sugerido 48 – 56 %.
B29: Margen · Marca propia y tienda en línea | C29: 0.46 | D29: Rango sugerido 42 – 50 %.
B30: Margen · Mayoreo a tiendas y distribución | C30: 0.36 | D30: Rango sugerido 32 – 40 %.
B34: Coladas de vida útil del molde y la bandeja | C34: 450 | D34: El molde de silicona platinada y la bandeja de estufado no se consumen: se reutilizan. Su costo se divide entre las coladas que aguantan antes de perder definición. Por debajo de 300 coladas conviene revisar la calidad del molde.
B37: Lugares de bandeja en la cámara de estufado | C37: 7200 | D37: El estufado es el cuello de botella real de la confitería de gomas: una pieza que pide cuarenta y ocho horas de curado ocupa un lugar de bandeja dos días enteros. Con los lugares que tengas y las horas que pida cada fórmula sale tu techo de piezas al día.
B38: Costo mensual de la cámara de estufado | C38: 2800 | D38: Renta de la superficie de secado, deshidratador, rejillas y su depreciación.
B39: Costo de la pieza-hora de estufado | C39: =IFERROR(C38/MAX(1,C37*24*30),0) | D39: Cuesta poco dinero y mucha capacidad: lo que de verdad limita tu producción son los lugares de secado, no los pesos.

Sheet Recetas y precios
A1: Recetas y precios
A2: Hoja principal. Cambia un precio en Insumos y los 50 precios se recalculan solos.
A4: Nº | B4: Receta | C4: Capítulo | D4: Bloque | E4: Sistema | F4: Vida útil (meses) | G4: Unidad de venta | H4: Piezas que rinde | I4: Insumos de la colada | J4: Insumos por pieza | K4: Empaque extra | L4: Cocción y luz por pieza | M4: Min. de colada (jarabe, cocción, vaciado) | N4: Min. de pieza (desmolde, rebozado, acabado) | O4: Mano de obra | P4: Gastos fijos | Q4: Estufado (h) | R4: Estufado | S4: Piezas al día que permite tu estufa | T4: Costo base | U4: Merma propia | V4: Merma aplicada | W4: COSTO TOTAL | X4: Piezas por bolsa de 100 g | Y4: Costo de la bolsa | Z4: PVP Mostrador y venta directa | AA4: PVP Evento, regalo y corporativo | AB4: PVP Marca propia y tienda en línea | AC4: PVP Mayoreo a tiendas y distribución
A5: 1 | B5: Gomita Clásica de Oso de Fresa Silvestre (Classic High-Bloom Strawberry Bear) | C5: Bloque 1 · Tradicionales, frutales y gelificantes clásicos | D5: 1 | E5: G | F5: 6 | G5: pieza | H5: 200 | I5: =SUMIF(Ingredientes!$A$5:$A$1063,A5,Ingredientes!$I$5:$I$1063) | J5: =IFERROR(I5/H5,0) | K5: 0 | L5: 0.012 | M5: 85 | N5: 0.09 | O5: =IFERROR((M5/MAX(1,'Mi negocio'!$C$26)+N5)/60*'Mi negocio'!$C$23,0) | P5: ='Mi negocio'!$C$20 | Q5: 24 | R5: =Q5*'Mi negocio'!$C$39 | S5: =IFERROR(ROUNDDOWN('Mi negocio'!$C$37*24/MAX(1,Q5),0),0) | T5: =J5+K5+L5+O5+P5+R5 | V5: =IF(U5="",'Mi negocio'!$C$24,U5) | W5: =IFERROR(T5/(1-V5),0) | X5: 40 | Y5: =W5*MAX(1,X5) | Z5: =IFERROR(CEILING(ROUND(W5*MAX(1,X5)/(1-'Mi negocio'!$C$27),6),'Mi negocio'!$C$25)/MAX(1,X5),0) | AA5: =IFERROR(CEILING(ROUND(W5*MAX(1,X5)/(1-'Mi negocio'!$C$28),6),'Mi negocio'!$C$25)/MAX(1,X5),0) | AB5: =IFERROR(CEILING(ROUND(W5*MAX(1,X5)/(1-'Mi negocio'!$C$29),6),'Mi negocio'!$C$25)/MAX(1,X5),0) | AC5: =IFERROR(CEILING(ROUND(W5*MAX(1,X5)/(1-'Mi negocio'!$C$30),6),'Mi negocio'!$C$25)/MAX(1,X5),0)
A6: 2 | B6: Gota Francesa de Naranja y Mandarina en Pectina de Alto Metoxilo (Pâte de Fruits Gélifiée en Pectine Jaune) | C6: Bloque 1 · Tradicionales, frutales y gelificantes clásicos | D6: 1 | E6: P | F6: 4 | G6: pieza | H6: 160 | I6: =SUMIF(Ingredientes!$A$5:$A$1063,A6,Ingredientes!$I$5:$I$1063) | J6: =IFERROR(I6/H6,0) | K6: 0 | L6: 0.012 | M6: 85 | N6: 0.09 | O6: =IFERROR((M6/MAX(1,'Mi negocio'!$C$26)+N6)/60*'Mi negocio'!$C$23,0) | P6: ='Mi negocio'!$C$20 | Q6: 36 | R6: =Q6*'Mi negocio'!$C$39 | S6: =IFERROR(ROUNDDOWN('Mi negocio'!$C$37*24/MAX(1,Q6),0),0) | T6: =J6+K6+L6+O6+P6+R6 | V6: =IF(U6="",'Mi negocio'!$C$24,U6) | W6: =IFERROR(T6/(1-V6),0) | X6: 33 | Y6: =W6*MAX(1,X6) | Z6: =IFERROR(CEILING(ROUND(W6*MAX(1,X6)/(1-'Mi negocio'!$C$27),6),'Mi negocio'!$C$25)/MAX(1,X6),0) | AA6: =IFERROR(CEILING(ROUND(W6*MAX(1,X6)/(1-'Mi negocio'!$C$28),6),'Mi negocio'!$C$25)/MAX(1,X6),0) | AB6: =IFERROR(CEILING(ROUND(W6*MAX(1,X6)/(1-'Mi negocio'!$C$29),6),'Mi negocio'!$C$25)/MAX(1,X6),0) | AC6: =IFERROR(CEILING(ROUND(W6*MAX(1,X6)/(1-'Mi negocio'!$C$30),6),'Mi negocio'!$C$25)/MAX(1,X6),0)
A7: 3 | B7: Gomita Tropical de Piña Colada en Sistema Híbrido (Gelatin-Pectin Hybrid Texture) | C7: Bloque 1 · Tradicionales, frutales y gelificantes clásicos | D7: 1 | E7: H | F7: 5 | G7: pieza | H7: 165 | I7: =SUMIF(Ingredientes!$A$5:$A$1063,A7,Ingredientes!$I$5:$I$1063) | J7: =IFERROR(I7/H7,0) | K7: 0 | L7: 0.012 | M7: 85 | N7: 0.09 | O7: =IFERROR((M7/MAX(1,'Mi negocio'!$C$26)+N7)/60*'Mi negocio'!$C$23,0) | P7: ='Mi negocio'!$C$20 | Q7: 36 | R7: =Q7*'Mi negocio'!$C$39 | S7: =IFERROR(ROUNDDOWN('Mi negocio'!$C$37*24/MAX(1,Q7),0),0) | T7: =J7+K7+L7+O7+P7+R7 | V7: =IF(U7="",'Mi negocio'!$C$24,U7) | W7: =IFERROR(T7/(1-V7),0) | X7: 33 | Y7: =W7*MAX(1,X7) | Z7: =IFERROR(CEILING(ROUND(W7*MAX(1,X7)/(1-'Mi negocio'!$C$27),6),'Mi negocio'!$C$25)/MAX(1,X7),0) | AA7: =IFERROR(CEILING(ROUND(W7*MAX(1,X7)/(1-'Mi negocio'!$C$28),6),'Mi negocio'!$C$25)/MAX(1,X7),0) | AB7: =IFERROR(CEILING(ROUND(W7*MAX(1,X7)/(1-'Mi negocio'!$C$29),6),'Mi negocio'!$C$25)/MAX(1,X7),0) | AC7: =IFERROR(CEILING(ROUND(W7*MAX(1,X7)/(1-'Mi negocio'!$C$30),6),'Mi negocio'!$C$25)/MAX(1,X7),0)
A8: 4 | B8: Gomita Vegana de Mango y Maracuyá en Agar-Agar Puro (Plant-Based Agar-Agar Tropical Jelly) | C8: Bloque 1 · Tradicionales, frutales y gelificantes clásicos | D8: 1 | E8: K | F8: 3 | G8: pieza | H8: 165 | I8: =SUMIF(Ingredientes!$A$5:$A$1063,A8,Ingredientes!$I$5:$I$1063) | J8: =IFERROR(I8/H8,0) | K8: 0 | L8: 0.012 | M8: 85 | N8: 0.09 | O8: =IFERROR((M8/MAX(1,'Mi negocio'!$C$26)+N8)/60*'Mi negocio'!$C$23,0) | P8: ='Mi negocio'!$C$20 | Q8: 18 | R8: =Q8*'Mi negocio'!$C$39 | S8: =IFERROR(ROUNDDOWN('Mi negocio'!$C$37*24/MAX(1,Q8),0),0) | T8: =J8+K8+L8+O8+P8+R8 | U8: 0.13 | V8: =IF(U8="",'Mi negocio'!$C$24,U8) | W8: =IFERROR(T8/(1-V8),0) | X8: 33 | Y8: =W8*MAX(1,X8) | Z8: =IFERROR(CEILING(ROUND(W8*MAX(1,X8)/(1-'Mi negocio'!$C$27),6),'Mi negocio'!$C$25)/MAX(1,X8),0) | AA8: =IFERROR(CEILING(ROUND(W8*MAX(1,X8)/(1-'Mi negocio'!$C$28),6),'Mi negocio'!$C$25)/MAX(1,X8),0) | AB8: =IFERROR(CEILING(ROUND(W8*MAX(1,X8)/(1-'Mi negocio'!$C$29),6),'Mi negocio'!$C$25)/MAX(1,X8),0) | AC8: =IFERROR(CEILING(ROUND(W8*MAX(1,X8)/(1-'Mi negocio'!$C$30),6),'Mi negocio'!$C$25)/MAX(1,X8),0)
A9: 5 | B9: Gomita Cristaliana de Moras Silvestres con Corazón Elástico (High-Elasticity Blackberry Drop) | C9: Bloque 1 · Tradicionales, frutales y gelificantes clásicos | D9: 1 | E9: A | F9: 6 | G9: pieza | H9: 165 | I9: =SUMIF(Ingredientes!$A$5:$A$1063,A9,Ingredientes!$I$5:$I$1063) | J9: =IFERROR(I9/H9,0) | K9: 0 | L9: 0.012 | M9: 85 | N9: 0.09 | O9: =IFERROR((M9/MAX(1,'Mi negocio'!$C$26)+N9)/60*'Mi negocio'!$C$23,0) | P9: ='Mi negocio'!$C$20 | Q9: 30 | R9: =Q9*'Mi negocio'!$C$39 | S9: =IFERROR(ROUNDDOWN('Mi negocio'!$C$37*24/MAX(1,Q9),0),0) | T9: =J9+K9+L9+O9+P9+R9 | V9: =IF(U9="",'Mi negocio'!$C$24,U9) | W9: =IFERROR(T9/(1-V9),0) | X9: 33 | Y9: =W9*MAX(1,X9) | Z9: =IFERROR(CEILING(ROUND(W9*MAX(1,X9)/(1-'Mi negocio'!$C$27),6),'Mi negocio'!$C$25)/MAX(1,X9),0) | AA9: =IFERROR(CEILING(ROUND(W9*MAX(1,X9)/(1-'Mi negocio'!$C$28),6),'Mi negocio'!$C$25)/MAX(1,X9),0) | AB9: =IFERROR(CEILING(ROUND(W9*MAX(1,X9)/(1-'Mi negocio'!$C$29),6),'Mi negocio'!$C$25)/MAX(1,X9),0) | AC9: =IFERROR(CEILING(ROUND(W9*MAX(1,X9)/(1-'Mi negocio'!$C$30),6),'Mi negocio'!$C$25)/MAX(1,X9),0)
A10: 6 | B10: Gomita Traslúcida de Manzana Verde Granny Smith (Acidic Green Apple Translucent Drop) | C10: Bloque 1 · Tradicionales, frutales y gelificantes clásicos | D10: 1 | E10: G | F10: 6 | G10: pieza | H10: 165 | I10: =SUMIF(Ingredientes!$A$5:$A$1063,A10,Ingredientes!$I$5:$I$1063) | J10: =IFERROR(I10/H10,0) | K10: 0 | L10: 0.012 | M10: 85 | N10: 0.09 | O10: =IFERROR((M10/MAX(1,'Mi negocio'!$C$26)+N10)/60*'Mi negocio'!$C$23,0) | P10: ='Mi negocio'!$C$20 | Q10: 24 | R10: =Q10*'Mi negocio'!$C$39 | S10: =IFERROR(ROUNDDOWN('Mi negocio'!$C$37*24/MAX(1,Q10),0),0) | T10: =J10+K10+L10+O10+P10+R10 | V10: =IF(U10="",'Mi negocio'!$C$24,U10) | W10: =IFERROR(T10/(1-V10),0) | X10: 33 | Y10: =W10*MAX(1,X10) | Z10: =IFERROR(CEILING(ROUND(W10*MAX(1,X10)/(1-'Mi negocio'!$C$27),6),'Mi negocio'!$C$25)/MAX(1,X10),0) | AA10: =IFERROR(CEILING(ROUND(W10*MAX(1,X10)/(1-'Mi negocio'!$C$28),6),'Mi negocio'!$C$25)/MAX(1,X10),0) | AB10: =IFERROR(CEILING(ROUND(W10*MAX(1,X10)/(1-'Mi negocio'!$C$29),6),'Mi negocio'!$C$25)/MAX(1,X10),0) | AC10: =IFERROR(CEILING(ROUND(W10*MAX(1,X10)/(1-'Mi negocio'!$C$30),6),'Mi negocio'!$C$25)/MAX(1,X10),0)
A11: 7 | B11: Domo de Uva Moscatel en Carragenato Kappa-Iota (Vegan Grape Jelly in Kappa-Iota Carrageenan Matrix) | C11: Bloque 1 · Tradicionales, frutales y gelificantes clásicos | D11: 1 | E11: K | F11: 4 | G11: pieza | H11: 140 | I11: =SUMIF(Ingredientes!$A$5:$A$1063,A11,Ingredientes!$I$5:$I$1063) | J11: =IFERROR(I11/H11,0) | K11: 0 | L11: 0.012 | M11: 85 | N11: 0.09 | O11: =IFERROR((M11/MAX(1,'Mi negocio'!$C$26)+N11)/60*'Mi negocio'!$C$23,0) | P11: ='Mi negocio'!$C$20 | Q11: 18 | R11: =Q11*'Mi negocio'!$C$39 | S11: =IFERROR(ROUNDDOWN('Mi negocio'!$C$37*24/MAX(1,Q11),0),0) | T11: =J11+K11+L11+O11+P11+R11 | V11: =IF(U11="",'Mi negocio'!$C$24,U11) | W11: =IFERROR(T11/(1-V11),0) | X11: 29 | Y11: =W11*MAX(1,X11) | Z11: =IFERROR(CEILING(ROUND(W11*MAX(1,X11)/(1-'Mi negocio'!$C$27),6),'Mi negocio'!$C$25)/MAX(1,X11),0) | AA11: =IFERROR(CEILING(ROUND(W11*MAX(1,X11)/(1-'Mi negocio'!$C$28),6),'Mi negocio'!$C$25)/MAX(1,X11),0) | AB11: =IFERROR(CEILING(ROUND(W11*MAX(1,X11)/(1-'Mi negocio'!$C$29),6),'Mi negocio'!$C$25)/MAX(1,X11),0) | AC11: =IFERROR(CEILING(ROUND(W11*MAX(1,X11)/(1-'Mi negocio'!$C$30),6),'Mi negocio'!$C$25)/MAX(1,X11),0)
A12: 8 | B12: Gomita Reducida en Azúcar de Melocotón y Durazno en Pectina LMA (Low Methoxyl Amidated Pectin Peach Gummy) | C12: Bloque 1 · Tradicionales, frutales y gelificantes clásicos | D12: 1 | E12: L | F12: 3 | G12: pieza | H12: 165 | I12: =SUMIF(Ingredientes!$A$5:$A$1063,A12,Ingredientes!$I$5:$I$1063) | J12: =IFERROR(I12/H12,0) | K12: 0 | L12: 0.012 | M12: 85 | N12: 0.09 | O12: =IFERROR((M12/MAX(1,'Mi negocio'!$C$26)+N12)/60*'Mi negocio'!$C$23,0) | P12: ='Mi negocio'!$C$20 | Q12: 30 | R12: =Q12*'Mi negocio'!$C$39 | S12: =IFERROR(ROUNDDOWN('Mi negocio'!$C$37*24/MAX(1,Q12),0),0) | T12: =J12+K12+L12+O12+P12+R12 | U12: 0.14 | V12: =IF(U12="",'Mi negocio'!$C$24,U12) | W12: =IFERROR(T12/(1-V12),0) | X12: 33 | Y12: =W12*MAX(1,X12) | Z12: =IFERROR(CEILING(ROUND(W12*MAX(1,X12)/(1-'Mi negocio'!$C$27),6),'Mi negocio'!$C$25)/MAX(1,X12),0) | AA12: =IFERROR(CEILING(ROUND(W12*MAX(1,X12)/(1-'Mi negocio'!$C$28),6),'Mi negocio'!$C$25)/MAX(1,X12),0) | AB12: =IFERROR(CEILING(ROUND(W12*MAX(1,X12)/(1-'Mi negocio'!$C$29),6),'Mi negocio'!$C$25)/MAX(1,X12),0) | AC12: =IFERROR(CEILING(ROUND(W12*MAX(1,X12)/(1-'Mi negocio'!$C$30),6),'Mi negocio'!$C$25)/MAX(1,X12),0)
A13: 9 | B13: Perla de Frutos Rojos en Pectina Lenta (Slow-Set HM Pectin Red Berry Gem) | C13: Bloque 1 · Tradicionales, frutales y gelificantes clásicos | D13: 1 | E13: P | F13: 5 | G13: pieza | H13: 200 | I13: =SUMIF(Ingredientes!$A$5:$A$1063,A13,Ingredientes!$I$5:$I$1063) | J13: =IFERROR(I13/H13,0) | K13: 0 | L13: 0.012 | M13: 85 | N13: 0.09 | O13: =IFERROR((M13/MAX(1,'Mi negocio'!$C$26)+N13)/60*'Mi negocio'!$C$23,0) | P13: ='Mi negocio'!$C$20 | Q13: 36 | R13: =Q13*'Mi negocio'!$C$39 | S13: =IFERROR(ROUNDDOWN('Mi negocio'!$C$37*24/MAX(1,Q13),0),0) | T13: =J13+K13+L13+O13+P13+R13 | V13: =IF(U13="",'Mi negocio'!$C$24,U13) | W13: =IFERROR(T13/(1-V13),0) | X13: 40 | Y13: =W13*MAX(1,X13) | Z13: =IFERROR(CEILING(ROUND(W13*MAX(1,X13)/(1-'Mi negocio'!$C$27),6),'Mi negocio'!$C$25)/MAX(1,X13),0) | AA13: =IFERROR(CEILING(ROUND(W13*MAX(1,X13)/(1-'Mi negocio'!$C$28),6),'Mi negocio'!$C$25)/MAX(1,X13),0) | AB13: =IFERROR(CEILING(ROUND(W13*MAX(1,X13)/(1-'Mi negocio'!$C$29),6),'Mi negocio'!$C$25)/MAX(1,X13),0) | AC13: =IFERROR(CEILING(ROUND(W13*MAX(1,X13)/(1-'Mi negocio'!$C$30),6),'Mi negocio'!$C$25)/MAX(1,X13),0)
A14: 10 | B14: Pastilla de Goma Balsámica de Limón Criollo y Eucalipto (Balsamic Eucalyptus & Key Lime Pastille) | C14: Bloque 1 · Tradicionales, frutales y gelificantes clásicos | D14: 1 | E14: A | F14: 8 | G14: pieza | H14: 200 | I14: =SUMIF(Ingredientes!$A$5:$A$1063,A14,Ingredientes!$I$5:$I$1063) | J14: =IFERROR(I14/H14,0) | K14: 0 | L14: 0.012 | M14: 85 | N14: 0.09 | O14: =IFERROR((M14/MAX(1,'Mi negocio'!$C$26)+N14)/60*'Mi negocio'!$C$23,0) | P14: ='Mi negocio'!$C$20 | Q14: 36 | R14: =Q14*'Mi negocio'!$C$39 | S14: =IFERROR(ROUNDDOWN('Mi negocio'!$C$37*24/MAX(1,Q14),0),0) | T14: =J14+K14+L14+O14+P14+R14 | V14: =IF(U14="",'Mi negocio'!$C$24,U14) | W14: =IFERROR(T14/(1-V14),0) | X14: 40 | Y14: =W14*MAX(1,X14) | Z14: =IFERROR(CEILING(ROUND(W14*MAX(1,X14)/(1-'Mi negocio'!$C$27),6),'Mi negocio'!$C$25)/MAX(1,X14),0) | AA14: =IFERROR(CEILING(ROUND(W14*MAX(1,X14)/(1-'Mi negocio'!$C$28),6),'Mi negocio'!$C$25)/MAX(1,X14),0) | AB14: =IFERROR(CEILING(ROUND(W14*MAX(1,X14)/(1-'Mi negocio'!$C$29),6),'Mi negocio'!$C$25)/MAX(1,X14),0) | AC14: =IFERROR(CEILING(ROUND(W14*MAX(1,X14)/(1-'Mi negocio'!$C$30),6),'Mi negocio'!$C$25)/MAX(1,X14),0)
A15: 11 | B15: Lengua / Tira Ácida de Fresa Salvaje (Ultra-Sour Strawberry Sanded Ribbon) | C15: Bloque 2 · Ácidas, cítricas y rebozados cristalinos | D15: 2 | E15: G | F15: 6 | G15: pieza | H15: 50 | I15: =SUMIF(Ingredientes!$A$5:$A$1063,A15,Ingredientes!$I$5:$I$1063) | J15: =IFERROR(I15/H15,0) | K15: 0 | L15: 0.012 | M15: 95 | N15: 0.2 | O15: =IFERROR((M15/MAX(1,'Mi negocio'!$C$26)+N15)/60*'Mi negocio'!$C$23,0) | P15: ='Mi negocio'!$C$20 | Q15: 24 | R15: =Q15*'Mi negocio'!$C$39 | S15: =IFERROR(ROUNDDOWN('Mi negocio'!$C$37*24/MAX(1,Q15),0),0) | T15: =J15+K15+L15+O15+P15+R15 | V15: =IF(U15="",'Mi negocio'!$C$24,U15) | W15: =IFERROR(T15/(1-V15),0) | X15: 10 | Y15: =W15*MAX(1,X15) | Z15: =IFERROR(CEILING(ROUND(W15*MAX(1,X15)/(1-'Mi negocio'!$C$27),6),'Mi negocio'!$C$25)/MAX(1,X15),0) | AA15: =IFERROR(CEILING(ROUND(W15*MAX(1,X15)/(1-'Mi negocio'!$C$28),6),'Mi negocio'!$C$25)/MAX(1,X15),0) | AB15: =IFERROR(CEILING(ROUND(W15*MAX(1,X15)/(1-'Mi negocio'!$C$29),6),'Mi negocio'!$C$25)/MAX(1,X15),0) | AC15: =IFERROR(CEILING(ROUND(W15*MAX(1,X15)/(1-'Mi negocio'!$C$30),6),'Mi negocio'!$C$25)/MAX(1,X15),0)
A16: 12 | B16: Gajo Super-Ácido de Limón Eureka y Yuzu (Extreme Citrus Yuzu-Lemon Wedge) | C16: Bloque 2 · Ácidas, cítricas y rebozados cristalinos | D16: 2 | E16: G | F16: 5 | G16: pieza | H16: 125 | I16: =SUMIF(Ingredientes!$A$5:$A$1063,A16,Ingredientes!$I$5:$I$1063) | J16: =IFERROR(I16/H16,0) | K16: 0 | L16: 0.012 | M16: 95 | N16: 0.14 | O16: =IFERROR((M16/MAX(1,'Mi negocio'!$C$26)+N16)/60*'Mi negocio'!$C$23,0) | P16: ='Mi negocio'!$C$20 | Q16: 24 | R16: =Q16*'Mi negocio'!$C$39 | S16: =IFERROR(ROUNDDOWN('Mi negocio'!$C$37*24/MAX(1,Q16),0),0) | T16: =J16+K16+L16+O16+P16+R16 | V16: =IF(U16="",'Mi negocio'!$C$24,U16) | W16: =IFERROR(T16/(1-V16),0) | X16: 25 | Y16: =W16*MAX(1,X16) | Z16: =IFERROR(CEILING(ROUND(W16*MAX(1,X16)/(1-'Mi negocio'!$C$27),6),'Mi negocio'!$C$25)/MAX(1,X16),0) | AA16: =IFERROR(CEILING(ROUND(W16*MAX(1,X16)/(1-'Mi negocio'!$C$28),6),'Mi negocio'!$C$25)/MAX(1,X16),0) | AB16: =IFERROR(CEILING(ROUND(W16*MAX(1,X16)/(1-'Mi negocio'!$C$29),6),'Mi negocio'!$C$25)/MAX(1,X16),0) | AC16: =IFERROR(CEILING(ROUND(W16*MAX(1,X16)/(1-'Mi negocio'!$C$30),6),'Mi negocio'!$C$25)/MAX(1,X16),0)
A17: 13 | B17: Cubo Ácido de Maracuyá y Granada en Pectina Lenta (Sour Passion Fruit & Pomegranate HM Jelly) | C17: Bloque 2 · Ácidas, cítricas y rebozados cristalinos | D17: 2 | E17: P | F17: 5 | G17: pieza | H17: 165 | I17: =SUMIF(Ingredientes!$A$5:$A$1063,A17,Ingredientes!$I$5:$I$1063) | J17: =IFERROR(I17/H17,0) | K17: 0 | L17: 0.012 | M17: 95 | N17: 0.14 | O17: =IFERROR((M17/MAX(1,'Mi negocio'!$C$26)+N17)/60*'Mi negocio'!$C$23,0) | P17: ='Mi negocio'!$C$20 | Q17: 36 | R17: =Q17*'Mi negocio'!$C$39 | S17: =IFERROR(ROUNDDOWN('Mi negocio'!$C$37*24/MAX(1,Q17),0),0) | T17: =J17+K17+L17+O17+P17+R17 | V17: =IF(U17="",'Mi negocio'!$C$24,U17) | W17: =IFERROR(T17/(1-V17),0) | X17: 33 | Y17: =W17*MAX(1,X17) | Z17: =IFERROR(CEILING(ROUND(W17*MAX(1,X17)/(1-'Mi negocio'!$C$27),6),'Mi negocio'!$C$25)/MAX(1,X17),0) | AA17: =IFERROR(CEILING(ROUND(W17*MAX(1,X17)/(1-'Mi negocio'!$C$28),6),'Mi negocio'!$C$25)/MAX(1,X17),0) | AB17: =IFERROR(CEILING(ROUND(W17*MAX(1,X17)/(1-'Mi negocio'!$C$29),6),'Mi negocio'!$C$25)/MAX(1,X17),0) | AC17: =IFERROR(CEILING(ROUND(W17*MAX(1,X17)/(1-'Mi negocio'!$C$30),6),'Mi negocio'!$C$25)/MAX(1,X17),0)
A18: 14 | B18: Lágrima de Toronja Rosa y Flor de Saúco con Búfer de Lactato (Buffered Ruby Grapefruit & Elderflower Sour Tear) | C18: Bloque 2 · Ácidas, cítricas y rebozados cristalinos | D18: 2 | E18: H | F18: 6 | G18: pieza | H18: 140 | I18: =SUMIF(Ingredientes!$A$5:$A$1063,A18,Ingredientes!$I$5:$I$1063) | J18: =IFERROR(I18/H18,0) | K18: 0 | L18: 0.012 | M18: 95 | N18: 0.14 | O18: =IFERROR((M18/MAX(1,'Mi negocio'!$C$26)+N18)/60*'Mi negocio'!$C$23,0) | P18: ='Mi negocio'!$C$20 | Q18: 36 | R18: =Q18*'Mi negocio'!$C$39 | S18: =IFERROR(ROUNDDOWN('Mi negocio'!$C$37*24/MAX(1,Q18),0),0) | T18: =J18+K18+L18+O18+P18+R18 | V18: =IF(U18="",'Mi negocio'!$C$24,U18) | W18: =IFERROR(T18/(1-V18),0) | X18: 29 | Y18: =W18*MAX(1,X18) | Z18: =IFERROR(CEILING(ROUND(W18*MAX(1,X18)/(1-'Mi negocio'!$C$27),6),'Mi negocio'!$C$25)/MAX(1,X18),0) | AA18: =IFERROR(CEILING(ROUND(W18*MAX(1,X18)/(1-'Mi negocio'!$C$28),6),'Mi negocio'!$C$25)/MAX(1,X18),0) | AB18: =IFERROR(CEILING(ROUND(W18*MAX(1,X18)/(1-'Mi negocio'!$C$29),6),'Mi negocio'!$C$25)/MAX(1,X18),0) | AC18: =IFERROR(CEILING(ROUND(W18*MAX(1,X18)/(1-'Mi negocio'!$C$30),6),'Mi negocio'!$C$25)/MAX(1,X18),0)
A19: 15 | B19: Botón Ácido de Fruta de la Pasión y Lima Kaffir (Kaffir Lime & Passion Fruit Sour Button) | C19: Bloque 2 · Ácidas, cítricas y rebozados cristalinos | D19: 2 | E19: G | F19: 6 | G19: pieza | H19: 165 | I19: =SUMIF(Ingredientes!$A$5:$A$1063,A19,Ingredientes!$I$5:$I$1063) | J19: =IFERROR(I19/H19,0) | K19: 0 | L19: 0.012 | M19: 95 | N19: 0.14 | O19: =IFERROR((M19/MAX(1,'Mi negocio'!$C$26)+N19)/60*'Mi negocio'!$C$23,0) | P19: ='Mi negocio'!$C$20 | Q19: 24 | R19: =Q19*'Mi negocio'!$C$39 | S19: =IFERROR(ROUNDDOWN('Mi negocio'!$C$37*24/MAX(1,Q19),0),0) | T19: =J19+K19+L19+O19+P19+R19 | V19: =IF(U19="",'Mi negocio'!$C$24,U19) | W19: =IFERROR(T19/(1-V19),0) | X19: 33 | Y19: =W19*MAX(1,X19) | Z19: =IFERROR(CEILING(ROUND(W19*MAX(1,X19)/(1-'Mi negocio'!$C$27),6),'Mi negocio'!$C$25)/MAX(1,X19),0) | AA19: =IFERROR(CEILING(ROUND(W19*MAX(1,X19)/(1-'Mi negocio'!$C$28),6),'Mi negocio'!$C$25)/MAX(1,X19),0) | AB19: =IFERROR(CEILING(ROUND(W19*MAX(1,X19)/(1-'Mi negocio'!$C$29),6),'Mi negocio'!$C$25)/MAX(1,X19),0) | AC19: =IFERROR(CEILING(ROUND(W19*MAX(1,X19)/(1-'Mi negocio'!$C$30),6),'Mi negocio'!$C$25)/MAX(1,X19),0)
A20: 16 | B20: Botella Efervescente de Cola Ácida (Fizzy Sour Cola Bottle) | C20: Bloque 2 · Ácidas, cítricas y rebozados cristalinos | D20: 2 | E20: G | F20: 5 | G20: pieza | H20: 125 | I20: =SUMIF(Ingredientes!$A$5:$A$1063,A20,Ingredientes!$I$5:$I$1063) | J20: =IFERROR(I20/H20,0) | K20: 0 | L20: 0.012 | M20: 95 | N20: 0.14 | O20: =IFERROR((M20/MAX(1,'Mi negocio'!$C$26)+N20)/60*'Mi negocio'!$C$23,0) | P20: ='Mi negocio'!$C$20 | Q20: 24 | R20: =Q20*'Mi negocio'!$C$39 | S20: =IFERROR(ROUNDDOWN('Mi negocio'!$C$37*24/MAX(1,Q20),0),0) | T20: =J20+K20+L20+O20+P20+R20 | V20: =IF(U20="",'Mi negocio'!$C$24,U20) | W20: =IFERROR(T20/(1-V20),0) | X20: 25 | Y20: =W20*MAX(1,X20) | Z20: =IFERROR(CEILING(ROUND(W20*MAX(1,X20)/(1-'Mi negocio'!$C$27),6),'Mi negocio'!$C$25)/MAX(1,X20),0) | AA20: =IFERROR(CEILING(ROUND(W20*MAX(1,X20)/(1-'Mi negocio'!$C$28),6),'Mi negocio'!$C$25)/MAX(1,X20),0) | AB20: =IFERROR(CEILING(ROUND(W20*MAX(1,X20)/(1-'Mi negocio'!$C$29),6),'Mi negocio'!$C$25)/MAX(1,X20),0) | AC20: =IFERROR(CEILING(ROUND(W20*MAX(1,X20)/(1-'Mi negocio'!$C$30),6),'Mi negocio'!$C$25)/MAX(1,X20),0)
A21: 17 | B21: Cinta Ácida de Naranja Sangrienta y Granada (Sour Blood Orange & Pomegranate Belt) | C21: Bloque 2 · Ácidas, cítricas y rebozados cristalinos | D21: 2 | E21: H | F21: 6 | G21: pieza | H21: 150 | I21: =SUMIF(Ingredientes!$A$5:$A$1063,A21,Ingredientes!$I$5:$I$1063) | J21: =IFERROR(I21/H21,0) | K21: 0 | L21: 0.012 | M21: 95 | N21: 0.14 | O21: =IFERROR((M21/MAX(1,'Mi negocio'!$C$26)+N21)/60*'Mi negocio'!$C$23,0) | P21: ='Mi negocio'!$C$20 | Q21: 36 | R21: =Q21*'Mi negocio'!$C$39 | S21: =IFERROR(ROUNDDOWN('Mi negocio'!$C$37*24/MAX(1,Q21),0),0) | T21: =J21+K21+L21+O21+P21+R21 | V21: =IF(U21="",'Mi negocio'!$C$24,U21) | W21: =IFERROR(T21/(1-V21),0) | X21: 8 | Y21: =W21*MAX(1,X21) | Z21: =IFERROR(CEILING(ROUND(W21*MAX(1,X21)/(1-'Mi negocio'!$C$27),6),'Mi negocio'!$C$25)/MAX(1,X21),0) | AA21: =IFERROR(CEILING(ROUND(W21*MAX(1,X21)/(1-'Mi negocio'!$C$28),6),'Mi negocio'!$C$25)/MAX(1,X21),0) | AB21: =IFERROR(CEILING(ROUND(W21*MAX(1,X21)/(1-'Mi negocio'!$C$29),6),'Mi negocio'!$C$25)/MAX(1,X21),0) | AC21: =IFERROR(CEILING(ROUND(W21*MAX(1,X21)/(1-'Mi negocio'!$C$30),6),'Mi negocio'!$C$25)/MAX(1,X21),0)
A22: 18 | B22: Esfera de Mandarina Verde y Lima-Limón en Pectina Rápida (Quick-Gel Green Mandarin Sour Orb) | C22: Bloque 2 · Ácidas, cítricas y rebozados cristalinos | D22: 2 | E22: P | F22: 5 | G22: pieza | H22: 165 | I22: =SUMIF(Ingredientes!$A$5:$A$1063,A22,Ingredientes!$I$5:$I$1063) | J22: =IFERROR(I22/H22,0) | K22: 0 | L22: 0.012 | M22: 95 | N22: 0.14 | O22: =IFERROR((M22/MAX(1,'Mi negocio'!$C$26)+N22)/60*'Mi negocio'!$C$23,0) | P22: ='Mi negocio'!$C$20 | Q22: 36 | R22: =Q22*'Mi negocio'!$C$39 | S22: =IFERROR(ROUNDDOWN('Mi negocio'!$C$37*24/MAX(1,Q22),0),0) | T22: =J22+K22+L22+O22+P22+R22 | V22: =IF(U22="",'Mi negocio'!$C$24,U22) | W22: =IFERROR(T22/(1-V22),0) | X22: 33 | Y22: =W22*MAX(1,X22) | Z22: =IFERROR(CEILING(ROUND(W22*MAX(1,X22)/(1-'Mi negocio'!$C$27),6),'Mi negocio'!$C$25)/MAX(1,X22),0) | AA22: =IFERROR(CEILING(ROUND(W22*MAX(1,X22)/(1-'Mi negocio'!$C$28),6),'Mi negocio'!$C$25)/MAX(1,X22),0) | AB22: =IFERROR(CEILING(ROUND(W22*MAX(1,X22)/(1-'Mi negocio'!$C$29),6),'Mi negocio'!$C$25)/MAX(1,X22),0) | AC22: =IFERROR(CEILING(ROUND(W22*MAX(1,X22)/(1-'Mi negocio'!$C$30),6),'Mi negocio'!$C$25)/MAX(1,X22),0)
A23: 19 | B23: Aro Ácido de Manzana y Grosella Negra (Sour Blackcurrant & Green Apple Ring) | C23: Bloque 2 · Ácidas, cítricas y rebozados cristalinos | D23: 2 | E23: G | F23: 6 | G23: pieza | H23: 110 | I23: =SUMIF(Ingredientes!$A$5:$A$1063,A23,Ingredientes!$I$5:$I$1063) | J23: =IFERROR(I23/H23,0) | K23: 0 | L23: 0.012 | M23: 95 | N23: 0.14 | O23: =IFERROR((M23/MAX(1,'Mi negocio'!$C$26)+N23)/60*'Mi negocio'!$C$23,0) | P23: ='Mi negocio'!$C$20 | Q23: 24 | R23: =Q23*'Mi negocio'!$C$39 | S23: =IFERROR(ROUNDDOWN('Mi negocio'!$C$37*24/MAX(1,Q23),0),0) | T23: =J23+K23+L23+O23+P23+R23 | V23: =IF(U23="",'Mi negocio'!$C$24,U23) | W23: =IFERROR(T23/(1-V23),0) | X23: 22 | Y23: =W23*MAX(1,X23) | Z23: =IFERROR(CEILING(ROUND(W23*MAX(1,X23)/(1-'Mi negocio'!$C$27),6),'Mi negocio'!$C$25)/MAX(1,X23),0) | AA23: =IFERROR(CEILING(ROUND(W23*MAX(1,X23)/(1-'Mi negocio'!$C$28),6),'Mi negocio'!$C$25)/MAX(1,X23),0) | AB23: =IFERROR(CEILING(ROUND(W23*MAX(1,X23)/(1-'Mi negocio'!$C$29),6),'Mi negocio'!$C$25)/MAX(1,X23),0) | AC23: =IFERROR(CEILING(ROUND(W23*MAX(1,X23)/(1-'Mi negocio'!$C$30),6),'Mi negocio'!$C$25)/MAX(1,X23),0)
A24: 20 | B24: Lengüeta Ácida de Piña Asada y Jengibre Picante (Sour Charred Pineapple & Ginger Tongue) | C24: Bloque 2 · Ácidas, cítricas y rebozados cristalinos | D24: 2 | E24: G | F24: 6 | G24: pieza | H24: 150 | I24: =SUMIF(Ingredientes!$A$5:$A$1063,A24,Ingredientes!$I$5:$I$1063) | J24: =IFERROR(I24/H24,0) | K24: 0 | L24: 0.012 | M24: 95 | N24: 0.14 | O24: =IFERROR((M24/MAX(1,'Mi negocio'!$C$26)+N24)/60*'Mi negocio'!$C$23,0) | P24: ='Mi negocio'!$C$20 | Q24: 24 | R24: =Q24*'Mi negocio'!$C$39 | S24: =IFERROR(ROUNDDOWN('Mi negocio'!$C$37*24/MAX(1,Q24),0),0) | T24: =J24+K24+L24+O24+P24+R24 | V24: =IF(U24="",'Mi negocio'!$C$24,U24) | W24: =IFERROR(T24/(1-V24),0) | X24: 11 | Y24: =W24*MAX(1,X24) | Z24: =IFERROR(CEILING(ROUND(W24*MAX(1,X24)/(1-'Mi negocio'!$C$27),6),'Mi negocio'!$C$25)/MAX(1,X24),0) | AA24: =IFERROR(CEILING(ROUND(W24*MAX(1,X24)/(1-'Mi negocio'!$C$28),6),'Mi negocio'!$C$25)/MAX(1,X24),0) | AB24: =IFERROR(CEILING(ROUND(W24*MAX(1,X24)/(1-'Mi negocio'!$C$29),6),'Mi negocio'!$C$25)/MAX(1,X24),0) | AC24: =IFERROR(CEILING(ROUND(W24*MAX(1,X24)/(1-'Mi negocio'!$C$30),6),'Mi negocio'!$C$25)/MAX(1,X24),0)
... A34: 30 | B34: Manzana Verde con Canela de Ceilán, Chipotle y Piquín (Green Apple, Ceylon Cinnamon & Sweet Chipotle Drop) | C34: Bloque 3 · Enchiladas, botánicas y confituras con chamoy | D34: 3 | E34: H | F34: 5 | G34: pieza | H34: 140 | I34: =SUMIF(Ingredientes!$A$5:$A$1063,A34,Ingredientes!$I$5:$I$1063) | J34: =IFERROR(I34/H34,0) | K34: 0 | L34: 0.012 | M34: 95 | N34: 0.14 | O34: =IFERROR((M34/MAX(1,'Mi negocio'!$C$26)+N34)/60*'Mi negocio'!$C$23,0) | P34: ='Mi negocio'!$C$20 | Q34: 36 | R34: =Q34*'Mi negocio'!$C$39 | S34: =IFERROR(ROUNDDOWN('Mi negocio'!$C$37*24/MAX(1,Q34),0),0) | T34: =J34+K34+L34+O34+P34+R34 | V34: =IF(U34="",'Mi negocio'!$C$24,U34) | W34: =IFERROR(T34/(1-V34),0) | X34: 29 | Y34: =W34*MAX(1,X34) | Z34: =IFERROR(CEILING(ROUND(W34*MAX(1,X34)/(1-'Mi negocio'!$C$27),6),'Mi negocio'!$C$25)/MAX(1,X34),0) | AA34: =IFERROR(CEILING(ROUND(W34*MAX(1,X34)/(1-'Mi negocio'!$C$28),6),'Mi negocio'!$C$25)/MAX(1,X34),0) | AB34: =IFERROR(CEILING(ROUND(W34*MAX(1,X34)/(1-'Mi negocio'!$C$29),6),'Mi negocio'!$C$25)/MAX(1,X34),0) | AC34: =IFERROR(CEILING(ROUND(W34*MAX(1,X34)/(1-'Mi negocio'!$C$30),6),'Mi negocio'!$C$25)/MAX(1,X34),0)
A35: 31 | B35: Tiburón / Delfín Bicolor de Frambuesa Azul y Espuma Marshmallow (Two-Tone Blue Raspberry & Marshmallow Foam Sea-Jelly) | C35: Bloque 4 · Multicapa, bicolor, espumadas y núcleos líquidos | D35: 4 | E35: G | F35: 6 | G35: pieza | H35: 100 | I35: =SUMIF(Ingredientes!$A$5:$A$1063,A35,Ingredientes!$I$5:$I$1063) | J35: =IFERROR(I35/H35,0) | K35: 0 | L35: 0.02 | M35: 165 | N35: 0.26 | O35: =IFERROR((M35/MAX(1,'Mi negocio'!$C$26)+N35)/60*'Mi negocio'!$C$23,0) | P35: ='Mi negocio'!$C$20 | Q35: 42 | R35: =Q35*'Mi negocio'!$C$39 | S35: =IFERROR(ROUNDDOWN('Mi negocio'!$C$37*24/MAX(1,Q35),0),0) | T35: =J35+K35+L35+O35+P35+R35 | U35: 0.14 | V35: =IF(U35="",'Mi negocio'!$C$24,U35) | W35: =IFERROR(T35/(1-V35),0) | X35: 20 | Y35: =W35*MAX(1,X35) | Z35: =IFERROR(CEILING(ROUND(W35*MAX(1,X35)/(1-'Mi negocio'!$C$27),6),'Mi negocio'!$C$25)/MAX(1,X35),0) | AA35: =IFERROR(CEILING(ROUND(W35*MAX(1,X35)/(1-'Mi negocio'!$C$28),6),'Mi negocio'!$C$25)/MAX(1,X35),0) | AB35: =IFERROR(CEILING(ROUND(W35*MAX(1,X35)/(1-'Mi negocio'!$C$29),6),'Mi negocio'!$C$25)/MAX(1,X35),0) | AC35: =IFERROR(CEILING(ROUND(W35*MAX(1,X35)/(1-'Mi negocio'!$C$30),6),'Mi negocio'!$C$25)/MAX(1,X35),0)
A36: 32 | B36: Domo con Núcleo Líquido Inyectado de Fresa (Liquid-Center Co-Deposited Strawberry Lava Dome) | C36: Bloque 4 · Multicapa, bicolor, espumadas y núcleos líquidos | D36: 4 | E36: H | F36: 4 | G36: pieza | H36: 80 | I36: =SUMIF(Ingredientes!$A$5:$A$1063,A36,Ingredientes!$I$5:$I$1063) | J36: =IFERROR(I36/H36,0) | K36: 0 | L36: 0.02 | M36: 150 | N36: 0.2 | O36: =IFERROR((M36/MAX(1,'Mi negocio'!$C$26)+N36)/60*'Mi negocio'!$C$23,0) | P36: ='Mi negocio'!$C$20 | Q36: 42 | R36: =Q36*'Mi negocio'!$C$39 | S36: =IFERROR(ROUNDDOWN('Mi negocio'!$C$37*24/MAX(1,Q36),0),0) | T36: =J36+K36+L36+O36+P36+R36 | V36: =IF(U36="",'Mi negocio'!$C$24,U36) | W36: =IFERROR(T36/(1-V36),0) | X36: 17 | Y36: =W36*MAX(1,X36) | Z36: =IFERROR(CEILING(ROUND(W36*MAX(1,X36)/(1-'Mi negocio'!$C$27),6),'Mi negocio'!$C$25)/MAX(1,X36),0) | AA36: =IFERROR(CEILING(ROUND(W36*MAX(1,X36)/(1-'Mi negocio'!$C$28),6),'Mi negocio'!$C$25)/MAX(1,X36),0) | AB36: =IFERROR(CEILING(ROUND(W36*MAX(1,X36)/(1-'Mi negocio'!$C$29),6),'Mi negocio'!$C$25)/MAX(1,X36),0) | AC36: =IFERROR(CEILING(ROUND(W36*MAX(1,X36)/(1-'Mi negocio'!$C$30),6),'Mi negocio'!$C$25)/MAX(1,X36),0)
A37: 33 | B37: Sándwich Tricapa Napolitano de Fresa, Vainilla y Chocolate (Neapolitan Tri-Layer Marshmallow & Gummy Sandwich) | C37: Bloque 4 · Multicapa, bicolor, espumadas y núcleos líquidos | D37: 4 | E37: G | F37: 5 | G37: pieza | H37: 150 | I37: =SUMIF(Ingredientes!$A$5:$A$1063,A37,Ingredientes!$I$5:$I$1063) | J37: =IFERROR(I37/H37,0) | K37: 0 | L37: 0.02 | M37: 150 | N37: 0.2 | O37: =IFERROR((M37/MAX(1,'Mi negocio'!$C$26)+N37)/60*'Mi negocio'!$C$23,0) | P37: ='Mi negocio'!$C$20 | Q37: 40 | R37: =Q37*'Mi negocio'!$C$39 | S37: =IFERROR(ROUNDDOWN('Mi negocio'!$C$37*24/MAX(1,Q37),0),0) | T37: =J37+K37+L37+O37+P37+R37 | V37: =IF(U37="",'Mi negocio'!$C$24,U37) | W37: =IFERROR(T37/(1-V37),0) | X37: 17 | Y37: =W37*MAX(1,X37) | Z37: =IFERROR(CEILING(ROUND(W37*MAX(1,X37)/(1-'Mi negocio'!$C$27),6),'Mi negocio'!$C$25)/MAX(1,X37),0) | AA37: =IFERROR(CEILING(ROUND(W37*MAX(1,X37)/(1-'Mi negocio'!$C$28),6),'Mi negocio'!$C$25)/MAX(1,X37),0) | AB37: =IFERROR(CEILING(ROUND(W37*MAX(1,X37)/(1-'Mi negocio'!$C$29),6),'Mi negocio'!$C$25)/MAX(1,X37),0) | AC37: =IFERROR(CEILING(ROUND(W37*MAX(1,X37)/(1-'Mi negocio'!$C$30),6),'Mi negocio'!$C$25)/MAX(1,X37),0)
A38: 34 | B38: Perla Encapsulada con Esfera de Isomalt y Núcleo Semilíquido (Suspended Geode Pearl with Semi-Liquid Core) | C38: Bloque 4 · Multicapa, bicolor, espumadas y núcleos líquidos | D38: 4 | E38: G | F38: 4 | G38: pieza | H38: 100 | I38: =SUMIF(Ingredientes!$A$5:$A$1063,A38,Ingredientes!$I$5:$I$1063) | J38: =IFERROR(I38/H38,0) | K38: 0 | L38: 0.02 | M38: 185 | N38: 0.45 | O38: =IFERROR((M38/MAX(1,'Mi negocio'!$C$26)+N38)/60*'Mi negocio'!$C$23,0) | P38: ='Mi negocio'!$C$20 | Q38: 48 | R38: =Q38*'Mi negocio'!$C$39 | S38: =IFERROR(ROUNDDOWN('Mi negocio'!$C$37*24/MAX(1,Q38),0),0) | T38: =J38+K38+L38+O38+P38+R38 | U38: 0.18 | V38: =IF(U38="",'Mi negocio'!$C$24,U38) | W38: =IFERROR(T38/(1-V38),0) | X38: 20 | Y38: =W38*MAX(1,X38) | Z38: =IFERROR(CEILING(ROUND(W38*MAX(1,X38)/(1-'Mi negocio'!$C$27),6),'Mi negocio'!$C$25)/MAX(1,X38),0) | AA38: =IFERROR(CEILING(ROUND(W38*MAX(1,X38)/(1-'Mi negocio'!$C$28),6),'Mi negocio'!$C$25)/MAX(1,X38),0) | AB38: =IFERROR(CEILING(ROUND(W38*MAX(1,X38)/(1-'Mi negocio'!$C$29),6),'Mi negocio'!$C$25)/MAX(1,X38),0) | AC38: =IFERROR(CEILING(ROUND(W38*MAX(1,X38)/(1-'Mi negocio'!$C$30),6),'Mi negocio'!$C$25)/MAX(1,X38),0)
A39: 35 | B39: Trenza Helicoidal Bicolor de Mango y Frambuesa en Extrusión Doble (Double-Helix Extruded Mango & Raspberry Twist) | C39: Bloque 4 · Multicapa, bicolor, espumadas y núcleos líquidos | D39: 4 | E39: G | F39: 6 | G39: pieza | H39: 80 | I39: =SUMIF(Ingredientes!$A$5:$A$1063,A39,Ingredientes!$I$5:$I$1063) | J39: =IFERROR(I39/H39,0) | K39: 0 | L39: 0.02 | M39: 150 | N39: 0.2 | O39: =IFERROR((M39/MAX(1,'Mi negocio'!$C$26)+N39)/60*'Mi negocio'!$C$23,0) | P39: ='Mi negocio'!$C$20 | Q39: 42 | R39: =Q39*'Mi negocio'!$C$39 | S39: =IFERROR(ROUNDDOWN('Mi negocio'!$C$37*24/MAX(1,Q39),0),0) | T39: =J39+K39+L39+O39+P39+R39 | U39: 0.15 | V39: =IF(U39="",'Mi negocio'!$C$24,U39) | W39: =IFERROR(T39/(1-V39),0) | X39: 17 | Y39: =W39*MAX(1,X39) | Z39: =IFERROR(CEILING(ROUND(W39*MAX(1,X39)/(1-'Mi negocio'!$C$27),6),'Mi negocio'!$C$25)/MAX(1,X39),0) | AA39: =IFERROR(CEILING(ROUND(W39*MAX(1,X39)/(1-'Mi negocio'!$C$28),6),'Mi negocio'!$C$25)/MAX(1,X39),0) | AB39: =IFERROR(CEILING(ROUND(W39*MAX(1,X39)/(1-'Mi negocio'!$C$29),6),'Mi negocio'!$C$25)/MAX(1,X39),0) | AC39: =IFERROR(CEILING(ROUND(W39*MAX(1,X39)/(1-'Mi negocio'!$C$30),6),'Mi negocio'!$C$25)/MAX(1,X39),0)
A40: 36 | B40: Huevo Frito Clásico de Yema Cítrica y Clara Marshmallow (Sunny-Side Up Egg: Citrus Gel & Vanilla Foam) | C40: Bloque 4 · Multicapa, bicolor, espumadas y núcleos líquidos | D40: 4 | E40: G | F40: 6 | G40: pieza | H40: 90 | I40: =SUMIF(Ingredientes!$A$5:$A$1063,A40,Ingredientes!$I$5:$I$1063) | J40: =IFERROR(I40/H40,0) | K40: 0 | L40: 0.02 | M40: 170 | N40: 0.34 | O40: =IFERROR((M40/MAX(1,'Mi negocio'!$C$26)+N40)/60*'Mi negocio'!$C$23,0) | P40: ='Mi negocio'!$C$20 | Q40: 44 | R40: =Q40*'Mi negocio'!$C$39 | S40: =IFERROR(ROUNDDOWN('Mi negocio'!$C$37*24/MAX(1,Q40),0),0) | T40: =J40+K40+L40+O40+P40+R40 | U40: 0.16 | V40: =IF(U40="",'Mi negocio'!$C$24,U40) | W40: =IFERROR(T40/(1-V40),0) | X40: 18 | Y40: =W40*MAX(1,X40) | Z40: =IFERROR(CEILING(ROUND(W40*MAX(1,X40)/(1-'Mi negocio'!$C$27),6),'Mi negocio'!$C$25)/MAX(1,X40),0) | AA40: =IFERROR(CEILING(ROUND(W40*MAX(1,X40)/(1-'Mi negocio'!$C$28),6),'Mi negocio'!$C$25)/MAX(1,X40),0) | AB40: =IFERROR(CEILING(ROUND(W40*MAX(1,X40)/(1-'Mi negocio'!$C$29),6),'Mi negocio'!$C$25)/MAX(1,X40),0) | AC40: =IFERROR(CEILING(ROUND(W40*MAX(1,X40)/(1-'Mi negocio'!$C$30),6),'Mi negocio'!$C$25)/MAX(1,X40),0)
A41: 37 | B41: Ojo Eyeball Sangriento con Núcleo Líquido de Cereza Ácida (Spooky Eyeball with Sour Cherry Lava Core) | C41: Bloque 4 · Multicapa, bicolor, espumadas y núcleos líquidos | D41: 4 | E41: H | F41: 4 | G41: pieza | H41: 70 | I41: =SUMIF(Ingredientes!$A$5:$A$1063,A41,Ingredientes!$I$5:$I$1063) | J41: =IFERROR(I41/H41,0) | K41: 0 | L41: 0.02 | M41: 160 | N41: 0.38 | O41: =IFERROR((M41/MAX(1,'Mi negocio'!$C$26)+N41)/60*'Mi negocio'!$C$23,0) | P41: ='Mi negocio'!$C$20 | Q41: 40 | R41: =Q41*'Mi negocio'!$C$39 | S41: =IFERROR(ROUNDDOWN('Mi negocio'!$C$37*24/MAX(1,Q41),0),0) | T41: =J41+K41+L41+O41+P41+R41 | U41: 0.16 | V41: =IF(U41="",'Mi negocio'!$C$24,U41) | W41: =IFERROR(T41/(1-V41),0) | X41: 14 | Y41: =W41*MAX(1,X41) | Z41: =IFERROR(CEILING(ROUND(W41*MAX(1,X41)/(1-'Mi negocio'!$C$27),6),'Mi negocio'!$C$25)/MAX(1,X41),0) | AA41: =IFERROR(CEILING(ROUND(W41*MAX(1,X41)/(1-'Mi negocio'!$C$28),6),'Mi negocio'!$C$25)/MAX(1,X41),0) | AB41: =IFERROR(CEILING(ROUND(W41*MAX(1,X41)/(1-'Mi negocio'!$C$29),6),'Mi negocio'!$C$25)/MAX(1,X41),0) | AC41: =IFERROR(CEILING(ROUND(W41*MAX(1,X41)/(1-'Mi negocio'!$C$30),6),'Mi negocio'!$C$25)/MAX(1,X41),0)
A42: 38 | B42: Gota Francesa Rellena de Confit Frutal en Pectina Pura (Pâte de Fruits Framboise Fourrée au Confit de Maracuyá) | C42: Bloque 4 · Multicapa, bicolor, espumadas y núcleos líquidos | D42: 4 | E42: P | F42: 5 | G42: pieza | H42: 100 | I42: =SUMIF(Ingredientes!$A$5:$A$1063,A42,Ingredientes!$I$5:$I$1063) | J42: =IFERROR(I42/H42,0) | K42: 0 | L42: 0.02 | M42: 150 | N42: 0.2 | O42: =IFERROR((M42/MAX(1,'Mi negocio'!$C$26)+N42)/60*'Mi negocio'!$C$23,0) | P42: ='Mi negocio'!$C$20 | Q42: 40 | R42: =Q42*'Mi negocio'!$C$39 | S42: =IFERROR(ROUNDDOWN('Mi negocio'!$C$37*24/MAX(1,Q42),0),0) | T42: =J42+K42+L42+O42+P42+R42 | V42: =IF(U42="",'Mi negocio'!$C$24,U42) | W42: =IFERROR(T42/(1-V42),0) | X42: 20 | Y42: =W42*MAX(1,X42) | Z42: =IFERROR(CEILING(ROUND(W42*MAX(1,X42)/(1-'Mi negocio'!$C$27),6),'Mi negocio'!$C$25)/MAX(1,X42),0) | AA42: =IFERROR(CEILING(ROUND(W42*MAX(1,X42)/(1-'Mi negocio'!$C$28),6),'Mi negocio'!$C$25)/MAX(1,X42),0) | AB42: =IFERROR(CEILING(ROUND(W42*MAX(1,X42)/(1-'Mi negocio'!$C$29),6),'Mi negocio'!$C$25)/MAX(1,X42),0) | AC42: =IFERROR(CEILING(ROUND(W42*MAX(1,X42)/(1-'Mi negocio'!$C$30),6),'Mi negocio'!$C$25)/MAX(1,X42),0)
A43: 39 | B43: Bloque Bicolor de Melocotón y Mora con Doble Viscosidad (Dual-Viscosity Peach & Blackberry Layered Brick) | C43: Bloque 4 · Multicapa, bicolor, espumadas y núcleos líquidos | D43: 4 | E43: G | F43: 6 | G43: pieza | H43: 100 | I43: =SUMIF(Ingredientes!$A$5:$A$1063,A43,Ingredientes!$I$5:$I$1063) | J43: =IFERROR(I43/H43,0) | K43: 0 | L43: 0.02 | M43: 175 | N43: 0.3 | O43: =IFERROR((M43/MAX(1,'Mi negocio'!$C$26)+N43)/60*'Mi negocio'!$C$23,0) | P43: ='Mi negocio'!$C$20 | Q43: 44 | R43: =Q43*'Mi negocio'!$C$39 | S43: =IFERROR(ROUNDDOWN('Mi negocio'!$C$37*24/MAX(1,Q43),0),0) | T43: =J43+K43+L43+O43+P43+R43 | U43: 0.15 | V43: =IF(U43="",'Mi negocio'!$C$24,U43) | W43: =IFERROR(T43/(1-V43),0) | X43: 20 | Y43: =W43*MAX(1,X43) | Z43: =IFERROR(CEILING(ROUND(W43*MAX(1,X43)/(1-'Mi negocio'!$C$27),6),'Mi negocio'!$C$25)/MAX(1,X43),0) | AA43: =IFERROR(CEILING(ROUND(W43*MAX(1,X43)/(1-'Mi negocio'!$C$28),6),'Mi negocio'!$C$25)/MAX(1,X43),0) | AB43: =IFERROR(CEILING(ROUND(W43*MAX(1,X43)/(1-'Mi negocio'!$C$29),6),'Mi negocio'!$C$25)/MAX(1,X43),0) | AC43: =IFERROR(CEILING(ROUND(W43*MAX(1,X43)/(1-'Mi negocio'!$C$30),6),'Mi negocio'!$C$25)/MAX(1,X43),0)
A44: 40 | B44: Nube Cítrica de Lima-Limón en Espuma Suave con Base Elástica (Marshmallow Cloud & Citrus Jelly Base) | C44: Bloque 4 · Multicapa, bicolor, espumadas y núcleos líquidos | D44: 4 | E44: G | F44: 5 | G44: pieza | H44: 100 | I44: =SUMIF(Ingredientes!$A$5:$A$1063,A44,Ingredientes!$I$5:$I$1063) | J44: =IFERROR(I44/H44,0) | K44: 0 | L44: 0.02 | M44: 165 | N44: 0.2 | O44: =IFERROR((M44/MAX(1,'Mi negocio'!$C$26)+N44)/60*'Mi negocio'!$C$23,0) | P44: ='Mi negocio'!$C$20 | Q44: 42 | R44: =Q44*'Mi negocio'!$C$39 | S44: =IFERROR(ROUNDDOWN('Mi negocio'!$C$37*24/MAX(1,Q44),0),0) | T44: =J44+K44+L44+O44+P44+R44 | U44: 0.14 | V44: =IF(U44="",'Mi negocio'!$C$24,U44) | W44: =IFERROR(T44/(1-V44),0) | X44: 20 | Y44: =W44*MAX(1,X44) | Z44: =IFERROR(CEILING(ROUND(W44*MAX(1,X44)/(1-'Mi negocio'!$C$27),6),'Mi negocio'!$C$25)/MAX(1,X44),0) | AA44: =IFERROR(CEILING(ROUND(W44*MAX(1,X44)/(1-'Mi negocio'!$C$28),6),'Mi negocio'!$C$25)/MAX(1,X44),0) | AB44: =IFERROR(CEILING(ROUND(W44*MAX(1,X44)/(1-'Mi negocio'!$C$29),6),'Mi negocio'!$C$25)/MAX(1,X44),0) | AC44: =IFERROR(CEILING(ROUND(W44*MAX(1,X44)/(1-'Mi negocio'!$C$30),6),'Mi negocio'!$C$25)/MAX(1,X44),0)
A45: 41 | B45: Perla de Gin Tonic con Enebro, Cardamomo y Pepino (Gin & Tonic Botanical Jewel) | C45: Bloque 5 · Gourmet de autor, coctelería, infusiones y funcionales | D45: 5 | E45: A | F45: 5 | G45: pieza | H45: 125 | I45: =SUMIF(Ingredientes!$A$5:$A$1063,A45,Ingredientes!$I$5:$I$1063) | J45: =IFERROR(I45/H45,0) | K45: 0 | L45: 0.02 | M45: 140 | N45: 0.17 | O45: =IFERROR((M45/MAX(1,'Mi negocio'!$C$26)+N45)/60*'Mi negocio'!$C$23,0) | P45: ='Mi negocio'!$C$20 | Q45: 30 | R45: =Q45*'Mi negocio'!$C$39 | S45: =IFERROR(ROUNDDOWN('Mi negocio'!$C$37*24/MAX(1,Q45),0),0) | T45: =J45+K45+L45+O45+P45+R45 | V45: =IF(U45="",'Mi negocio'!$C$24,U45) | W45: =IFERROR(T45/(1-V45),0) | X45: 25 | Y45: =W45*MAX(1,X45) | Z45: =IFERROR(CEILING(ROUND(W45*MAX(1,X45)/(1-'Mi negocio'!$C$27),6),'Mi negocio'!$C$25)/MAX(1,X45),0) | AA45: =IFERROR(CEILING(ROUND(W45*MAX(1,X45)/(1-'Mi negocio'!$C$28),6),'Mi negocio'!$C$25)/MAX(1,X45),0) | AB45: =IFERROR(CEILING(ROUND(W45*MAX(1,X45)/(1-'Mi negocio'!$C$29),6),'Mi negocio'!$C$25)/MAX(1,X45),0) | AC45: =IFERROR(CEILING(ROUND(W45*MAX(1,X45)/(1-'Mi negocio'!$C$30),6),'Mi negocio'!$C$25)/MAX(1,X45),0)
A46: 42 | B46: Confitura de Frambuesa al Vinagre Balsámico Tradicional de Módena DOP (Balsamic Raspberry & Aceto di Modena DOP Pâte de Fruits) | C46: Bloque 5 · Gourmet de autor, coctelería, infusiones y funcionales | D46: 5 | E46: P | F46: 5 | G46: pieza | H46: 125 | I46: =SUMIF(Ingredientes!$A$5:$A$1063,A46,Ingredientes!$I$5:$I$1063) | J46: =IFERROR(I46/H46,0) | K46: 0 | L46: 0.02 | M46: 125 | N46: 0.17 | O46: =IFERROR((M46/MAX(1,'Mi negocio'!$C$26)+N46)/60*'Mi negocio'!$C$23,0) | P46: ='Mi negocio'!$C$20 | Q46: 36 | R46: =Q46*'Mi negocio'!$C$39 | S46: =IFERROR(ROUNDDOWN('Mi negocio'!$C$37*24/MAX(1,Q46),0),0) | T46: =J46+K46+L46+O46+P46+R46 | V46: =IF(U46="",'Mi negocio'!$C$24,U46) | W46: =IFERROR(T46/(1-V46),0) | X46: 25 | Y46: =W46*MAX(1,X46) | Z46: =IFERROR(CEILING(ROUND(W46*MAX(1,X46)/(1-'Mi negocio'!$C$27),6),'Mi negocio'!$C$25)/MAX(1,X46),0) | AA46: =IFERROR(CEILING(ROUND(W46*MAX(1,X46)/(1-'Mi negocio'!$C$28),6),'Mi negocio'!$C$25)/MAX(1,X46),0) | AB46: =IFERROR(CEILING(ROUND(W46*MAX(1,X46)/(1-'Mi negocio'!$C$29),6),'Mi negocio'!$C$25)/MAX(1,X46),0) | AC46: =IFERROR(CEILING(ROUND(W46*MAX(1,X46)/(1-'Mi negocio'!$C$30),6),'Mi negocio'!$C$25)/MAX(1,X46),0)
A47: 43 | B47: Gomita de Cacao Grand Cru y Flor de Sal de Guérande (Pure Dark Chocolate 70% & Fleur de Sel Jelly) | C47: Bloque 5 · Gourmet de autor, coctelería, infusiones y funcionales | D47: 5 | E47: G | F47: 5 | G47: pieza | H47: 125 | I47: =SUMIF(Ingredientes!$A$5:$A$1063,A47,Ingredientes!$I$5:$I$1063) | J47: =IFERROR(I47/H47,0) | K47: 0 | L47: 0.02 | M47: 125 | N47: 0.17 | O47: =IFERROR((M47/MAX(1,'Mi negocio'!$C$26)+N47)/60*'Mi negocio'!$C$23,0) | P47: ='Mi negocio'!$C$20 | Q47: 24 | R47: =Q47*'Mi negocio'!$C$39 | S47: =IFERROR(ROUNDDOWN('Mi negocio'!$C$37*24/MAX(1,Q47),0),0) | T47: =J47+K47+L47+O47+P47+R47 | V47: =IF(U47="",'Mi negocio'!$C$24,U47) | W47: =IFERROR(T47/(1-V47),0) | X47: 25 | Y47: =W47*MAX(1,X47) | Z47: =IFERROR(CEILING(ROUND(W47*MAX(1,X47)/(1-'Mi negocio'!$C$27),6),'Mi negocio'!$C$25)/MAX(1,X47),0) | AA47: =IFERROR(CEILING(ROUND(W47*MAX(1,X47)/(1-'Mi negocio'!$C$28),6),'Mi negocio'!$C$25)/MAX(1,X47),0) | AB47: =IFERROR(CEILING(ROUND(W47*MAX(1,X47)/(1-'Mi negocio'!$C$29),6),'Mi negocio'!$C$25)/MAX(1,X47),0) | AC47: =IFERROR(CEILING(ROUND(W47*MAX(1,X47)/(1-'Mi negocio'!$C$30),6),'Mi negocio'!$C$25)/MAX(1,X47),0)
A48: 44 | B48: Domo de Té Verde Matcha Ceremonial y Limón Yuzu (Uji Matcha & Yuzu Citrus Dome) | C48: Bloque 5 · Gourmet de autor, coctelería, infusiones y funcionales | D48: 5 | E48: H | F48: 4 | G48: pieza | H48: 140 | I48: =SUMIF(Ingredientes!$A$5:$A$1063,A48,Ingredientes!$I$5:$I$1063) | J48: =IFERROR(I48/H48,0) | K48: 0 | L48: 0.02 | M48: 135 | N48: 0.17 | O48: =IFERROR((M48/MAX(1,'Mi negocio'!$C$26)+N48)/60*'Mi negocio'!$C$23,0) | P48: ='Mi negocio'!$C$20 | Q48: 36 | R48: =Q48*'Mi negocio'!$C$39 | S48: =IFERROR(ROUNDDOWN('Mi negocio'!$C$37*24/MAX(1,Q48),0),0) | T48: =J48+K48+L48+O48+P48+R48 | V48: =IF(U48="",'Mi negocio'!$C$24,U48) | W48: =IFERROR(T48/(1-V48),0) | X48: 29 | Y48: =W48*MAX(1,X48) | Z48: =IFERROR(CEILING(ROUND(W48*MAX(1,X48)/(1-'Mi negocio'!$C$27),6),'Mi negocio'!$C$25)/MAX(1,X48),0) | AA48: =IFERROR(CEILING(ROUND(W48*MAX(1,X48)/(1-'Mi negocio'!$C$28),6),'Mi negocio'!$C$25)/MAX(1,X48),0) | AB48: =IFERROR(CEILING(ROUND(W48*MAX(1,X48)/(1-'Mi negocio'!$C$29),6),'Mi negocio'!$C$25)/MAX(1,X48),0) | AC48: =IFERROR(CEILING(ROUND(W48*MAX(1,X48)/(1-'Mi negocio'!$C$30),6),'Mi negocio'!$C$25)/MAX(1,X48),0)
A49: 45 | B49: Joya de Maracuyá, Lavanda Francesa y Miel de Abeja Cruda (Passion Fruit, Lavender & Raw Honey Botanical Gem) | C49: Bloque 5 · Gourmet de autor, coctelería, infusiones y funcionales | D49: 5 | E49: G | F49: 5 | G49: pieza | H49: 125 | I49: =SUMIF(Ingredientes!$A$5:$A$1063,A49,Ingredientes!$I$5:$I$1063) | J49: =IFERROR(I49/H49,0) | K49: 0 | L49: 0.02 | M49: 125 | N49: 0.17 | O49: =IFERROR((M49/MAX(1,'Mi negocio'!$C$26)+N49)/60*'Mi negocio'!$C$23,0) | P49: ='Mi negocio'!$C$20 | Q49: 24 | R49: =Q49*'Mi negocio'!$C$39 | S49: =IFERROR(ROUNDDOWN('Mi negocio'!$C$37*24/MAX(1,Q49),0),0) | T49: =J49+K49+L49+O49+P49+R49 | V49: =IF(U49="",'Mi negocio'!$C$24,U49) | W49: =IFERROR(T49/(1-V49),0) | X49: 25 | Y49: =W49*MAX(1,X49) | Z49: =IFERROR(CEILING(ROUND(W49*MAX(1,X49)/(1-'Mi negocio'!$C$27),6),'Mi negocio'!$C$25)/MAX(1,X49),0) | AA49: =IFERROR(CEILING(ROUND(W49*MAX(1,X49)/(1-'Mi negocio'!$C$28),6),'Mi negocio'!$C$25)/MAX(1,X49),0) | AB49: =IFERROR(CEILING(ROUND(W49*MAX(1,X49)/(1-'Mi negocio'!$C$29),6),'Mi negocio'!$C$25)/MAX(1,X49),0) | AC49: =IFERROR(CEILING(ROUND(W49*MAX(1,X49)/(1-'Mi negocio'!$C$30),6),'Mi negocio'!$C$25)/MAX(1,X49),0)
A50: 46 | B50: Cubo de Cóctel Negroni de Autor con Naranja Amarga (Smoked Negroni & Bitter Orange Cocktail Jelly) | C50: Bloque 5 · Gourmet de autor, coctelería, infusiones y funcionales | D50: 5 | E50: A | F50: 5 | G50: pieza | H50: 125 | I50: =SUMIF(Ingredientes!$A$5:$A$1063,A50,Ingredientes!$I$5:$I$1063) | J50: =IFERROR(I50/H50,0) | K50: 0 | L50: 0.02 | M50: 125 | N50: 0.17 | O50: =IFERROR((M50/MAX(1,'Mi negocio'!$C$26)+N50)/60*'Mi negocio'!$C$23,0) | P50: ='Mi negocio'!$C$20 | Q50: 30 | R50: =Q50*'Mi negocio'!$C$39 | S50: =IFERROR(ROUNDDOWN('Mi negocio'!$C$37*24/MAX(1,Q50),0),0) | T50: =J50+K50+L50+O50+P50+R50 | V50: =IF(U50="",'Mi negocio'!$C$24,U50) | W50: =IFERROR(T50/(1-V50),0) | X50: 25 | Y50: =W50*MAX(1,X50) | Z50: =IFERROR(CEILING(ROUND(W50*MAX(1,X50)/(1-'Mi negocio'!$C$27),6),'Mi negocio'!$C$25)/MAX(1,X50),0) | AA50: =IFERROR(CEILING(ROUND(W50*MAX(1,X50)/(1-'Mi negocio'!$C$28),6),'Mi negocio'!$C$25)/MAX(1,X50),0) | AB50: =IFERROR(CEILING(ROUND(W50*MAX(1,X50)/(1-'Mi negocio'!$C$29),6),'Mi negocio'!$C$25)/MAX(1,X50),0) | AC50: =IFERROR(CEILING(ROUND(W50*MAX(1,X50)/(1-'Mi negocio'!$C$30),6),'Mi negocio'!$C$25)/MAX(1,X50),0)
...

Sheet Producción
A1: Producción y merma
A2: Una fila por lote o tanda. La primera fila es un ejemplo: sobrescríbela.
A4: Fecha | B4: Lote | C4: Nº receta | D4: Receta | E4: Planeadas | F4: Buenas | G4: Falladas | H4: % merma | I4: Costo total unitario | J4: Costo de la merma | K4: Causa principal | L4: Notas
A5: 46298 | B5: L-2610-01 | C5: 1 | D5: =IF(C5="","",IFERROR(VLOOKUP(C5,'Recetas y precios'!$A$5:$B$54,2,FALSE),"")) | E5: 1200 | F5: 1080 | G5: 120 | H5: =IF((F5+G5)>0,G5/(F5+G5),"") | I5: =IF(C5="",0,IFERROR(VLOOKUP(C5,'Recetas y precios'!$A$5:$W$54,23,FALSE),0)) | J5: =G5*I5 | K5: Colada que no cuajó o quedó blanda | L5: Fila de ejemplo
D6: =IF(C6="","",IFERROR(VLOOKUP(C6,'Recetas y precios'!$A$5:$B$54,2,FALSE),"")) | H6: =IF((F6+G6)>0,G6/(F6+G6),"") | I6: =IF(C6="",0,IFERROR(VLOOKUP(C6,'Recetas y precios'!$A$5:$W$54,23,FALSE),0)) | J6: =G6*I6
