Workbook

Sheet LÉEME
A1: Anexo 1 · Sistema de Costeo de Dulcería
A2: Endulcora · Estudio Gastronómico, en colaboración con LEVENT — herramienta del eBook «Dulces Mexicanos Tradicionales: Del Jamoncillo al Cristalizado de Convento»
B4: CÓMO SE USA ESTE ARCHIVO
B5: 1. Insumos
B6: Escribe el PRECIO y la PRESENTACIÓN que TÚ compras, empezando por el costal de azúcar y la nuez. Los precios cargados son de referencia (mercado CDMX 2026), no cotizaciones.
B7: 2. Mi negocio
B8: Captura tus gastos fijos del mes, cuántas piezas produces, el sueldo que quieres cobrarte y tus horas de trabajo. De aquí salen el overhead por pieza y el costo de tu hora.
B9: 3. Bases madre
B10: Costo por lote y por pieza de las seis bases del Capítulo 3. Sirve para cotizar rápido cualquier dulce nuevo que crees tú.
B11: 4. Recetas y precios
B12: La hoja principal. Costo POR PIEZA de las 50 recetas y precio sugerido en cuatro canales. Ajusta empaque, energía, minutos y % de merma por receta.
B13: 5. Producción
B14: Registra cada lote: piezas buenas y falladas. Así conoces tu MERMA REAL de producción.
B15: 6. Ventas
... B21: Costo por gramo
B22: =Precio de compra ÷ Cantidad comprada
B23: Costo de insumos del lote
B24: =SUMA(cantidad × costo por gramo) de todas las líneas de la receta
B25: Costo de insumos por pieza
B26: =Costo del lote ÷ Piezas que rinde
B27: Costo base
B28: =Insumos/pieza + Empaque + Energía + Mano de obra + Overhead
B29: Costo total unitario
B30: =Costo base ÷ (1 − % merma) ← se DIVIDE, no se suma
B31: Precio de venta (PVP)
B32: =Costo total ÷ (1 − margen deseado)
B33: Utilidad por pieza
B34: =PVP − Costo total
B36: ADVERTENCIAS
B37: Los frutos secos son el insumo crítico
B38: La nuez, el piñón y la almendra pueden ser más del 50 % del costo de una receta y suben cada diciembre. Actualiza su precio cada compra.
B39: Cantidades «al gusto»
B40: Las líneas del recetario que dicen «para decorar» o «lo necesario» se cargaron con una cantidad razonable por lote. Ajústalas a tu ejecución real en la hoja Ingredientes.
B41: Empaque aparte
B42: El empaque NO se cuenta como ingrediente: se captura por pieza en la hoja «Recetas y precios». Los insumos de empaque están en el catálogo solo como referencia de precio.
B43: Las dos mermas
B44: Merma de producción (lotes fallados) y producto no vendido. Cuenta las dos o tu costeo miente.
B45: Alérgenos
B46: Este recetario contiene LECHE, FRUTOS SECOS, CACAHUATE, AJONJOLÍ, HUEVO, TRIGO y ALCOHOL según la receta. Decláralos siempre en la etiqueta.
B47: Uso
...

Sheet Insumos
A1: Insumos
A2: Paso 1 · Cambia PRECIO y PRESENTACIÓN por los de tus tickets reales. Empieza por el azúcar y la nuez.
A4: Categoría | B4: Insumo | C4: Unidad | D4: Presentación (cantidad que compras) | E4: Precio pagado (MXN) | F4: Costo por unidad | G4: Recetas que lo usan
A5: Azúcares | B5: Azúcar refinada | C5: g | D5: 1000 | E5: 25 | F5: =IFERROR(E5/D5,0) | G5: =COUNTIF(Ingredientes!$C:$C,B5)
A6: Azúcares | B6: Azúcar mascabado | C6: g | D6: 1000 | E6: 48 | F6: =IFERROR(E6/D6,0) | G6: =COUNTIF(Ingredientes!$C:$C,B6)
A7: Azúcares | B7: Piloncillo | C7: g | D7: 1000 | E7: 58 | F7: =IFERROR(E7/D7,0) | G7: =COUNTIF(Ingredientes!$C:$C,B7)
A8: Azúcares | B8: Glucosa / jarabe de maíz | C8: g | D8: 1000 | E8: 95 | F8: =IFERROR(E8/D8,0) | G8: =COUNTIF(Ingredientes!$C:$C,B8)
A9: Azúcares | B9: Miel de abeja | C9: ml | D9: 1000 | E9: 220 | F9: =IFERROR(E9/D9,0) | G9: =COUNTIF(Ingredientes!$C:$C,B9)
A10: Azúcares | B10: Miel de agave | C10: ml | D10: 1000 | E10: 140 | F10: =IFERROR(E10/D10,0) | G10: =COUNTIF(Ingredientes!$C:$C,B10)
A11: Azúcares | B11: Melaza de piloncillo | C11: ml | D11: 1000 | E11: 80 | F11: =IFERROR(E11/D11,0) | G11: =COUNTIF(Ingredientes!$C:$C,B11)
A12: Azúcares | B12: Jarabe de azúcar con piloncillo | C12: ml | D12: 1000 | E12: 60 | F12: =IFERROR(E12/D12,0) | G12: =COUNTIF(Ingredientes!$C:$C,B12)
A13: Lácteos | B13: Leche entera | C13: ml | D13: 1000 | E13: 28 | F13: =IFERROR(E13/D13,0) | G13: =COUNTIF(Ingredientes!$C:$C,B13)
A14: Lácteos | B14: Leche de cabra | C14: ml | D14: 1000 | E14: 55 | F14: =IFERROR(E14/D14,0) | G14: =COUNTIF(Ingredientes!$C:$C,B14)
A15: Lácteos | B15: Leche condensada | C15: g | D15: 387 | E15: 42 | F15: =IFERROR(E15/D15,0) | G15: =COUNTIF(Ingredientes!$C:$C,B15)
A16: Lácteos | B16: Leche en polvo entera | C16: g | D16: 1000 | E16: 220 | F16: =IFERROR(E16/D16,0) | G16: =COUNTIF(Ingredientes!$C:$C,B16)
... A81: Empaque | B81: Papel de ixtle / decorativo | C81: pza | D81: 50 | E81: 90 | F81: =IFERROR(E81/D81,0) | G81: =COUNTIF(Ingredientes!$C:$C,B81)

Sheet Bases madre
A1: Las seis bases madre
A2: Costo real de las fórmulas del Capítulo 3, con tus precios de insumos actuales.
A4: Base madre | B4: Insumo | C4: Cantidad | D4: Unidad | E4: Costo por unidad | F4: Costo
A5: B-1 · Leche quemada (base láctea) | B5: Leche entera | C5: 1000 | D5: ml | E5: =IFERROR(VLOOKUP(B5,Insumos!$B$5:$F$81,5,FALSE),0) | F5: =C5*E5
B6: Azúcar refinada | C6: 400 | D6: g | E6: =IFERROR(VLOOKUP(B6,Insumos!$B$5:$F$81,5,FALSE),0) | F6: =C6*E6
B7: Bicarbonato de sodio | C7: 1 | D7: g | E7: =IFERROR(VLOOKUP(B7,Insumos!$B$5:$F$81,5,FALSE),0) | F7: =C7*E7
B8: Esencia de vainilla | C8: 5 | D8: ml | E8: =IFERROR(VLOOKUP(B8,Insumos!$B$5:$F$81,5,FALSE),0) | F8: =C8*E8
B9: Costo del lote (520 g de pasta · rinde 20) | F9: =SUM(F5:F8)
A11: B-2 · Cajeta de cabra | B11: Leche de cabra | C11: 1000 | D11: ml | E11: =IFERROR(VLOOKUP(B11,Insumos!$B$5:$F$81,5,FALSE),0) | F11: =C11*E11
B12: Azúcar refinada | C12: 400 | D12: g | E12: =IFERROR(VLOOKUP(B12,Insumos!$B$5:$F$81,5,FALSE),0) | F12: =C12*E12
B13: Bicarbonato de sodio | C13: 1 | D13: g | E13: =IFERROR(VLOOKUP(B13,Insumos!$B$5:$F$81,5,FALSE),0) | F13: =C13*E13
B14: Canela en raja | C14: 3 | D14: g | E14: =IFERROR(VLOOKUP(B14,Insumos!$B$5:$F$81,5,FALSE),0) | F14: =C14*E14
B15: Costo del lote (500 ml · rinde 1) | F15: =SUM(F11:F14)
A17: B-3 · Miel de piloncillo especiada | B17: Piloncillo | C17: 500 | D17: g | E17: =IFERROR(VLOOKUP(B17,Insumos!$B$5:$F$81,5,FALSE),0) | F17: =C17*E17
B18: Agua purificada | C18: 500 | D18: ml | E18: =IFERROR(VLOOKUP(B18,Insumos!$B$5:$F$81,5,FALSE),0) | F18: =C18*E18
B19: Canela en raja | C19: 6 | D19: g | E19: =IFERROR(VLOOKUP(B19,Insumos!$B$5:$F$81,5,FALSE),0) | F19: =C19*E19
B20: Clavo de olor | C20: 1.5 | D20: g | E20: =IFERROR(VLOOKUP(B20,Insumos!$B$5:$F$81,5,FALSE),0) | F20: =C20*E20
B21: Anís estrella | C21: 2 | D21: g | E21: =IFERROR(VLOOKUP(B21,Insumos!$B$5:$F$81,5,FALSE),0) | F21: =C21*E21
B22: Costo del lote (700 ml de miel · rinde 8) | F22: =SUM(F17:F21)
A24: B-4 · Azúcar trabajada | B24: Azúcar refinada | C24: 400 | D24: g | E24: =IFERROR(VLOOKUP(B24,Insumos!$B$5:$F$81,5,FALSE),0) | F24: =C24*E24
B25: Agua purificada | C25: 100 | D25: ml | E25: =IFERROR(VLOOKUP(B25,Insumos!$B$5:$F$81,5,FALSE),0) | F25: =C25*E25
B26: Glucosa / jarabe de maíz | C26: 20 | D26: g | E26: =IFERROR(VLOOKUP(B26,Insumos!$B$5:$F$81,5,FALSE),0) | F26: =C26*E26
B27: Mantequilla sin sal | C27: 10 | D27: g | E27: =IFERROR(VLOOKUP(B27,Insumos!$B$5:$F$81,5,FALSE),0) | F27: =C27*E27
B28: Costo del lote (480 g de caramelo · liga 500 g de semilla · rinde 12) | F28: =SUM(F24:F27)
A30: B-5 · Jarabe de cristalizado | B30: Azúcar refinada | C30: 1000 | D30: g | E30: =IFERROR(VLOOKUP(B30,Insumos!$B$5:$F$81,5,FALSE),0) | F30: =C30*E30
B31: Agua purificada | C31: 1000 | D31: ml | E31: =IFERROR(VLOOKUP(B31,Insumos!$B$5:$F$81,5,FALSE),0) | F31: =C31*E31
B32: Cal viva (grado alimenticio) | C32: 10 | D32: g | E32: =IFERROR(VLOOKUP(B32,Insumos!$B$5:$F$81,5,FALSE),0) | F32: =C32*E32
B33: Limón | C33: 40 | D33: g | E33: =IFERROR(VLOOKUP(B33,Insumos!$B$5:$F$81,5,FALSE),0) | F33: =C33*E33
B34: Costo del lote (1.6 L de jarabe · confita 1 kg · rinde 12) | F34: =SUM(F30:F33)
A36: B-6 · Pasta de fruta y enchilado | B36: Pulpa de tamarindo | C36: 500 | D36: g | E36: =IFERROR(VLOOKUP(B36,Insumos!$B$5:$F$81,5,FALSE),0) | F36: =C36*E36
B37: Azúcar refinada | C37: 400 | D37: g | E37: =IFERROR(VLOOKUP(B37,Insumos!$B$5:$F$81,5,FALSE),0) | F37: =C37*E37
B38: Glucosa / jarabe de maíz | C38: 20 | D38: g | E38: =IFERROR(VLOOKUP(B38,Insumos!$B$5:$F$81,5,FALSE),0) | F38: =C38*E38
B39: Limón | C39: 15 | D39: g | E39: =IFERROR(VLOOKUP(B39,Insumos!$B$5:$F$81,5,FALSE),0) | F39: =C39*E39
B40: Chile piquín en polvo | C40: 20 | D40: g | E40: =IFERROR(VLOOKUP(B40,Insumos!$B$5:$F$81,5,FALSE),0) | F40: =C40*E40
B41: Sal fina | C41: 2 | D41: g | E41: =IFERROR(VLOOKUP(B41,Insumos!$B$5:$F$81,5,FALSE),0) | F41: =C41*E41
B42: Costo del lote (700 g de pasta · rinde 25) | F42: =SUM(F36:F41)
A44: RESUMEN · costo por base madre
A45: Base madre | B45: Uso | C45: Rendimiento | D45: Piezas | E45: Costo del lote | F45: Costo por pieza
A46: B-1 · Leche quemada (base láctea) | B46: Jamoncillos, pastillas, cocadas, mostachones y borrachitos | C46: 520 g de pasta | D46: 20 | E46: =SUM(F5:F8) | F46: =IFERROR(E46/D46,0)
A47: B-2 · Cajeta de cabra | B47: Cajeta, glorias y relleno de otras recetas | C47: 500 ml | D47: 1 | E47: =SUM(F11:F14) | F47: =IFERROR(E47/D47,0)
...

Sheet Ingredientes
A1: Ingredientes de las 50 recetas
A2: Cada línea del recetario, normalizada al catálogo de insumos. Las cantidades son para el LOTE completo.
A4: # | B4: Receta | C4: Insumo | D4: Cantidad | E4: Unidad | F4: Costo por unidad | G4: Costo | H4: Texto original del recetario
A5: 1 | B5: Jamoncillo de Leche (Dulce de Leche Cortada) | C5: Leche entera | D5: 1000 | E5: ml | F5: =IFERROR(VLOOKUP(C5,Insumos!$B$5:$F$81,5,FALSE),0) | G5: =D5*F5 | H5: 1 litro de leche entera
A6: 1 | B6: Jamoncillo de Leche (Dulce de Leche Cortada) | C6: Azúcar refinada | D6: 500 | E6: g | F6: =IFERROR(VLOOKUP(C6,Insumos!$B$5:$F$81,5,FALSE),0) | G6: =D6*F6 | H6: 500 g de azúcar blanca
A7: 1 | B7: Jamoncillo de Leche (Dulce de Leche Cortada) | C7: Bicarbonato de sodio | D7: 1 | E7: g | F7: =IFERROR(VLOOKUP(C7,Insumos!$B$5:$F$81,5,FALSE),0) | G7: =D7*F7 | H7: 1 pizca de bicarbonato de sodio
A8: 1 | B8: Jamoncillo de Leche (Dulce de Leche Cortada) | C8: Esencia de vainilla | D8: 5 | E8: ml | F8: =IFERROR(VLOOKUP(C8,Insumos!$B$5:$F$81,5,FALSE),0) | G8: =D8*F8 | H8: 1 cucharadita de esencia de vainilla
A9: 1 | B9: Jamoncillo de Leche (Dulce de Leche Cortada) | C9: Nuez de Castilla | D9: 60 | E9: g | F9: =IFERROR(VLOOKUP(C9,Insumos!$B$5:$F$81,5,FALSE),0) | G9: =D9*F9 | H9: Nueces en mitades para decorar
A10: 2 | B10: Glorias de Linares (Nuevo León) | C10: Leche de cabra | D10: 1000 | E10: ml | F10: =IFERROR(VLOOKUP(C10,Insumos!$B$5:$F$81,5,FALSE),0) | G10: =D10*F10 | H10: 1 litro de leche de cabra (o entera)
A11: 2 | B11: Glorias de Linares (Nuevo León) | C11: Azúcar refinada | D11: 500 | E11: g | F11: =IFERROR(VLOOKUP(C11,Insumos!$B$5:$F$81,5,FALSE),0) | G11: =D11*F11 | H11: 500 g de azúcar
A12: 2 | B12: Glorias de Linares (Nuevo León) | C12: Glucosa / jarabe de maíz | D12: 20.62 | E12: g | F12: =IFERROR(VLOOKUP(C12,Insumos!$B$5:$F$81,5,FALSE),0) | G12: =D12*F12 | H12: 1 cucharada de glucosa
A13: 2 | B13: Glorias de Linares (Nuevo León) | C13: Nuez de Castilla | D13: 115 | E13: g | F13: =IFERROR(VLOOKUP(C13,Insumos!$B$5:$F$81,5,FALSE),0) | G13: =D13*F13 | H13: 1 taza de trozos de nuez de Castilla
A14: 3 | B14: Cajeta Casera Quemada de Celaya | C14: Leche de cabra | D14: 1500 | E14: ml | F14: =IFERROR(VLOOKUP(C14,Insumos!$B$5:$F$81,5,FALSE),0) | G14: =D14*F14 | H14: 1.5 litros de leche de cabra fresca
A15: 3 | B15: Cajeta Casera Quemada de Celaya | C15: Azúcar refinada | D15: 600 | E15: g | F15: =IFERROR(VLOOKUP(C15,Insumos!$B$5:$F$81,5,FALSE),0) | G15: =D15*F15 | H15: 600 g de azúcar estándar
A16: 3 | B16: Cajeta Casera Quemada de Celaya | C16: Bicarbonato de sodio | D16: 0.78 | E16: g | F16: =IFERROR(VLOOKUP(C16,Insumos!$B$5:$F$81,5,FALSE),0) | G16: =D16*F16 | H16: 1/4 cucharadita de bicarbonato de sodio disuelto en 2 cucharadas de agua
... A197: 50 | B197: Bolitas de Tamarindo con Ajonjolí Tostado | C197: Ajonjolí | D197: 145 | E197: g | F197: =IFERROR(VLOOKUP(C197,Insumos!$B$5:$F$81,5,FALSE),0) | G197: =D197*F197 | H197: 1 taza de semillas de ajonjolí tostadas

Sheet Mi negocio
A1: Mi negocio
A2: Los supuestos que mueven todos los precios. Si estos números están mal, todos tus precios están mal.
B4: GASTOS FIJOS MENSUALES | E4: TRABAJO Y VOLUMEN
B5: Renta del local / espacio de producción | C5: 5000 | E5: Piezas que produces al mes | F5: 8000
B6: Gas de la hornilla | C6: 1500 | E6: Sueldo mensual que quieres cobrarte | F6: 15000
B7: Luz y agua | C7: 900 | E7: Horas de trabajo al mes | F7: 200
B8: Internet y telefonía | C8: 500 | E8: % de merma de producción por defecto | F8: 0.08
B9: Publicidad y redes | C9: 700
B10: Papelería, limpieza y consumibles | C10: 400 | E10: Overhead por pieza | F10: =IFERROR($C$15/$F$5,0)
B11: Transporte y repartos | C11: 800 | E11: Costo de tu hora de trabajo | F11: =IFERROR($F$6/$F$7,0)
B12: Depreciación de cazo, moldes y equipo | C12: 600
B13: Sueldos fijos de terceros | C13: 1200 | E13: MÁRGENES OBJETIVO POR CANAL
B14: Otros gastos fijos | C14: 400 | E14: Mostrador y tianguis | F14: 0.55 | G14: libro: 50 % – 65 %
B15: TOTAL DE GASTOS FIJOS | C15: =SUM(C5:C14) | E15: Caja o bolsa de regalo | F15: 0.72 | G15: libro: 65 % – 78 %
E16: Restaurante / petit four | F16: 0.8 | G16: libro: 75 % – 88 %
E17: Mayoreo a dulcerías | F17: 0.32 | G17: libro: 25 % – 40 %

Sheet Recetas y precios
A1: Recetas y precios
A2: La hoja principal. Costos POR PIEZA. Ajusta empaque, energía, minutos y merma por receta.
A4: # | B4: Receta | C4: Capítulo | D4: Base madre | E4: Punto de azúcar | F4: Piezas que rinde | G4: Costo insumos del lote | H4: Costo insumos / pieza | I4: Empaque | J4: Energía | K4: Min. de trabajo | L4: Mano de obra | M4: Overhead | N4: Costo base | O4: % merma | P4: COSTO TOTAL / PIEZA | Q4: PVP mostrador | R4: PVP caja de regalo | S4: PVP restaurante | T4: PVP mayoreo | U4: Utilidad mostrador
A5: 1 | B5: Jamoncillo de Leche (Dulce de Leche Cortada) | C5: Cap. 6 · Leche y cajeta | D5: B-1 · Leche quemada (base láctea) | E5: Bola suave · 112–116 °C | F5: 20 | G5: =SUMIF(Ingredientes!$A:$A,A5,Ingredientes!$G:$G) | H5: =IFERROR(G5/F5,0) | I5: 0.6 | J5: 0.45 | K5: 1 | L5: =K5/60*'Mi negocio'!$F$11 | M5: ='Mi negocio'!$F$10 | N5: =H5+I5+J5+L5+M5 | O5: ='Mi negocio'!$F$8 | P5: =IFERROR(N5/(1-O5),0) | Q5: =IFERROR(CEILING(P5/(1-'Mi negocio'!$F$14),1),0) | R5: =IFERROR(CEILING(P5/(1-'Mi negocio'!$F$15),1),0) | S5: =IFERROR(CEILING(P5/(1-'Mi negocio'!$F$16),1),0) | T5: =IFERROR(CEILING(P5/(1-'Mi negocio'!$F$17),1),0) | U5: =Q5-P5
A6: 2 | B6: Glorias de Linares (Nuevo León) | C6: Cap. 6 · Leche y cajeta | D6: B-2 · Cajeta de cabra | E6: Bola suave · 112–116 °C | F6: 25 | G6: =SUMIF(Ingredientes!$A:$A,A6,Ingredientes!$G:$G) | H6: =IFERROR(G6/F6,0) | I6: 0.6 | J6: 0.45 | K6: 1 | L6: =K6/60*'Mi negocio'!$F$11 | M6: ='Mi negocio'!$F$10 | N6: =H6+I6+J6+L6+M6 | O6: ='Mi negocio'!$F$8 | P6: =IFERROR(N6/(1-O6),0) | Q6: =IFERROR(CEILING(P6/(1-'Mi negocio'!$F$14),1),0) | R6: =IFERROR(CEILING(P6/(1-'Mi negocio'!$F$15),1),0) | S6: =IFERROR(CEILING(P6/(1-'Mi negocio'!$F$16),1),0) | T6: =IFERROR(CEILING(P6/(1-'Mi negocio'!$F$17),1),0) | U6: =Q6-P6
A7: 3 | B7: Cajeta Casera Quemada de Celaya | C7: Cap. 6 · Leche y cajeta | D7: B-2 · Cajeta de cabra | E7: Hebra · 103–105 °C | F7: 1 | G7: =SUMIF(Ingredientes!$A:$A,A7,Ingredientes!$G:$G) | H7: =IFERROR(G7/F7,0) | I7: 0.6 | J7: 0.45 | K7: 1.8 | L7: =K7/60*'Mi negocio'!$F$11 | M7: ='Mi negocio'!$F$10 | N7: =H7+I7+J7+L7+M7 | O7: ='Mi negocio'!$F$8 | P7: =IFERROR(N7/(1-O7),0) | Q7: =IFERROR(CEILING(P7/(1-'Mi negocio'!$F$14),1),0) | R7: =IFERROR(CEILING(P7/(1-'Mi negocio'!$F$15),1),0) | S7: =IFERROR(CEILING(P7/(1-'Mi negocio'!$F$16),1),0) | T7: =IFERROR(CEILING(P7/(1-'Mi negocio'!$F$17),1),0) | U7: =Q7-P7
A8: 4 | B8: Borrachitos poblanos con rompope | C8: Cap. 6 · Leche y cajeta | D8: B-1 · Leche quemada (base láctea) | E8: Hebra · 103–105 °C | F8: 30 | G8: =SUMIF(Ingredientes!$A:$A,A8,Ingredientes!$G:$G) | H8: =IFERROR(G8/F8,0) | I8: 0.6 | J8: 0.45 | K8: 1 | L8: =K8/60*'Mi negocio'!$F$11 | M8: ='Mi negocio'!$F$10 | N8: =H8+I8+J8+L8+M8 | O8: ='Mi negocio'!$F$8 | P8: =IFERROR(N8/(1-O8),0) | Q8: =IFERROR(CEILING(P8/(1-'Mi negocio'!$F$14),1),0) | R8: =IFERROR(CEILING(P8/(1-'Mi negocio'!$F$15),1),0) | S8: =IFERROR(CEILING(P8/(1-'Mi negocio'!$F$16),1),0) | T8: =IFERROR(CEILING(P8/(1-'Mi negocio'!$F$17),1),0) | U8: =Q8-P8
A9: 5 | B9: Queso de Pera (Dulce de Leche moldeado) | C9: Cap. 6 · Leche y cajeta | D9: B-1 · Leche quemada (base láctea) | E9: Bola dura · 121–130 °C | F9: 12 | G9: =SUMIF(Ingredientes!$A:$A,A9,Ingredientes!$G:$G) | H9: =IFERROR(G9/F9,0) | I9: 0.6 | J9: 0.45 | K9: 1 | L9: =K9/60*'Mi negocio'!$F$11 | M9: ='Mi negocio'!$F$10 | N9: =H9+I9+J9+L9+M9 | O9: ='Mi negocio'!$F$8 | P9: =IFERROR(N9/(1-O9),0) | Q9: =IFERROR(CEILING(P9/(1-'Mi negocio'!$F$14),1),0) | R9: =IFERROR(CEILING(P9/(1-'Mi negocio'!$F$15),1),0) | S9: =IFERROR(CEILING(P9/(1-'Mi negocio'!$F$16),1),0) | T9: =IFERROR(CEILING(P9/(1-'Mi negocio'!$F$17),1),0) | U9: =Q9-P9
A10: 6 | B10: Jamoncillo de Piñón | C10: Cap. 6 · Leche y cajeta | D10: B-1 · Leche quemada (base láctea) | E10: Sin punto de azúcar | F10: 15 | G10: =SUMIF(Ingredientes!$A:$A,A10,Ingredientes!$G:$G) | H10: =IFERROR(G10/F10,0) | I10: 0.6 | J10: 0.45 | K10: 0.7 | L10: =K10/60*'Mi negocio'!$F$11 | M10: ='Mi negocio'!$F$10 | N10: =H10+I10+J10+L10+M10 | O10: ='Mi negocio'!$F$8 | P10: =IFERROR(N10/(1-O10),0) | Q10: =IFERROR(CEILING(P10/(1-'Mi negocio'!$F$14),1),0) | R10: =IFERROR(CEILING(P10/(1-'Mi negocio'!$F$15),1),0) | S10: =IFERROR(CEILING(P10/(1-'Mi negocio'!$F$16),1),0) | T10: =IFERROR(CEILING(P10/(1-'Mi negocio'!$F$17),1),0) | U10: =Q10-P10
A11: 7 | B11: Cajeta Envinada con Nuez | C11: Cap. 6 · Leche y cajeta | D11: B-2 · Cajeta de cabra | E11: Hebra · 103–105 °C | F11: 4 | G11: =SUMIF(Ingredientes!$A:$A,A11,Ingredientes!$G:$G) | H11: =IFERROR(G11/F11,0) | I11: 0.6 | J11: 0.45 | K11: 1.8 | L11: =K11/60*'Mi negocio'!$F$11 | M11: ='Mi negocio'!$F$10 | N11: =H11+I11+J11+L11+M11 | O11: ='Mi negocio'!$F$8 | P11: =IFERROR(N11/(1-O11),0) | Q11: =IFERROR(CEILING(P11/(1-'Mi negocio'!$F$14),1),0) | R11: =IFERROR(CEILING(P11/(1-'Mi negocio'!$F$15),1),0) | S11: =IFERROR(CEILING(P11/(1-'Mi negocio'!$F$16),1),0) | T11: =IFERROR(CEILING(P11/(1-'Mi negocio'!$F$17),1),0) | U11: =Q11-P11
A12: 8 | B12: Dulce de Jamoncillo Tapado con Nueces | C12: Cap. 6 · Leche y cajeta | D12: B-1 · Leche quemada (base láctea) | E12: Bola suave · 112–116 °C | F12: 16 | G12: =SUMIF(Ingredientes!$A:$A,A12,Ingredientes!$G:$G) | H12: =IFERROR(G12/F12,0) | I12: 0.6 | J12: 0.45 | K12: 0.7 | L12: =K12/60*'Mi negocio'!$F$11 | M12: ='Mi negocio'!$F$10 | N12: =H12+I12+J12+L12+M12 | O12: ='Mi negocio'!$F$8 | P12: =IFERROR(N12/(1-O12),0) | Q12: =IFERROR(CEILING(P12/(1-'Mi negocio'!$F$14),1),0) | R12: =IFERROR(CEILING(P12/(1-'Mi negocio'!$F$15),1),0) | S12: =IFERROR(CEILING(P12/(1-'Mi negocio'!$F$16),1),0) | T12: =IFERROR(CEILING(P12/(1-'Mi negocio'!$F$17),1),0) | U12: =Q12-P12
A13: 9 | B13: Mostachones de Leche Condensada | C13: Cap. 6 · Leche y cajeta | D13: B-1 · Leche quemada (base láctea) | E13: Sin punto de azúcar | F13: 20 | G13: =SUMIF(Ingredientes!$A:$A,A13,Ingredientes!$G:$G) | H13: =IFERROR(G13/F13,0) | I13: 0.6 | J13: 0.45 | K13: 0.7 | L13: =K13/60*'Mi negocio'!$F$11 | M13: ='Mi negocio'!$F$10 | N13: =H13+I13+J13+L13+M13 | O13: ='Mi negocio'!$F$8 | P13: =IFERROR(N13/(1-O13),0) | Q13: =IFERROR(CEILING(P13/(1-'Mi negocio'!$F$14),1),0) | R13: =IFERROR(CEILING(P13/(1-'Mi negocio'!$F$15),1),0) | S13: =IFERROR(CEILING(P13/(1-'Mi negocio'!$F$16),1),0) | T13: =IFERROR(CEILING(P13/(1-'Mi negocio'!$F$17),1),0) | U13: =Q13-P13
A14: 10 | B14: Pastillas de Leche Quemada Tradicionales | C14: Cap. 6 · Leche y cajeta | D14: B-1 · Leche quemada (base láctea) | E14: Bola dura · 121–130 °C | F14: 30 | G14: =SUMIF(Ingredientes!$A:$A,A14,Ingredientes!$G:$G) | H14: =IFERROR(G14/F14,0) | I14: 0.6 | J14: 0.45 | K14: 1 | L14: =K14/60*'Mi negocio'!$F$11 | M14: ='Mi negocio'!$F$10 | N14: =H14+I14+J14+L14+M14 | O14: ='Mi negocio'!$F$8 | P14: =IFERROR(N14/(1-O14),0) | Q14: =IFERROR(CEILING(P14/(1-'Mi negocio'!$F$14),1),0) | R14: =IFERROR(CEILING(P14/(1-'Mi negocio'!$F$15),1),0) | S14: =IFERROR(CEILING(P14/(1-'Mi negocio'!$F$16),1),0) | T14: =IFERROR(CEILING(P14/(1-'Mi negocio'!$F$17),1),0) | U14: =Q14-P14
A15: 11 | B15: Cocadas Horneadas Doraditas | C15: Cap. 7 · Coco y fruta | D15: B-1 · Leche quemada (base láctea) | E15: Sin punto de azúcar | F15: 15 | G15: =SUMIF(Ingredientes!$A:$A,A15,Ingredientes!$G:$G) | H15: =IFERROR(G15/F15,0) | I15: 0.6 | J15: 0.45 | K15: 0.7 | L15: =K15/60*'Mi negocio'!$F$11 | M15: ='Mi negocio'!$F$10 | N15: =H15+I15+J15+L15+M15 | O15: ='Mi negocio'!$F$8 | P15: =IFERROR(N15/(1-O15),0) | Q15: =IFERROR(CEILING(P15/(1-'Mi negocio'!$F$14),1),0) | R15: =IFERROR(CEILING(P15/(1-'Mi negocio'!$F$15),1),0) | S15: =IFERROR(CEILING(P15/(1-'Mi negocio'!$F$16),1),0) | T15: =IFERROR(CEILING(P15/(1-'Mi negocio'!$F$17),1),0) | U15: =Q15-P15
A16: 12 | B16: Jamoncillo de Coco con Piña | C16: Cap. 7 · Coco y fruta | D16: B-1 · Leche quemada (base láctea) | E16: Bola suave · 112–116 °C | F16: 20 | G16: =SUMIF(Ingredientes!$A:$A,A16,Ingredientes!$G:$G) | H16: =IFERROR(G16/F16,0) | I16: 0.6 | J16: 0.45 | K16: 1 | L16: =K16/60*'Mi negocio'!$F$11 | M16: ='Mi negocio'!$F$10 | N16: =H16+I16+J16+L16+M16 | O16: ='Mi negocio'!$F$8 | P16: =IFERROR(N16/(1-O16),0) | Q16: =IFERROR(CEILING(P16/(1-'Mi negocio'!$F$14),1),0) | R16: =IFERROR(CEILING(P16/(1-'Mi negocio'!$F$15),1),0) | S16: =IFERROR(CEILING(P16/(1-'Mi negocio'!$F$16),1),0) | T16: =IFERROR(CEILING(P16/(1-'Mi negocio'!$F$17),1),0) | U16: =Q16-P16
... A54: 50 | B54: Bolitas de Tamarindo con Ajonjolí Tostado | C54: Cap. 10 · Confitería y tradición | D54: B-6 · Pasta de fruta y enchilado | E54: Bola suave · 112–116 °C | F54: 25 | G54: =SUMIF(Ingredientes!$A:$A,A54,Ingredientes!$G:$G) | H54: =IFERROR(G54/F54,0) | I54: 0.6 | J54: 0.45 | K54: 0.7 | L54: =K54/60*'Mi negocio'!$F$11 | M54: ='Mi negocio'!$F$10 | N54: =H54+I54+J54+L54+M54 | O54: ='Mi negocio'!$F$8 | P54: =IFERROR(N54/(1-O54),0) | Q54: =IFERROR(CEILING(P54/(1-'Mi negocio'!$F$14),1),0) | R54: =IFERROR(CEILING(P54/(1-'Mi negocio'!$F$15),1),0) | S54: =IFERROR(CEILING(P54/(1-'Mi negocio'!$F$16),1),0) | T54: =IFERROR(CEILING(P54/(1-'Mi negocio'!$F$17),1),0) | U54: =Q54-P54
B56: PROMEDIOS DEL RECETARIO
B57: Costo total promedio por pieza | C57: =AVERAGE(P5:P54)
B58: PVP promedio de mostrador | C58: =AVERAGE(Q5:Q54)
B59: Utilidad promedio por pieza | C59: =AVERAGE(U5:U54)
B60: Receta más cara | C60: =INDEX(B5:B54,MATCH(MAX(P5:P54),P5:P54,0))
B61: Receta más barata | C61: =INDEX(B5:B54,MATCH(MIN(P5:P54),P5:P54,0))

Sheet Producción
A1: Bitácora de producción y merma
A2: Anota cada lote. Aquí descubres tu MERMA REAL de producción: si es distinta a la que supones, tus precios están mal.
A4: Fecha | B4: Lote | C4: # receta | D4: Receta | E4: Punto alcanzado (°C) | F4: Planeadas | G4: Buenas | H4: Falladas | I4: % merma real | J4: Costo perdido | K4: Causa principal | L4: Notas
D5: =IFERROR(VLOOKUP(C5,'Recetas y precios'!$A$5:$B$54,2,FALSE),"") | I5: =IFERROR(H5/(G5+H5),"") | J5: =IFERROR(H5*VLOOKUP(C5,'Recetas y precios'!$A$5:$P$54,16,FALSE),"")
D6: =IFERROR(VLOOKUP(C6,'Recetas y precios'!$A$5:$B$54,2,FALSE),"") | I6: =IFERROR(H6/(G6+H6),"") | J6: =IFERROR(H6*VLOOKUP(C6,'Recetas y precios'!$A$5:$P$54,16,FALSE),"")
D7: =IFERROR(VLOOKUP(C7,'Recetas y precios'!$A$5:$B$54,2,FALSE),"") | I7: =IFERROR(H7/(G7+H7),"") | J7: =IFERROR(H7*VLOOKUP(C7,'Recetas y precios'!$A$5:$P$54,16,FALSE),"")
D8: =IFERROR(VLOOKUP(C8,'Recetas y precios'!$A$5:$B$54,2,FALSE),"") | I8: =IFERROR(H8/(G8+H8),"") | J8: =IFERROR(H8*VLOOKUP(C8,'Recetas y precios'!$A$5:$P$54,16,FALSE),"")
D9: =IFERROR(VLOOKUP(C9,'Recetas y precios'!$A$5:$B$54,2,FALSE),"") | I9: =IFERROR(H9/(G9+H9),"") | J9: =IFERROR(H9*VLOOKUP(C9,'Recetas y precios'!$A$5:$P$54,16,FALSE),"")
D10: =IFERROR(VLOOKUP(C10,'Recetas y precios'!$A$5:$B$54,2,FALSE),"") | I10: =IFERROR(H10/(G10+H10),"") | J10: =IFERROR(H10*VLOOKUP(C10,'Recetas y precios'!$A$5:$P$54,16,FALSE),"")
D11: =IFERROR(VLOOKUP(C11,'Recetas y precios'!$A$5:$B$54,2,FALSE),"") | I11: =IFERROR(H11/(G11+H11),"") | J11: =IFERROR(H11*VLOOKUP(C11,'Recetas y precios'!$A$5:$P$54,16,FALSE),"")
D12: =IFERROR(VLOOKUP(C12,'Recetas y precios'!$A$5:$B$54,2,FALSE),"") | I12: =IFERROR(H12/(G12+H12),"") | J12: =IFERROR(H12*VLOOKUP(C12,'Recetas y precios'!$A$5:$P$54,16,FALSE),"")
D13: =IFERROR(VLOOKUP(C13,'Recetas y precios'!$A$5:$B$54,2,FALSE),"") | I13: =IFERROR(H13/(G13+H13),"") | J13: =IFERROR(H13*VLOOKUP(C13,'Recetas y precios'!$A$5:$P$54,16,FALSE),"")
D14: =IFERROR(VLOOKUP(C14,'Recetas y precios'!$A$5:$B$54,2,FALSE),"") | I14: =IFERROR(H14/(G14+H14),"") | J14: =IFERROR(H14*VLOOKUP(C14,'Recetas y precios'!$A$5:$P$54,16,FALSE),"")
D15: =IFERROR(VLOOKUP(C15,'Recetas y precios'!$A$5:$B$54,2,FALSE),"") | I15: =IFERROR(H15/(G15+H15),"") | J15: =IFERROR(H15*VLOOKUP(C15,'Recetas y precios'!$A$5:$P$54,16,FALSE),"")
D16: =IFERROR(VLOOKUP(C16,'Recetas y precios'!$A$5:$B$54,2,FALSE),"") | I16: =IFERROR(H16/(G16+H16),"") | J16: =IFERROR(H16*VLOOKUP(C16,'Recetas y precios'!$A$5:$P$54,16,FALSE),"")
... D304: =IFERROR(VLOOKUP(C304,'Recetas y precios'!$A$5:$B$54,2,FALSE),"") | I304: =IFERROR(H304/(G304+H304),"") | J304: =IFERROR(H304*VLOOKUP(C304,'Recetas y precios'!$A$5:$P$54,16,FALSE),"")

Sheet Ventas
A1: Bitácora de ventas y producto no vendido
A2: Una línea por venta o por jornada. El producto no vendido no se tira en dulcería, pero sí inmoviliza tu dinero: regístralo.
A4: Fecha | B4: # receta | C4: Receta | D4: Canal | E4: Piezas vendidas | F4: Precio unitario | G4: Ingreso | H4: Costo de lo vendido | I4: Piezas no vendidas | J4: Costo del no vendido | K4: Utilidad neta | L4: Margen | M4: Cliente o nota
C5: =IFERROR(VLOOKUP(B5,'Recetas y precios'!$A$5:$B$54,2,FALSE),"") | G5: =IFERROR(E5*F5,"") | H5: =IFERROR(E5*VLOOKUP(B5,'Recetas y precios'!$A$5:$P$54,16,FALSE),"") | J5: =IFERROR(I5*VLOOKUP(B5,'Recetas y precios'!$A$5:$P$54,16,FALSE),"") | K5: =IFERROR(G5-H5,"") | L5: =IFERROR(K5/G5,"")
C6: =IFERROR(VLOOKUP(B6,'Recetas y precios'!$A$5:$B$54,2,FALSE),"") | G6: =IFERROR(E6*F6,"") | H6: =IFERROR(E6*VLOOKUP(B6,'Recetas y precios'!$A$5:$P$54,16,FALSE),"") | J6: =IFERROR(I6*VLOOKUP(B6,'Recetas y precios'!$A$5:$P$54,16,FALSE),"") | K6: =IFERROR(G6-H6,"") | L6: =IFERROR(K6/G6,"")
C7: =IFERROR(VLOOKUP(B7,'Recetas y precios'!$A$5:$B$54,2,FALSE),"") | G7: =IFERROR(E7*F7,"") | H7: =IFERROR(E7*VLOOKUP(B7,'Recetas y precios'!$A$5:$P$54,16,FALSE),"") | J7: =IFERROR(I7*VLOOKUP(B7,'Recetas y precios'!$A$5:$P$54,16,FALSE),"") | K7: =IFERROR(G7-H7,"") | L7: =IFERROR(K7/G7,"")
C8: =IFERROR(VLOOKUP(B8,'Recetas y precios'!$A$5:$B$54,2,FALSE),"") | G8: =IFERROR(E8*F8,"") | H8: =IFERROR(E8*VLOOKUP(B8,'Recetas y precios'!$A$5:$P$54,16,FALSE),"") | J8: =IFERROR(I8*VLOOKUP(B8,'Recetas y precios'!$A$5:$P$54,16,FALSE),"") | K8: =IFERROR(G8-H8,"") | L8: =IFERROR(K8/G8,"")
C9: =IFERROR(VLOOKUP(B9,'Recetas y precios'!$A$5:$B$54,2,FALSE),"") | G9: =IFERROR(E9*F9,"") | H9: =IFERROR(E9*VLOOKUP(B9,'Recetas y precios'!$A$5:$P$54,16,FALSE),"") | J9: =IFERROR(I9*VLOOKUP(B9,'Recetas y precios'!$A$5:$P$54,16,FALSE),"") | K9: =IFERROR(G9-H9,"") | L9: =IFERROR(K9/G9,"")
C10: =IFERROR(VLOOKUP(B10,'Recetas y precios'!$A$5:$B$54,2,FALSE),"") | G10: =IFERROR(E10*F10,"") | H10: =IFERROR(E10*VLOOKUP(B10,'Recetas y precios'!$A$5:$P$54,16,FALSE),"") | J10: =IFERROR(I10*VLOOKUP(B10,'Recetas y precios'!$A$5:$P$54,16,FALSE),"") | K10: =IFERROR(G10-H10,"") | L10: =IFERROR(K10/G10,"")
C11: =IFERROR(VLOOKUP(B11,'Recetas y precios'!$A$5:$B$54,2,FALSE),"") | G11: =IFERROR(E11*F11,"") | H11: =IFERROR(E11*VLOOKUP(B11,'Recetas y precios'!$A$5:$P$54,16,FALSE),"") | J11: =IFERROR(I11*VLOOKUP(B11,'Recetas y precios'!$A$5:$P$54,16,FALSE),"") | K11: =IFERROR(G11-H11,"") | L11: =IFERROR(K11/G11,"")
C12: =IFERROR(VLOOKUP(B12,'Recetas y precios'!$A$5:$B$54,2,FALSE),"") | G12: =IFERROR(E12*F12,"") | H12: =IFERROR(E12*VLOOKUP(B12,'Recetas y precios'!$A$5:$P$54,16,FALSE),"") | J12: =IFERROR(I12*VLOOKUP(B12,'Recetas y precios'!$A$5:$P$54,16,FALSE),"") | K12: =IFERROR(G12-H12,"") | L12: =IFERROR(K12/G12,"")
C13: =IFERROR(VLOOKUP(B13,'Recetas y precios'!$A$5:$B$54,2,FALSE),"") | G13: =IFERROR(E13*F13,"") | H13: =IFERROR(E13*VLOOKUP(B13,'Recetas y precios'!$A$5:$P$54,16,FALSE),"") | J13: =IFERROR(I13*VLOOKUP(B13,'Recetas y precios'!$A$5:$P$54,16,FALSE),"") | K13: =IFERROR(G13-H13,"") | L13: =IFERROR(K13/G13,"")
C14: =IFERROR(VLOOKUP(B14,'Recetas y precios'!$A$5:$B$54,2,FALSE),"") | G14: =IFERROR(E14*F14,"") | H14: =IFERROR(E14*VLOOKUP(B14,'Recetas y precios'!$A$5:$P$54,16,FALSE),"") | J14: =IFERROR(I14*VLOOKUP(B14,'Recetas y precios'!$A$5:$P$54,16,FALSE),"") | K14: =IFERROR(G14-H14,"") | L14: =IFERROR(K14/G14,"")
C15: =IFERROR(VLOOKUP(B15,'Recetas y precios'!$A$5:$B$54,2,FALSE),"") | G15: =IFERROR(E15*F15,"") | H15: =IFERROR(E15*VLOOKUP(B15,'Recetas y precios'!$A$5:$P$54,16,FALSE),"") | J15: =IFERROR(I15*VLOOKUP(B15,'Recetas y precios'!$A$5:$P$54,16,FALSE),"") | K15: =IFERROR(G15-H15,"") | L15: =IFERROR(K15/G15,"")
C16: =IFERROR(VLOOKUP(B16,'Recetas y precios'!$A$5:$B$54,2,FALSE),"") | G16: =IFERROR(E16*F16,"") | H16: =IFERROR(E16*VLOOKUP(B16,'Recetas y precios'!$A$5:$P$54,16,FALSE),"") | J16: =IFERROR(I16*VLOOKUP(B16,'Recetas y precios'!$A$5:$P$54,16,FALSE),"") | K16: =IFERROR(G16-H16,"") | L16: =IFERROR(K16/G16,"")
... C404: =IFERROR(VLOOKUP(B404,'Recetas y precios'!$A$5:$B$54,2,FALSE),"") | G404: =IFERROR(E404*F404,"") | H404: =IFERROR(E404*VLOOKUP(B404,'Recetas y precios'!$A$5:$P$54,16,FALSE),"") | J404: =IFERROR(I404*VLOOKUP(B404,'Recetas y precios'!$A$5:$P$54,16,FALSE),"") | K404: =IFERROR(G404-H404,"") | L404: =IFERROR(K404/G404,"")

Sheet Tablero
A1: Tablero
A2: Resumen de tu operación. Se alimenta solo de las bitácoras de Producción y Ventas.
B4: RESULTADOS ACUMULADOS | E4: LAS DOS MERMAS
B5: Piezas vendidas | C5: =SUM(Ventas!E5:E404) | E5: Piezas buenas producidas | F5: =SUM(Producción!G5:G304)
B6: Ingreso total | C6: =SUM(Ventas!G5:G404) | E6: Piezas falladas en producción | F6: =SUM(Producción!H5:H304)
B7: Costo de lo vendido | C7: =SUM(Ventas!H5:H404) | E7: MERMA DE PRODUCCIÓN real | F7: =IFERROR(F6/(F5+F6),0)
B8: Utilidad bruta (antes de gastos fijos) | C8: =C6-C7 | E8: Merma que supones | F8: ='Mi negocio'!$F$8
B9: Margen bruto promedio | C9: =IFERROR(C8/C6,0) | E9: Piezas no vendidas (inventario) | F9: =SUM(Ventas!I5:I404)
B10: Ticket promedio por pieza | C10: =IFERROR(C6/C5,0) | E10: Dinero inmovilizado en no vendido | F10: =SUM(Ventas!J5:J404)
B11: Utilidad después de gastos fijos | C11: =C8-'Mi negocio'!$C$15 | E11: Dinero perdido en producción | F11: =SUM(Producción!J5:J304)
B14: PUNTO DE EQUILIBRIO DEL MES
B15: Gastos fijos del mes | C15: ='Mi negocio'!$C$15
B16: Precio promedio de mostrador | C16: ='Recetas y precios'!$C$58
B17: Costo total promedio por pieza | C17: ='Recetas y precios'!$C$57
B18: Margen de contribución por pieza | C18: =C16-C17
B19: Piezas que debes vender al mes para no perder | C19: =IFERROR(ROUNDUP(C15/C18,0),0)
B20: Piezas al día (30 días) | C20: =ROUNDUP(C19/30,0)
B21: Piezas vendidas hasta hoy | C21: =C5
B22: Avance al punto de equilibrio | C22: =IFERROR(C21/C19,0)
B24: Endulcora · Estudio Gastronómico · Anexo 1 del eBook «Dulces Mexicanos Tradicionales»
B25: Contenido: Chef Luis Alfonso Jiménez Cárdenas · Edición: Manuel Ramiro Justo Guzmán · WhatsApp 5665271901
B26: En colaboración con LEVENT · Consultoría en modelo de negocio, costos y punto de equilibrio
